Workbook

Sheet 白紙(4m)
B1: 工事名： | C1: ='白紙(5m)'!C1 -> 東白川特2高層配水池揚水管取替工事 | S1: 管 | X1: 口 | AC1: =IF(Y2<=100,4,0) -> 4
U2: NS | Y2: 75 | AC2: =IF(AC1=4,0,IF(Y2<=250,5,0)) -> 0
S3: 種 | W3: 形 | X3: 径 | AA3: ㎜ | AC3: =IF(Y2>250,6,0) -> 0
B5: 管切断工・挿し口加工数量計算書
B7: 管番号 | C7: 形 状 | R7: 残延長 | U7: 切断 | W7: 挿 し 口 加 工
U8: ＧＸ形 | V8: ＫＴ形 | W8: ＧＸ形 | X8: ＮＳ形 | Y8: ＫＦ形 | Z8: ＮＳ(溝) | AA8: ＳⅡ(溝)
B10: =IF(S10="","",1) -> 1 | E10: =IF(F10="","",IF(F10=0,"","L=")) -> L= | F10: 1 | H10: =IF(F10="","",IF(F10=0,"","m")) -> m | K10: =IF(L10="","",IF(L10=0,"","L=")) -> L= | L10: 1 | N10: =IF(L10="","",IF(L10=0,"","m")) -> m | R10: =IF(OR(S10="入力ｴﾗｰ",S10=0,S10="")=TRUE,"",IF(F10="","甲",IF(F10=0,"甲",""))) | S10: =IF((F10+I15+L10+O15)=0,"",IF((F10+I15+L10+O15)>SUM($AC$1:$AC$3),"入力ｴﾗｰ",SUM($AC$1:$AC$3)-(F10+I15+L10+O15))) -> 1 | T10: =IF(S10="","",IF(S10="入力ｴﾗｰ","","m")) -> m | U10: =IF(B10="","",COUNT(F10,I15,L10,O15)-IF(S10=0,1,0)-V10) -> 2 | V10: 1 | W10: 3
R13: =IF(R10="甲","",IF(OR(S10=0,S10="")=TRUE,"",IF(S10="入力ｴﾗｰ","","乙"))) -> 乙
H15: =IF(I15="","",IF(I15=0,"","L=")) -> L= | I15: 1 | K15: =IF(I15="","",IF(I15=0,"","m")) -> m | N15: =IF(O15="","",IF(O15=0,"","L=")) | Q15: =IF(O15="","",IF(O15=0,"","m")) | AC15: =IF(U10="",0,IF(U10>SUM(W10:AA15),U10-SUM(W10:AA15),0)) -> 0
B18: =IF(S18="","",IF(B10="","",1+B10)) | E18: =IF(F18="","",IF(F18=0,"","L=")) | H18: =IF(F18="","",IF(F18=0,"","m")) | K18: =IF(L18="","",IF(L18=0,"","L=")) | N18: =IF(L18="","",IF(L18=0,"","m")) | R18: =IF(OR(S18="入力ｴﾗｰ",S18=0,S18="")=TRUE,"",IF(F18="","甲",IF(F18=0,"甲",""))) | S18: =IF((F18+I23+L18+O23)=0,"",IF((F18+I23+L18+O23)>SUM($AC$1:$AC$3),"入力ｴﾗｰ",SUM($AC$1:$AC$3)-(F18+I23+L18+O23))) | T18: =IF(S18="","",IF(S18="入力ｴﾗｰ","","m")) | U18: =IF(B18="","",COUNT(F18,I23,L18,O23)-IF(S18=0,1,0)-V18)
R21: =IF(R18="甲","",IF(OR(S18=0,S18="")=TRUE,"",IF(S18="入力ｴﾗｰ","","乙")))
H23: =IF(I23="","",IF(I23=0,"","L=")) | K23: =IF(I23="","",IF(I23=0,"","m")) | N23: =IF(O23="","",IF(O23=0,"","L=")) | Q23: =IF(O23="","",IF(O23=0,"","m")) | AC23: =IF(U18="",0,IF(U18>SUM(W18:AA23),U18-SUM(W18:AA23),0)) -> 0
B26: =IF(S26="","",IF(B18="","",1+B18)) | E26: =IF(F26="","",IF(F26=0,"","L=")) | H26: =IF(F26="","",IF(F26=0,"","m")) | K26: =IF(L26="","",IF(L26=0,"","L=")) | N26: =IF(L26="","",IF(L26=0,"","m")) | R26: =IF(OR(S26="入力ｴﾗｰ",S26=0,S26="")=TRUE,"",IF(F26="","甲",IF(F26=0,"甲",""))) | S26: =IF((F26+I31+L26+O31)=0,"",IF((F26+I31+L26+O31)>SUM($AC$1:$AC$3),"入力ｴﾗｰ",SUM($AC$1:$AC$3)-(F26+I31+L26+O31))) | T26: =IF(S26="","",IF(S26="入力ｴﾗｰ","","m")) | U26: =IF(B26="","",COUNT(F26,I31,L26,O31)-IF(S26=0,1,0)-V26)
R29: =IF(R26="甲","",IF(OR(S26=0,S26="")=TRUE,"",IF(S26="入力ｴﾗｰ","","乙")))
H31: =IF(I31="","",IF(I31=0,"","L=")) | K31: =IF(I31="","",IF(I31=0,"","m")) | N31: =IF(O31="","",IF(O31=0,"","L=")) | Q31: =IF(O31="","",IF(O31=0,"","m")) | AC31: =IF(U26="",0,IF(U26>SUM(W26:AA31),U26-SUM(W26:AA31),0)) -> 0
B34: =IF(S34="","",IF(B26="","",1+B26)) | E34: =IF(F34="","",IF(F34=0,"","L=")) | H34: =IF(F34="","",IF(F34=0,"","m")) | K34: =IF(L34="","",IF(L34=0,"","L=")) | N34: =IF(L34="","",IF(L34=0,"","m")) | R34: =IF(OR(S34="入力ｴﾗｰ",S34=0,S34="")=TRUE,"",IF(F34="","甲",IF(F34=0,"甲",""))) | S34: =IF((F34+I39+L34+O39)=0,"",IF((F34+I39+L34+O39)>SUM($AC$1:$AC$3),"入力ｴﾗｰ",SUM($AC$1:$AC$3)-(F34+I39+L34+O39))) | T34: =IF(S34="","",IF(S34="入力ｴﾗｰ","","m")) | U34: =IF(B34="","",COUNT(F34,I39,L34,O39)-IF(S34=0,1,0)-V34)
R37: =IF(R34="甲","",IF(OR(S34=0,S34="")=TRUE,"",IF(S34="入力ｴﾗｰ","","乙")))
H39: =IF(I39="","",IF(I39=0,"","L=")) | K39: =IF(I39="","",IF(I39=0,"","m")) | N39: =IF(O39="","",IF(O39=0,"","L=")) | Q39: =IF(O39="","",IF(O39=0,"","m")) | AC39: =IF(U34="",0,IF(U34>SUM(W34:AA39),U34-SUM(W34:AA39),0)) -> 0
B42: =IF(S42="","",IF(B34="","",1+B34)) | E42: =IF(F42="","",IF(F42=0,"","L=")) | H42: =IF(F42="","",IF(F42=0,"","m")) | K42: =IF(L42="","",IF(L42=0,"","L=")) | N42: =IF(L42="","",IF(L42=0,"","m")) | R42: =IF(OR(S42="入力ｴﾗｰ",S42=0,S42="")=TRUE,"",IF(F42="","甲",IF(F42=0,"甲",""))) | S42: =IF((F42+I47+L42+O47)=0,"",IF((F42+I47+L42+O47)>SUM($AC$1:$AC$3),"入力ｴﾗｰ",SUM($AC$1:$AC$3)-(F42+I47+L42+O47))) | T42: =IF(S42="","",IF(S42="入力ｴﾗｰ","","m")) | U42: =IF(B42="","",COUNT(F42,I47,L42,O47)-IF(S42=0,1,0)-V42)
R45: =IF(R42="甲","",IF(OR(S42=0,S42="")=TRUE,"",IF(S42="入力ｴﾗｰ","","乙")))
H47: =IF(I47="","",IF(I47=0,"","L=")) | K47: =IF(I47="","",IF(I47=0,"","m")) | N47: =IF(O47="","",IF(O47=0,"","L=")) | Q47: =IF(O47="","",IF(O47=0,"","m")) | AC47: =IF(U42="",0,IF(U42>SUM(W42:AA47),U42-SUM(W42:AA47),0)) -> 0
B50: =IF(S50="","",IF(B42="","",1+B42)) | E50: =IF(F50="","",IF(F50=0,"","L=")) | H50: =IF(F50="","",IF(F50=0,"","m")) | K50: =IF(L50="","",IF(L50=0,"","L=")) | N50: =IF(L50="","",IF(L50=0,"","m")) | R50: =IF(OR(S50="入力ｴﾗｰ",S50=0,S50="")=TRUE,"",IF(F50="","甲",IF(F50=0,"甲",""))) | S50: =IF((F50+I55+L50+O55)=0,"",IF((F50+I55+L50+O55)>SUM($AC$1:$AC$3),"入力ｴﾗｰ",SUM($AC$1:$AC$3)-(F50+I55+L50+O55))) | T50: =IF(S50="","",IF(S50="入力ｴﾗｰ","","m")) | U50: =IF(B50="","",COUNT(F50,I55,L50,O55)-IF(S50=0,1,0)-V50)
R53: =IF(R50="甲","",IF(OR(S50=0,S50="")=TRUE,"",IF(S50="入力ｴﾗｰ","","乙")))
H55: =IF(I55="","",IF(I55=0,"","L=")) | K55: =IF(I55="","",IF(I55=0,"","m")) | N55: =IF(O55="","",IF(O55=0,"","L=")) | Q55: =IF(O55="","",IF(O55=0,"","m")) | AC55: =IF(U50="",0,IF(U50>SUM(W50:AA55),U50-SUM(W50:AA55),0)) -> 0
B58: =IF(S58="","",IF(B50="","",1+B50)) | E58: =IF(F58="","",IF(F58=0,"","L=")) | H58: =IF(F58="","",IF(F58=0,"","m")) | K58: =IF(L58="","",IF(L58=0,"","L=")) | N58: =IF(L58="","",IF(L58=0,"","m")) | R58: =IF(OR(S58="入力ｴﾗｰ",S58=0,S58="")=TRUE,"",IF(F58="","甲",IF(F58=0,"甲",""))) | S58: =IF((F58+I63+L58+O63)=0,"",IF((F58+I63+L58+O63)>SUM($AC$1:$AC$3),"入力ｴﾗｰ",SUM($AC$1:$AC$3)-(F58+I63+L58+O63))) | T58: =IF(S58="","",IF(S58="入力ｴﾗｰ","","m")) | U58: =IF(B58="","",COUNT(F58,I63,L58,O63)-IF(S58=0,1,0)-V58)
R61: =IF(R58="甲","",IF(OR(S58=0,S58="")=TRUE,"",IF(S58="入力ｴﾗｰ","","乙")))
H63: =IF(I63="","",IF(I63=0,"","L=")) | K63: =IF(I63="","",IF(I63=0,"","m")) | N63: =IF(O63="","",IF(O63=0,"","L=")) | Q63: =IF(O63="","",IF(O63=0,"","m")) | AC63: =IF(U58="",0,IF(U58>SUM(W58:AA63),U58-SUM(W58:AA63),0)) -> 0
B66: =IF(S66="","",IF(B58="","",1+B58)) | E66: =IF(F66="","",IF(F66=0,"","L=")) | H66: =IF(F66="","",IF(F66=0,"","m")) | K66: =IF(L66="","",IF(L66=0,"","L=")) | N66: =IF(L66="","",IF(L66=0,"","m")) | R66: =IF(OR(S66="入力ｴﾗｰ",S66=0,S66="")=TRUE,"",IF(F66="","甲",IF(F66=0,"甲",""))) | S66: =IF((F66+I71+L66+O71)=0,"",IF((F66+I71+L66+O71)>SUM($AC$1:$AC$3),"入力ｴﾗｰ",SUM($AC$1:$AC$3)-(F66+I71+L66+O71))) | T66: =IF(S66="","",IF(S66="入力ｴﾗｰ","","m")) | U66: =IF(B66="","",COUNT(F66,I71,L66,O71)-IF(S66=0,1,0)-V66)
R69: =IF(R66="甲","",IF(OR(S66=0,S66="")=TRUE,"",IF(S66="入力ｴﾗｰ","","乙")))
H71: =IF(I71="","",IF(I71=0,"","L=")) | K71: =IF(I71="","",IF(I71=0,"","m")) | N71: =IF(O71="","",IF(O71=0,"","L=")) | Q71: =IF(O71="","",IF(O71=0,"","m")) | AC71: =IF(U66="",0,IF(U66>SUM(W66:AA71),U66-SUM(W66:AA71),0)) -> 0
B74: =IF(S74="","",IF(B66="","",1+B66)) | E74: =IF(F74="","",IF(F74=0,"","L=")) | H74: =IF(F74="","",IF(F74=0,"","m")) | K74: =IF(L74="","",IF(L74=0,"","L=")) | N74: =IF(L74="","",IF(L74=0,"","m")) | R74: =IF(OR(S74="入力ｴﾗｰ",S74=0,S74="")=TRUE,"",IF(F74="","甲",IF(F74=0,"甲",""))) | S74: =IF((F74+I79+L74+O79)=0,"",IF((F74+I79+L74+O79)>SUM($AC$1:$AC$3),"入力ｴﾗｰ",SUM($AC$1:$AC$3)-(F74+I79+L74+O79))) | T74: =IF(S74="","",IF(S74="入力ｴﾗｰ","","m")) | U74: =IF(B74="","",COUNT(F74,I79,L74,O79)-IF(S74=0,1,0)-V74)
R77: =IF(R74="甲","",IF(OR(S74=0,S74="")=TRUE,"",IF(S74="入力ｴﾗｰ","","乙")))
H79: =IF(I79="","",IF(I79=0,"","L=")) | K79: =IF(I79="","",IF(I79=0,"","m")) | N79: =IF(O79="","",IF(O79=0,"","L=")) | Q79: =IF(O79="","",IF(O79=0,"","m")) | AC79: =IF(U74="",0,IF(U74>SUM(W74:AA79),U74-SUM(W74:AA79),0)) -> 0
B82: =IF(S82="","",IF(B74="","",1+B74)) | E82: =IF(F82="","",IF(F82=0,"","L=")) | H82: =IF(F82="","",IF(F82=0,"","m")) | K82: =IF(L82="","",IF(L82=0,"","L=")) | N82: =IF(L82="","",IF(L82=0,"","m")) | R82: =IF(OR(S82="入力ｴﾗｰ",S82=0,S82="")=TRUE,"",IF(F82="","甲",IF(F82=0,"甲",""))) | S82: =IF((F82+I87+L82+O87)=0,"",IF((F82+I87+L82+O87)>SUM($AC$1:$AC$3),"入力ｴﾗｰ",SUM($AC$1:$AC$3)-(F82+I87+L82+O87))) | T82: =IF(S82="","",IF(S82="入力ｴﾗｰ","","m")) | U82: =IF(B82="","",COUNT(F82,I87,L82,O87)-IF(S82=0,1,0)-V82)
R85: =IF(R82="甲","",IF(OR(S82=0,S82="")=TRUE,"",IF(S82="入力ｴﾗｰ","","乙")))
H87: =IF(I87="","",IF(I87=0,"","L=")) | K87: =IF(I87="","",IF(I87=0,"","m")) | N87: =IF(O87="","",IF(O87=0,"","L=")) | Q87: =IF(O87="","",IF(O87=0,"","m")) | AC87: =IF(U82="",0,IF(U82>SUM(W82:AA87),U82-SUM(W82:AA87),0)) -> 0
B90: =IF(S90="","",IF(B82="","",1+B82)) | E90: =IF(F90="","",IF(F90=0,"","L=")) | H90: =IF(F90="","",IF(F90=0,"","m")) | K90: =IF(L90="","",IF(L90=0,"","L=")) | N90: =IF(L90="","",IF(L90=0,"","m")) | R90: =IF(OR(S90="入力ｴﾗｰ",S90=0,S90="")=TRUE,"",IF(F90="","甲",IF(F90=0,"甲",""))) | T90: =IF(S90="","",IF(S90="入力ｴﾗｰ","","m")) | U90: =IF(B90="","",COUNT(F90,I95,L90,O95)-IF(S90=0,1,0)-V90)
R93: =IF(R90="甲","",IF(OR(S90=0,S90="")=TRUE,"",IF(S90="入力ｴﾗｰ","","乙")))
H95: =IF(I95="","",IF(I95=0,"","L=")) | K95: =IF(I95="","",IF(I95=0,"","m")) | N95: =IF(O95="","",IF(O95=0,"","L=")) | Q95: =IF(O95="","",IF(O95=0,"","m")) | AC95: =IF(U90="",0,IF(U90>SUM(W90:AA95),U90-SUM(W90:AA95),0)) -> 0
B98: =IF(S98="","",IF(B90="","",1+B90)) | E98: =IF(F98="","",IF(F98=0,"","L=")) | H98: =IF(F98="","",IF(F98=0,"","m")) | K98: =IF(L98="","",IF(L98=0,"","L=")) | N98: =IF(L98="","",IF(L98=0,"","m")) | R98: =IF(OR(S98="入力ｴﾗｰ",S98=0,S98="")=TRUE,"",IF(F98="","甲",IF(F98=0,"甲",""))) | S98: =IF((F98+I103+L98+O103)=0,"",IF((F98+I103+L98+O103)>SUM($AC$1:$AC$3),"入力ｴﾗｰ",SUM($AC$1:$AC$3)-(F98+I103+L98+O103))) | T98: =IF(S98="","",IF(S98="入力ｴﾗｰ","","m")) | U98: =IF(B98="","",COUNT(F98,I103,L98,O103)-IF(S98=0,1,0)-V98)
...

Sheet 白紙(5m)
B1: 工事名： | C1: 東白川特2高層配水池揚水管取替工事 | S1: 管 | X1: 口 | AC1: =IF(Y2<=100,4,0) -> 0
U2: NS | Y2: 150 | AC2: =IF(AC1=4,0,IF(Y2<=250,5,0)) -> 5
S3: 種 | W3: 形 | X3: 径 | AA3: ㎜ | AC3: =IF(Y2>250,6,0) -> 0
B5: 管切断工・挿し口加工数量計算書
B7: 管番号 | C7: 形 状 | R7: 残延長 | U7: 切断 | W7: 挿 し 口 加 工
U8: ＧＸ形 | V8: ＫＴ形 | W8: ＧＸ形 | X8: ＮＳ形 | Y8: ＫＦ形 | Z8: ＮＳ(溝) | AA8: ＳⅡ(溝)
B10: =IF(S10="","",1) | E10: =IF(F10="","",IF(F10=0,"","L=")) | H10: =IF(F10="","",IF(F10=0,"","m")) | K10: =IF(L10="","",IF(L10=0,"","L=")) | N10: =IF(L10="","",IF(L10=0,"","m")) | R10: =IF(OR(S10="入力ｴﾗｰ",S10=0,S10="")=TRUE,"",IF(F10="","甲",IF(F10=0,"甲",""))) | S10: =IF((F10+I15+L10+O15)=0,"",IF((F10+I15+L10+O15)>SUM($AC$1:$AC$3),"入力ｴﾗｰ",SUM($AC$1:$AC$3)-(F10+I15+L10+O15))) | T10: =IF(S10="","",IF(S10="入力ｴﾗｰ","","m")) | U10: =IF(B10="","",COUNT(F10,I15,L10,O15)-IF(S10=0,1,0)-V10)
R13: =IF(R10="甲","",IF(OR(S10=0,S10="")=TRUE,"",IF(S10="入力ｴﾗｰ","","乙")))
H15: =IF(I15="","",IF(I15=0,"","L=")) | K15: =IF(I15="","",IF(I15=0,"","m")) | N15: =IF(O15="","",IF(O15=0,"","L=")) | Q15: =IF(O15="","",IF(O15=0,"","m")) | AC15: =IF(U10="",0,IF(U10>SUM(W10:AA15),U10-SUM(W10:AA15),0)) -> 0
B18: =IF(S18="","",IF(B10="","",1+B10)) | E18: =IF(F18="","",IF(F18=0,"","L=")) | H18: =IF(F18="","",IF(F18=0,"","m")) | K18: =IF(L18="","",IF(L18=0,"","L=")) | N18: =IF(L18="","",IF(L18=0,"","m")) | R18: =IF(OR(S18="入力ｴﾗｰ",S18=0,S18="")=TRUE,"",IF(F18="","甲",IF(F18=0,"甲",""))) | S18: =IF((F18+I23+L18+O23)=0,"",IF((F18+I23+L18+O23)>SUM($AC$1:$AC$3),"入力ｴﾗｰ",SUM($AC$1:$AC$3)-(F18+I23+L18+O23))) | T18: =IF(S18="","",IF(S18="入力ｴﾗｰ","","m")) | U18: =IF(B18="","",COUNT(F18,I23,L18,O23)-IF(S18=0,1,0)-V18)
R21: =IF(R18="甲","",IF(OR(S18=0,S18="")=TRUE,"",IF(S18="入力ｴﾗｰ","","乙")))
H23: =IF(I23="","",IF(I23=0,"","L=")) | K23: =IF(I23="","",IF(I23=0,"","m")) | N23: =IF(O23="","",IF(O23=0,"","L=")) | Q23: =IF(O23="","",IF(O23=0,"","m")) | AC23: =IF(U18="",0,IF(U18>SUM(W18:AA23),U18-SUM(W18:AA23),0)) -> 0
B26: =IF(S26="","",IF(B18="","",1+B18)) | E26: =IF(F26="","",IF(F26=0,"","L=")) | K26: =IF(L26="","",IF(L26=0,"","L=")) | N26: =IF(L26="","",IF(L26=0,"","m")) | R26: =IF(OR(S26="入力ｴﾗｰ",S26=0,S26="")=TRUE,"",IF(F26="","甲",IF(F26=0,"甲",""))) | S26: =IF((F26+I31+L26+O31)=0,"",IF((F26+I31+L26+O31)>SUM($AC$1:$AC$3),"入力ｴﾗｰ",SUM($AC$1:$AC$3)-(F26+I31+L26+O31))) | T26: =IF(S26="","",IF(S26="入力ｴﾗｰ","","m")) | U26: =IF(B26="","",COUNT(F26,I31,L26,O31)-IF(S26=0,1,0)-V26)
R29: =IF(R26="甲","",IF(OR(S26=0,S26="")=TRUE,"",IF(S26="入力ｴﾗｰ","","乙")))
H31: =IF(I31="","",IF(I31=0,"","L=")) | N31: =IF(O31="","",IF(O31=0,"","L=")) | Q31: =IF(O31="","",IF(O31=0,"","m")) | AC31: =IF(U26="",0,IF(U26>SUM(W26:AA31),U26-SUM(W26:AA31),0)) -> 0
B34: =IF(S34="","",IF(B26="","",1+B26)) | E34: =IF(F34="","",IF(F34=0,"","L=")) | K34: =IF(L34="","",IF(L34=0,"","L=")) | N34: =IF(L34="","",IF(L34=0,"","m")) | R34: =IF(OR(S34="入力ｴﾗｰ",S34=0,S34="")=TRUE,"",IF(F34="","甲",IF(F34=0,"甲",""))) | S34: =IF((F34+I39+L34+O39)=0,"",IF((F34+I39+L34+O39)>SUM($AC$1:$AC$3),"入力ｴﾗｰ",SUM($AC$1:$AC$3)-(F34+I39+L34+O39))) | T34: =IF(S34="","",IF(S34="入力ｴﾗｰ","","m")) | U34: =IF(B34="","",COUNT(F34,I39,L34,O39)-IF(S34=0,1,0)-V34)
R37: =IF(R34="甲","",IF(OR(S34=0,S34="")=TRUE,"",IF(S34="入力ｴﾗｰ","","乙")))
H39: =IF(I39="","",IF(I39=0,"","L=")) | N39: =IF(O39="","",IF(O39=0,"","L=")) | Q39: =IF(O39="","",IF(O39=0,"","m")) | AC39: =IF(U34="",0,IF(U34>SUM(W34:AA39),U34-SUM(W34:AA39),0)) -> 0
B42: =IF(S42="","",IF(B34="","",1+B34)) | E42: =IF(F42="","",IF(F42=0,"","L=")) | K42: =IF(L42="","",IF(L42=0,"","L=")) | N42: =IF(L42="","",IF(L42=0,"","m")) | R42: =IF(OR(S42="入力ｴﾗｰ",S42=0,S42="")=TRUE,"",IF(F42="","甲",IF(F42=0,"甲",""))) | S42: =IF((F42+I47+L42+O47)=0,"",IF((F42+I47+L42+O47)>SUM($AC$1:$AC$3),"入力ｴﾗｰ",SUM($AC$1:$AC$3)-(F42+I47+L42+O47))) | T42: =IF(S42="","",IF(S42="入力ｴﾗｰ","","m")) | U42: =IF(B42="","",COUNT(F42,I47,L42,O47)-IF(S42=0,1,0)-V42)
R45: =IF(R42="甲","",IF(OR(S42=0,S42="")=TRUE,"",IF(S42="入力ｴﾗｰ","","乙")))
H47: =IF(I47="","",IF(I47=0,"","L=")) | N47: =IF(O47="","",IF(O47=0,"","L=")) | Q47: =IF(O47="","",IF(O47=0,"","m")) | AC47: =IF(U42="",0,IF(U42>SUM(W42:AA47),U42-SUM(W42:AA47),0)) -> 0
B50: =IF(S50="","",IF(B42="","",1+B42)) | E50: =IF(F50="","",IF(F50=0,"","L=")) | K50: =IF(L50="","",IF(L50=0,"","L=")) | N50: =IF(L50="","",IF(L50=0,"","m")) | R50: =IF(OR(S50="入力ｴﾗｰ",S50=0,S50="")=TRUE,"",IF(F50="","甲",IF(F50=0,"甲",""))) | S50: =IF((F50+I55+L50+O55)=0,"",IF((F50+I55+L50+O55)>SUM($AC$1:$AC$3),"入力ｴﾗｰ",SUM($AC$1:$AC$3)-(F50+I55+L50+O55))) | T50: =IF(S50="","",IF(S50="入力ｴﾗｰ","","m")) | U50: =IF(B50="","",COUNT(F50,I55,L50,O55)-IF(S50=0,1,0)-V50)
R53: =IF(R50="甲","",IF(OR(S50=0,S50="")=TRUE,"",IF(S50="入力ｴﾗｰ","","乙")))
H55: =IF(I55="","",IF(I55=0,"","L=")) | N55: =IF(O55="","",IF(O55=0,"","L=")) | Q55: =IF(O55="","",IF(O55=0,"","m")) | AC55: =IF(U50="",0,IF(U50>SUM(W50:AA55),U50-SUM(W50:AA55),0)) -> 0
B58: =IF(S58="","",IF(B50="","",1+B50)) | E58: =IF(F58="","",IF(F58=0,"","L=")) | K58: =IF(L58="","",IF(L58=0,"","L=")) | N58: =IF(L58="","",IF(L58=0,"","m")) | R58: =IF(OR(S58="入力ｴﾗｰ",S58=0,S58="")=TRUE,"",IF(F58="","甲",IF(F58=0,"甲",""))) | S58: =IF((F58+I63+L58+O63)=0,"",IF((F58+I63+L58+O63)>SUM($AC$1:$AC$3),"入力ｴﾗｰ",SUM($AC$1:$AC$3)-(F58+I63+L58+O63))) | T58: =IF(S58="","",IF(S58="入力ｴﾗｰ","","m")) | U58: =IF(B58="","",COUNT(F58,I63,L58,O63)-IF(S58=0,1,0)-V58)
R61: =IF(R58="甲","",IF(OR(S58=0,S58="")=TRUE,"",IF(S58="入力ｴﾗｰ","","乙")))
H63: =IF(I63="","",IF(I63=0,"","L=")) | N63: =IF(O63="","",IF(O63=0,"","L=")) | Q63: =IF(O63="","",IF(O63=0,"","m")) | AC63: =IF(U58="",0,IF(U58>SUM(W58:AA63),U58-SUM(W58:AA63),0)) -> 0
B66: =IF(S66="","",IF(B58="","",1+B58)) | E66: =IF(F66="","",IF(F66=0,"","L=")) | K66: =IF(L66="","",IF(L66=0,"","L=")) | N66: =IF(L66="","",IF(L66=0,"","m")) | R66: =IF(OR(S66="入力ｴﾗｰ",S66=0,S66="")=TRUE,"",IF(F66="","甲",IF(F66=0,"甲",""))) | S66: =IF((F66+I71+L66+O71)=0,"",IF((F66+I71+L66+O71)>SUM($AC$1:$AC$3),"入力ｴﾗｰ",SUM($AC$1:$AC$3)-(F66+I71+L66+O71))) | T66: =IF(S66="","",IF(S66="入力ｴﾗｰ","","m")) | U66: =IF(B66="","",COUNT(F66,I71,L66,O71)-IF(S66=0,1,0)-V66)
R69: =IF(R66="甲","",IF(OR(S66=0,S66="")=TRUE,"",IF(S66="入力ｴﾗｰ","","乙")))
H71: =IF(I71="","",IF(I71=0,"","L=")) | N71: =IF(O71="","",IF(O71=0,"","L=")) | Q71: =IF(O71="","",IF(O71=0,"","m")) | AC71: =IF(U66="",0,IF(U66>SUM(W66:AA71),U66-SUM(W66:AA71),0)) -> 0
B74: =IF(S74="","",IF(B66="","",1+B66)) | E74: =IF(F74="","",IF(F74=0,"","L=")) | K74: =IF(L74="","",IF(L74=0,"","L=")) | N74: =IF(L74="","",IF(L74=0,"","m")) | R74: =IF(OR(S74="入力ｴﾗｰ",S74=0,S74="")=TRUE,"",IF(F74="","甲",IF(F74=0,"甲",""))) | S74: =IF((F74+I79+L74+O79)=0,"",IF((F74+I79+L74+O79)>SUM($AC$1:$AC$3),"入力ｴﾗｰ",SUM($AC$1:$AC$3)-(F74+I79+L74+O79))) | T74: =IF(S74="","",IF(S74="入力ｴﾗｰ","","m")) | U74: =IF(B74="","",COUNT(F74,I79,L74,O79)-IF(S74=0,1,0)-V74)
R77: =IF(R74="甲","",IF(OR(S74=0,S74="")=TRUE,"",IF(S74="入力ｴﾗｰ","","乙")))
H79: =IF(I79="","",IF(I79=0,"","L=")) | N79: =IF(O79="","",IF(O79=0,"","L=")) | Q79: =IF(O79="","",IF(O79=0,"","m")) | AC79: =IF(U74="",0,IF(U74>SUM(W74:AA79),U74-SUM(W74:AA79),0)) -> 0
B82: =IF(S82="","",IF(B74="","",1+B74)) | E82: =IF(F82="","",IF(F82=0,"","L=")) | K82: =IF(L82="","",IF(L82=0,"","L=")) | N82: =IF(L82="","",IF(L82=0,"","m")) | R82: =IF(OR(S82="入力ｴﾗｰ",S82=0,S82="")=TRUE,"",IF(F82="","甲",IF(F82=0,"甲",""))) | S82: =IF((F82+I87+L82+O87)=0,"",IF((F82+I87+L82+O87)>SUM($AC$1:$AC$3),"入力ｴﾗｰ",SUM($AC$1:$AC$3)-(F82+I87+L82+O87))) | T82: =IF(S82="","",IF(S82="入力ｴﾗｰ","","m")) | U82: =IF(B82="","",COUNT(F82,I87,L82,O87)-IF(S82=0,1,0)-V82)
R85: =IF(R82="甲","",IF(OR(S82=0,S82="")=TRUE,"",IF(S82="入力ｴﾗｰ","","乙")))
H87: =IF(I87="","",IF(I87=0,"","L=")) | N87: =IF(O87="","",IF(O87=0,"","L=")) | Q87: =IF(O87="","",IF(O87=0,"","m")) | AC87: =IF(U82="",0,IF(U82>SUM(W82:AA87),U82-SUM(W82:AA87),0)) -> 0
B90: =IF(S90="","",IF(B82="","",1+B82)) | E90: =IF(F90="","",IF(F90=0,"","L=")) | K90: =IF(L90="","",IF(L90=0,"","L=")) | N90: =IF(L90="","",IF(L90=0,"","m")) | R90: =IF(OR(S90="入力ｴﾗｰ",S90=0,S90="")=TRUE,"",IF(F90="","甲",IF(F90=0,"甲",""))) | S90: =IF((F90+I95+L90+O95)=0,"",IF((F90+I95+L90+O95)>SUM($AC$1:$AC$3),"入力ｴﾗｰ",SUM($AC$1:$AC$3)-(F90+I95+L90+O95))) | T90: =IF(S90="","",IF(S90="入力ｴﾗｰ","","m")) | U90: =IF(B90="","",COUNT(F90,I95,L90,O95)-IF(S90=0,1,0)-V90)
R93: =IF(R90="甲","",IF(OR(S90=0,S90="")=TRUE,"",IF(S90="入力ｴﾗｰ","","乙")))
H95: =IF(I95="","",IF(I95=0,"","L=")) | N95: =IF(O95="","",IF(O95=0,"","L=")) | Q95: =IF(O95="","",IF(O95=0,"","m")) | AC95: =IF(U90="",0,IF(U90>SUM(W90:AA95),U90-SUM(W90:AA95),0)) -> 0
B98: =IF(S98="","",IF(B90="","",1+B90)) | E98: =IF(F98="","",IF(F98=0,"","L=")) | K98: =IF(L98="","",IF(L98=0,"","L=")) | N98: =IF(L98="","",IF(L98=0,"","m")) | R98: =IF(OR(S98="入力ｴﾗｰ",S98=0,S98="")=TRUE,"",IF(F98="","甲",IF(F98=0,"甲",""))) | S98: =IF((F98+I103+L98+O103)=0,"",IF((F98+I103+L98+O103)>SUM($AC$1:$AC$3),"入力ｴﾗｰ",SUM($AC$1:$AC$3)-(F98+I103+L98+O103))) | T98: =IF(S98="","",IF(S98="入力ｴﾗｰ","","m")) | U98: =IF(B98="","",COUNT(F98,I103,L98,O103)-IF(S98=0,1,0)-V98)
...

Sheet 白紙(6m)
B1: 工事名： | C1: ='白紙(5m)'!C1 -> 東白川特2高層配水池揚水管取替工事 | S1: 管 | X1: 口 | AC1: =IF(Y2<=100,4,0) -> 0
U2: NS | Y2: 300 | AC2: =IF(AC1=4,0,IF(Y2<=250,5,0)) -> 0
S3: 種 | W3: 形 | X3: 径 | AA3: ㎜ | AC3: =IF(Y2>250,6,0) -> 6
B5: 管切断工・挿し口加工数量計算書
B7: 管番号 | C7: 形 状 | R7: 残延長 | U7: 切断 | W7: 挿 し 口 加 工
U8: ＧＸ形 | V8: ＫＴ形 | W8: ＧＸ形 | X8: ＮＳ形 | Y8: ＫＦ形 | Z8: ＮＳ(溝) | AA8: ＳⅡ(溝)
B10: =IF(S10="","",1) -> 1 | E10: =IF(F10="","",IF(F10=0,"","L=")) -> L= | F10: 1 | H10: =IF(F10="","",IF(F10=0,"","m")) -> m | K10: =IF(L10="","",IF(L10=0,"","L=")) | N10: =IF(L10="","",IF(L10=0,"","m")) | R10: =IF(OR(S10="入力ｴﾗｰ",S10=0,S10="")=TRUE,"",IF(F10="","甲",IF(F10=0,"甲",""))) | S10: =IF((F10+I15+L10+O15)=0,"",IF((F10+I15+L10+O15)>SUM($AC$1:$AC$3),"入力ｴﾗｰ",SUM($AC$1:$AC$3)-(F10+I15+L10+O15))) -> 5 | T10: =IF(S10="","",IF(S10="入力ｴﾗｰ","","m")) -> m | U10: =IF(B10="","",COUNT(F10,I15,L10,O15)-IF(S10=0,1,0)-V10) -> 1 | W10: 1
R13: =IF(R10="甲","",IF(OR(S10=0,S10="")=TRUE,"",IF(S10="入力ｴﾗｰ","","乙"))) -> 乙
H15: =IF(I15="","",IF(I15=0,"","L=")) | K15: =IF(I15="","",IF(I15=0,"","m")) | N15: =IF(O15="","",IF(O15=0,"","L=")) | Q15: =IF(O15="","",IF(O15=0,"","m")) | AC15: =IF(U10="",0,IF(U10>SUM(W10:AA15),U10-SUM(W10:AA15),0)) -> 0
B18: =IF(S18="","",IF(B10="","",1+B10)) | E18: =IF(F18="","",IF(F18=0,"","L=")) | H18: =IF(F18="","",IF(F18=0,"","m")) | K18: =IF(L18="","",IF(L18=0,"","L=")) | N18: =IF(L18="","",IF(L18=0,"","m")) | R18: =IF(OR(S18="入力ｴﾗｰ",S18=0,S18="")=TRUE,"",IF(F18="","甲",IF(F18=0,"甲",""))) | S18: =IF((F18+I23+L18+O23)=0,"",IF((F18+I23+L18+O23)>SUM($AC$1:$AC$3),"入力ｴﾗｰ",SUM($AC$1:$AC$3)-(F18+I23+L18+O23))) | T18: =IF(S18="","",IF(S18="入力ｴﾗｰ","","m")) | U18: =IF(B18="","",COUNT(F18,I23,L18,O23)-IF(S18=0,1,0)-V18)
R21: =IF(R18="甲","",IF(OR(S18=0,S18="")=TRUE,"",IF(S18="入力ｴﾗｰ","","乙")))
H23: =IF(I23="","",IF(I23=0,"","L=")) | K23: =IF(I23="","",IF(I23=0,"","m")) | N23: =IF(O23="","",IF(O23=0,"","L=")) | Q23: =IF(O23="","",IF(O23=0,"","m")) | AC23: =IF(U18="",0,IF(U18>SUM(W18:AA23),U18-SUM(W18:AA23),0)) -> 0
B26: =IF(S26="","",IF(B18="","",1+B18)) | E26: =IF(F26="","",IF(F26=0,"","L=")) | H26: =IF(F26="","",IF(F26=0,"","m")) | K26: =IF(L26="","",IF(L26=0,"","L=")) | N26: =IF(L26="","",IF(L26=0,"","m")) | R26: =IF(OR(S26="入力ｴﾗｰ",S26=0,S26="")=TRUE,"",IF(F26="","甲",IF(F26=0,"甲",""))) | S26: =IF((F26+I31+L26+O31)=0,"",IF((F26+I31+L26+O31)>SUM($AC$1:$AC$3),"入力ｴﾗｰ",SUM($AC$1:$AC$3)-(F26+I31+L26+O31))) | T26: =IF(S26="","",IF(S26="入力ｴﾗｰ","","m")) | U26: =IF(B26="","",COUNT(F26,I31,L26,O31)-IF(S26=0,1,0)-V26)
R29: =IF(R26="甲","",IF(OR(S26=0,S26="")=TRUE,"",IF(S26="入力ｴﾗｰ","","乙")))
H31: =IF(I31="","",IF(I31=0,"","L=")) | K31: =IF(I31="","",IF(I31=0,"","m")) | N31: =IF(O31="","",IF(O31=0,"","L=")) | Q31: =IF(O31="","",IF(O31=0,"","m")) | AC31: =IF(U26="",0,IF(U26>SUM(W26:AA31),U26-SUM(W26:AA31),0)) -> 0
B34: =IF(S34="","",IF(B26="","",1+B26)) | E34: =IF(F34="","",IF(F34=0,"","L=")) | H34: =IF(F34="","",IF(F34=0,"","m")) | K34: =IF(L34="","",IF(L34=0,"","L=")) | N34: =IF(L34="","",IF(L34=0,"","m")) | R34: =IF(OR(S34="入力ｴﾗｰ",S34=0,S34="")=TRUE,"",IF(F34="","甲",IF(F34=0,"甲",""))) | S34: =IF((F34+I39+L34+O39)=0,"",IF((F34+I39+L34+O39)>SUM($AC$1:$AC$3),"入力ｴﾗｰ",SUM($AC$1:$AC$3)-(F34+I39+L34+O39))) | T34: =IF(S34="","",IF(S34="入力ｴﾗｰ","","m")) | U34: =IF(B34="","",COUNT(F34,I39,L34,O39)-IF(S34=0,1,0)-V34)
R37: =IF(R34="甲","",IF(OR(S34=0,S34="")=TRUE,"",IF(S34="入力ｴﾗｰ","","乙")))
H39: =IF(I39="","",IF(I39=0,"","L=")) | K39: =IF(I39="","",IF(I39=0,"","m")) | N39: =IF(O39="","",IF(O39=0,"","L=")) | Q39: =IF(O39="","",IF(O39=0,"","m")) | AC39: =IF(U34="",0,IF(U34>SUM(W34:AA39),U34-SUM(W34:AA39),0)) -> 0
B42: =IF(S42="","",IF(B34="","",1+B34)) | E42: =IF(F42="","",IF(F42=0,"","L=")) | H42: =IF(F42="","",IF(F42=0,"","m")) | K42: =IF(L42="","",IF(L42=0,"","L=")) | N42: =IF(L42="","",IF(L42=0,"","m")) | R42: =IF(OR(S42="入力ｴﾗｰ",S42=0,S42="")=TRUE,"",IF(F42="","甲",IF(F42=0,"甲",""))) | S42: =IF((F42+I47+L42+O47)=0,"",IF((F42+I47+L42+O47)>SUM($AC$1:$AC$3),"入力ｴﾗｰ",SUM($AC$1:$AC$3)-(F42+I47+L42+O47))) | T42: =IF(S42="","",IF(S42="入力ｴﾗｰ","","m")) | U42: =IF(B42="","",COUNT(F42,I47,L42,O47)-IF(S42=0,1,0)-V42)
R45: =IF(R42="甲","",IF(OR(S42=0,S42="")=TRUE,"",IF(S42="入力ｴﾗｰ","","乙")))
H47: =IF(I47="","",IF(I47=0,"","L=")) | K47: =IF(I47="","",IF(I47=0,"","m")) | N47: =IF(O47="","",IF(O47=0,"","L=")) | Q47: =IF(O47="","",IF(O47=0,"","m")) | AC47: =IF(U42="",0,IF(U42>SUM(W42:AA47),U42-SUM(W42:AA47),0)) -> 0
B50: =IF(S50="","",IF(B42="","",1+B42)) | E50: =IF(F50="","",IF(F50=0,"","L=")) | H50: =IF(F50="","",IF(F50=0,"","m")) | K50: =IF(L50="","",IF(L50=0,"","L=")) | N50: =IF(L50="","",IF(L50=0,"","m")) | R50: =IF(OR(S50="入力ｴﾗｰ",S50=0,S50="")=TRUE,"",IF(F50="","甲",IF(F50=0,"甲",""))) | S50: =IF((F50+I55+L50+O55)=0,"",IF((F50+I55+L50+O55)>SUM($AC$1:$AC$3),"入力ｴﾗｰ",SUM($AC$1:$AC$3)-(F50+I55+L50+O55))) | T50: =IF(S50="","",IF(S50="入力ｴﾗｰ","","m")) | U50: =IF(B50="","",COUNT(F50,I55,L50,O55)-IF(S50=0,1,0)-V50)
R53: =IF(R50="甲","",IF(OR(S50=0,S50="")=TRUE,"",IF(S50="入力ｴﾗｰ","","乙")))
H55: =IF(I55="","",IF(I55=0,"","L=")) | K55: =IF(I55="","",IF(I55=0,"","m")) | N55: =IF(O55="","",IF(O55=0,"","L=")) | Q55: =IF(O55="","",IF(O55=0,"","m")) | AC55: =IF(U50="",0,IF(U50>SUM(W50:AA55),U50-SUM(W50:AA55),0)) -> 0
B58: =IF(S58="","",IF(B50="","",1+B50)) | E58: =IF(F58="","",IF(F58=0,"","L=")) | H58: =IF(F58="","",IF(F58=0,"","m")) | K58: =IF(L58="","",IF(L58=0,"","L=")) | N58: =IF(L58="","",IF(L58=0,"","m")) | R58: =IF(OR(S58="入力ｴﾗｰ",S58=0,S58="")=TRUE,"",IF(F58="","甲",IF(F58=0,"甲",""))) | S58: =IF((F58+I63+L58+O63)=0,"",IF((F58+I63+L58+O63)>SUM($AC$1:$AC$3),"入力ｴﾗｰ",SUM($AC$1:$AC$3)-(F58+I63+L58+O63))) | T58: =IF(S58="","",IF(S58="入力ｴﾗｰ","","m")) | U58: =IF(B58="","",COUNT(F58,I63,L58,O63)-IF(S58=0,1,0)-V58)
R61: =IF(R58="甲","",IF(OR(S58=0,S58="")=TRUE,"",IF(S58="入力ｴﾗｰ","","乙")))
H63: =IF(I63="","",IF(I63=0,"","L=")) | K63: =IF(I63="","",IF(I63=0,"","m")) | N63: =IF(O63="","",IF(O63=0,"","L=")) | Q63: =IF(O63="","",IF(O63=0,"","m")) | AC63: =IF(U58="",0,IF(U58>SUM(W58:AA63),U58-SUM(W58:AA63),0)) -> 0
B66: =IF(S66="","",IF(B58="","",1+B58)) | E66: =IF(F66="","",IF(F66=0,"","L=")) | H66: =IF(F66="","",IF(F66=0,"","m")) | K66: =IF(L66="","",IF(L66=0,"","L=")) | N66: =IF(L66="","",IF(L66=0,"","m")) | R66: =IF(OR(S66="入力ｴﾗｰ",S66=0,S66="")=TRUE,"",IF(F66="","甲",IF(F66=0,"甲",""))) | S66: =IF((F66+I71+L66+O71)=0,"",IF((F66+I71+L66+O71)>SUM($AC$1:$AC$3),"入力ｴﾗｰ",SUM($AC$1:$AC$3)-(F66+I71+L66+O71))) | T66: =IF(S66="","",IF(S66="入力ｴﾗｰ","","m")) | U66: =IF(B66="","",COUNT(F66,I71,L66,O71)-IF(S66=0,1,0)-V66)
R69: =IF(R66="甲","",IF(OR(S66=0,S66="")=TRUE,"",IF(S66="入力ｴﾗｰ","","乙")))
H71: =IF(I71="","",IF(I71=0,"","L=")) | K71: =IF(I71="","",IF(I71=0,"","m")) | N71: =IF(O71="","",IF(O71=0,"","L=")) | Q71: =IF(O71="","",IF(O71=0,"","m")) | AC71: =IF(U66="",0,IF(U66>SUM(W66:AA71),U66-SUM(W66:AA71),0)) -> 0
B74: =IF(S74="","",IF(B66="","",1+B66)) | E74: =IF(F74="","",IF(F74=0,"","L=")) | H74: =IF(F74="","",IF(F74=0,"","m")) | K74: =IF(L74="","",IF(L74=0,"","L=")) | N74: =IF(L74="","",IF(L74=0,"","m")) | R74: =IF(OR(S74="入力ｴﾗｰ",S74=0,S74="")=TRUE,"",IF(F74="","甲",IF(F74=0,"甲",""))) | S74: =IF((F74+I79+L74+O79)=0,"",IF((F74+I79+L74+O79)>SUM($AC$1:$AC$3),"入力ｴﾗｰ",SUM($AC$1:$AC$3)-(F74+I79+L74+O79))) | T74: =IF(S74="","",IF(S74="入力ｴﾗｰ","","m")) | U74: =IF(B74="","",COUNT(F74,I79,L74,O79)-IF(S74=0,1,0)-V74)
R77: =IF(R74="甲","",IF(OR(S74=0,S74="")=TRUE,"",IF(S74="入力ｴﾗｰ","","乙")))
H79: =IF(I79="","",IF(I79=0,"","L=")) | K79: =IF(I79="","",IF(I79=0,"","m")) | N79: =IF(O79="","",IF(O79=0,"","L=")) | Q79: =IF(O79="","",IF(O79=0,"","m")) | AC79: =IF(U74="",0,IF(U74>SUM(W74:AA79),U74-SUM(W74:AA79),0)) -> 0
B82: =IF(S82="","",IF(B74="","",1+B74)) | E82: =IF(F82="","",IF(F82=0,"","L=")) | H82: =IF(F82="","",IF(F82=0,"","m")) | K82: =IF(L82="","",IF(L82=0,"","L=")) | N82: =IF(L82="","",IF(L82=0,"","m")) | R82: =IF(OR(S82="入力ｴﾗｰ",S82=0,S82="")=TRUE,"",IF(F82="","甲",IF(F82=0,"甲",""))) | S82: =IF((F82+I87+L82+O87)=0,"",IF((F82+I87+L82+O87)>SUM($AC$1:$AC$3),"入力ｴﾗｰ",SUM($AC$1:$AC$3)-(F82+I87+L82+O87))) | T82: =IF(S82="","",IF(S82="入力ｴﾗｰ","","m")) | U82: =IF(B82="","",COUNT(F82,I87,L82,O87)-IF(S82=0,1,0)-V82)
R85: =IF(R82="甲","",IF(OR(S82=0,S82="")=TRUE,"",IF(S82="入力ｴﾗｰ","","乙")))
H87: =IF(I87="","",IF(I87=0,"","L=")) | K87: =IF(I87="","",IF(I87=0,"","m")) | N87: =IF(O87="","",IF(O87=0,"","L=")) | Q87: =IF(O87="","",IF(O87=0,"","m")) | AC87: =IF(U82="",0,IF(U82>SUM(W82:AA87),U82-SUM(W82:AA87),0)) -> 0
B90: =IF(S90="","",IF(B82="","",1+B82)) | E90: =IF(F90="","",IF(F90=0,"","L=")) | H90: =IF(F90="","",IF(F90=0,"","m")) | K90: =IF(L90="","",IF(L90=0,"","L=")) | N90: =IF(L90="","",IF(L90=0,"","m")) | R90: =IF(OR(S90="入力ｴﾗｰ",S90=0,S90="")=TRUE,"",IF(F90="","甲",IF(F90=0,"甲",""))) | S90: =IF((F90+I95+L90+O95)=0,"",IF((F90+I95+L90+O95)>SUM($AC$1:$AC$3),"入力ｴﾗｰ",SUM($AC$1:$AC$3)-(F90+I95+L90+O95))) | T90: =IF(S90="","",IF(S90="入力ｴﾗｰ","","m")) | U90: =IF(B90="","",COUNT(F90,I95,L90,O95)-IF(S90=0,1,0)-V90)
R93: =IF(R90="甲","",IF(OR(S90=0,S90="")=TRUE,"",IF(S90="入力ｴﾗｰ","","乙")))
H95: =IF(I95="","",IF(I95=0,"","L=")) | K95: =IF(I95="","",IF(I95=0,"","m")) | N95: =IF(O95="","",IF(O95=0,"","L=")) | Q95: =IF(O95="","",IF(O95=0,"","m")) | AC95: =IF(U90="",0,IF(U90>SUM(W90:AA95),U90-SUM(W90:AA95),0)) -> 0
B98: =IF(S98="","",IF(B90="","",1+B90)) | E98: =IF(F98="","",IF(F98=0,"","L=")) | H98: =IF(F98="","",IF(F98=0,"","m")) | K98: =IF(L98="","",IF(L98=0,"","L=")) | N98: =IF(L98="","",IF(L98=0,"","m")) | R98: =IF(OR(S98="入力ｴﾗｰ",S98=0,S98="")=TRUE,"",IF(F98="","甲",IF(F98=0,"甲",""))) | S98: =IF((F98+I103+L98+O103)=0,"",IF((F98+I103+L98+O103)>SUM($AC$1:$AC$3),"入力ｴﾗｰ",SUM($AC$1:$AC$3)-(F98+I103+L98+O103))) | T98: =IF(S98="","",IF(S98="入力ｴﾗｰ","","m")) | U98: =IF(B98="","",COUNT(F98,I103,L98,O103)-IF(S98=0,1,0)-V98)
...

Sheet GX　200
B1: 工事名： | C1: ='白紙(5m)'!C1 -> 東白川特2高層配水池揚水管取替工事 | S1: 管 | X1: 口 | AC1: =IF(Y2<=100,4,0) -> 0
U2: GX | Y2: 200 | AC2: =IF(AC1=4,0,IF(Y2<=250,5,0)) -> 5
S3: 種 | W3: 形 | X3: 径 | AA3: ㎜ | AC3: =IF(Y2>250,6,0) -> 0
B5: 管切断工・挿し口加工数量計算書 | U5: ※切管延長に挿し口リング延長を含む
B7: 管番号 | C7: 形 状 | R7: 残延長 | U7: 切断 | W7: 挿 し 口 加 工
U8: ＧＸ形 | V8: ＫＴ形 | W8: ＧＸ形 | X8: ＮＳ形 | Y8: ＫＦ形 | Z8: ＮＳ(溝) | AA8: ＳⅡ(溝)
B10: =IF(S10="","",1) -> 1 | E10: =IF(F10="","",IF(F10=0,"","L=")) -> L= | F10: 2.54 | H10: =IF(F10="","",IF(F10=0,"","m")) -> m | K10: =IF(L10="","",IF(L10=0,"","L=")) | N10: =IF(L10="","",IF(L10=0,"","m")) | R10: =IF(OR(S10="入力ｴﾗｰ",S10=0,S10="")=TRUE,"",IF(F10="","甲",IF(F10=0,"甲",""))) | S10: =IF((F10+I15+L10+O15)=0,"",IF((F10+I15+L10+O15)>SUM($AC$1:$AC$3),"入力ｴﾗｰ",SUM($AC$1:$AC$3)-(F10+I15+L10+O15))) -> 1.57 | T10: =IF(S10="","",IF(S10="入力ｴﾗｰ","","m")) -> m | U10: =IF(B10="","",COUNT(F10,I15,L10,O15)-IF(S10=0,1,0)-V10) -> 2 | W10: 2
R13: =IF(R10="甲","",IF(OR(S10=0,S10="")=TRUE,"",IF(S10="入力ｴﾗｰ","","乙"))) -> 乙
H15: =IF(I15="","",IF(I15=0,"","L=")) | K15: =IF(I15="","",IF(I15=0,"","m")) | N15: =IF(O15="","",IF(O15=0,"","L=")) -> L= | O15: 0.89 | Q15: =IF(O15="","",IF(O15=0,"","m")) -> m | AC15: =IF(U10="",0,IF(U10>SUM(W10:AA15),U10-SUM(W10:AA15),0)) -> 0
B18: =IF(S18="","",IF(B10="","",1+B10)) -> 2 | E18: =IF(F18="","",IF(F18=0,"","L=")) -> L= | F18: 2.86 | H18: =IF(F18="","",IF(F18=0,"","m")) -> m | K18: =IF(L18="","",IF(L18=0,"","L=")) | N18: =IF(L18="","",IF(L18=0,"","m")) | R18: =IF(OR(S18="入力ｴﾗｰ",S18=0,S18="")=TRUE,"",IF(F18="","甲",IF(F18=0,"甲",""))) | S18: =IF((F18+I23+L18+O23)=0,"",IF((F18+I23+L18+O23)>SUM($AC$1:$AC$3),"入力ｴﾗｰ",SUM($AC$1:$AC$3)-(F18+I23+L18+O23))) -> 0.75 | T18: =IF(S18="","",IF(S18="入力ｴﾗｰ","","m")) -> m | U18: =IF(B18="","",COUNT(F18,I23,L18,O23)-IF(S18=0,1,0)-V18) -> 2 | W18: 2
R21: =IF(R18="甲","",IF(OR(S18=0,S18="")=TRUE,"",IF(S18="入力ｴﾗｰ","","乙"))) -> 乙
H23: =IF(I23="","",IF(I23=0,"","L=")) | K23: =IF(I23="","",IF(I23=0,"","m")) | N23: =IF(O23="","",IF(O23=0,"","L=")) -> L= | O23: 1.39 | Q23: =IF(O23="","",IF(O23=0,"","m")) -> m | AC23: =IF(U18="",0,IF(U18>SUM(W18:AA23),U18-SUM(W18:AA23),0)) -> 0
B26: =IF(S26="","",IF(B18="","",1+B18)) -> 3 | E26: =IF(F26="","",IF(F26=0,"","L=")) -> L= | F26: 3.5 | H26: =IF(F26="","",IF(F26=0,"","m")) -> m | K26: =IF(L26="","",IF(L26=0,"","L=")) | N26: =IF(L26="","",IF(L26=0,"","m")) | R26: =IF(OR(S26="入力ｴﾗｰ",S26=0,S26="")=TRUE,"",IF(F26="","甲",IF(F26=0,"甲",""))) | S26: =IF((F26+I31+L26+O31)=0,"",IF((F26+I31+L26+O31)>SUM($AC$1:$AC$3),"入力ｴﾗｰ",SUM($AC$1:$AC$3)-(F26+I31+L26+O31))) -> 1.5 | T26: =IF(S26="","",IF(S26="入力ｴﾗｰ","","m")) -> m | U26: =IF(B26="","",COUNT(F26,I31,L26,O31)-IF(S26=0,1,0)-V26) -> 1 | W26: 1
R29: =IF(R26="甲","",IF(OR(S26=0,S26="")=TRUE,"",IF(S26="入力ｴﾗｰ","","乙"))) -> 乙
H31: =IF(I31="","",IF(I31=0,"","L=")) | K31: =IF(I31="","",IF(I31=0,"","m")) | N31: =IF(O31="","",IF(O31=0,"","L=")) | Q31: =IF(O31="","",IF(O31=0,"","m")) | AC31: =IF(U26="",0,IF(U26>SUM(W26:AA31),U26-SUM(W26:AA31),0)) -> 0
B34: =IF(S34="","",IF(B26="","",1+B26)) -> 4 | E34: =IF(F34="","",IF(F34=0,"","L=")) -> L= | F34: 1 | H34: =IF(F34="","",IF(F34=0,"","m")) -> m | K34: =IF(L34="","",IF(L34=0,"","L=")) | N34: =IF(L34="","",IF(L34=0,"","m")) | R34: =IF(OR(S34="入力ｴﾗｰ",S34=0,S34="")=TRUE,"",IF(F34="","甲",IF(F34=0,"甲",""))) | S34: =IF((F34+I39+L34+O39)=0,"",IF((F34+I39+L34+O39)>SUM($AC$1:$AC$3),"入力ｴﾗｰ",SUM($AC$1:$AC$3)-(F34+I39+L34+O39))) -> 2.54 | T34: =IF(S34="","",IF(S34="入力ｴﾗｰ","","m")) -> m | U34: =IF(B34="","",COUNT(F34,I39,L34,O39)-IF(S34=0,1,0)-V34) -> 2 | W34: 2
R37: =IF(R34="甲","",IF(OR(S34=0,S34="")=TRUE,"",IF(S34="入力ｴﾗｰ","","乙"))) -> 乙
H39: =IF(I39="","",IF(I39=0,"","L=")) | K39: =IF(I39="","",IF(I39=0,"","m")) | N39: =IF(O39="","",IF(O39=0,"","L=")) -> L= | O39: 1.46 | Q39: =IF(O39="","",IF(O39=0,"","m")) -> m | AC39: =IF(U34="",0,IF(U34>SUM(W34:AA39),U34-SUM(W34:AA39),0)) -> 0
B42: =IF(S42="","",IF(B34="","",1+B34)) | E42: =IF(F42="","",IF(F42=0,"","L=")) | H42: =IF(F42="","",IF(F42=0,"","m")) | K42: =IF(L42="","",IF(L42=0,"","L=")) | N42: =IF(L42="","",IF(L42=0,"","m")) | R42: =IF(OR(S42="入力ｴﾗｰ",S42=0,S42="")=TRUE,"",IF(F42="","甲",IF(F42=0,"甲",""))) | S42: =IF((F42+I47+L42+O47)=0,"",IF((F42+I47+L42+O47)>SUM($AC$1:$AC$3),"入力ｴﾗｰ",SUM($AC$1:$AC$3)-(F42+I47+L42+O47))) | T42: =IF(S42="","",IF(S42="入力ｴﾗｰ","","m")) | U42: =IF(B42="","",COUNT(F42,I47,L42,O47)-IF(S42=0,1,0)-V42)
R45: =IF(R42="甲","",IF(OR(S42=0,S42="")=TRUE,"",IF(S42="入力ｴﾗｰ","","乙")))
H47: =IF(I47="","",IF(I47=0,"","L=")) | K47: =IF(I47="","",IF(I47=0,"","m")) | N47: =IF(O47="","",IF(O47=0,"","L=")) | Q47: =IF(O47="","",IF(O47=0,"","m")) | AC47: =IF(U42="",0,IF(U42>SUM(W42:AA47),U42-SUM(W42:AA47),0)) -> 0
B50: =IF(S50="","",IF(B42="","",1+B42)) | E50: =IF(F50="","",IF(F50=0,"","L=")) | H50: =IF(F50="","",IF(F50=0,"","m")) | K50: =IF(L50="","",IF(L50=0,"","L=")) | N50: =IF(L50="","",IF(L50=0,"","m")) | R50: =IF(OR(S50="入力ｴﾗｰ",S50=0,S50="")=TRUE,"",IF(F50="","甲",IF(F50=0,"甲",""))) | S50: =IF((F50+I55+L50+O55)=0,"",IF((F50+I55+L50+O55)>SUM($AC$1:$AC$3),"入力ｴﾗｰ",SUM($AC$1:$AC$3)-(F50+I55+L50+O55))) | T50: =IF(S50="","",IF(S50="入力ｴﾗｰ","","m")) | U50: =IF(B50="","",COUNT(F50,I55,L50,O55)-IF(S50=0,1,0)-V50)
R53: =IF(R50="甲","",IF(OR(S50=0,S50="")=TRUE,"",IF(S50="入力ｴﾗｰ","","乙")))
H55: =IF(I55="","",IF(I55=0,"","L=")) | K55: =IF(I55="","",IF(I55=0,"","m")) | N55: =IF(O55="","",IF(O55=0,"","L=")) | Q55: =IF(O55="","",IF(O55=0,"","m")) | AC55: =IF(U50="",0,IF(U50>SUM(W50:AA55),U50-SUM(W50:AA55),0)) -> 0
B58: =IF(S58="","",IF(B50="","",1+B50)) | E58: =IF(F58="","",IF(F58=0,"","L=")) | H58: =IF(F58="","",IF(F58=0,"","m")) | K58: =IF(L58="","",IF(L58=0,"","L=")) | N58: =IF(L58="","",IF(L58=0,"","m")) | R58: =IF(OR(S58="入力ｴﾗｰ",S58=0,S58="")=TRUE,"",IF(F58="","甲",IF(F58=0,"甲",""))) | S58: =IF((F58+I63+L58+O63)=0,"",IF((F58+I63+L58+O63)>SUM($AC$1:$AC$3),"入力ｴﾗｰ",SUM($AC$1:$AC$3)-(F58+I63+L58+O63))) | T58: =IF(S58="","",IF(S58="入力ｴﾗｰ","","m")) | U58: =IF(B58="","",COUNT(F58,I63,L58,O63)-IF(S58=0,1,0)-V58)
R61: =IF(R58="甲","",IF(OR(S58=0,S58="")=TRUE,"",IF(S58="入力ｴﾗｰ","","乙")))
H63: =IF(I63="","",IF(I63=0,"","L=")) | K63: =IF(I63="","",IF(I63=0,"","m")) | N63: =IF(O63="","",IF(O63=0,"","L=")) | Q63: =IF(O63="","",IF(O63=0,"","m")) | AC63: =IF(U58="",0,IF(U58>SUM(W58:AA63),U58-SUM(W58:AA63),0)) -> 0
B66: =IF(S66="","",IF(B58="","",1+B58)) | E66: =IF(F66="","",IF(F66=0,"","L=")) | H66: =IF(F66="","",IF(F66=0,"","m")) | K66: =IF(L66="","",IF(L66=0,"","L=")) | N66: =IF(L66="","",IF(L66=0,"","m")) | R66: =IF(OR(S66="入力ｴﾗｰ",S66=0,S66="")=TRUE,"",IF(F66="","甲",IF(F66=0,"甲",""))) | S66: =IF((F66+I71+L66+O71)=0,"",IF((F66+I71+L66+O71)>SUM($AC$1:$AC$3),"入力ｴﾗｰ",SUM($AC$1:$AC$3)-(F66+I71+L66+O71))) | T66: =IF(S66="","",IF(S66="入力ｴﾗｰ","","m")) | U66: =IF(B66="","",COUNT(F66,I71,L66,O71)-IF(S66=0,1,0)-V66)
R69: =IF(R66="甲","",IF(OR(S66=0,S66="")=TRUE,"",IF(S66="入力ｴﾗｰ","","乙")))
H71: =IF(I71="","",IF(I71=0,"","L=")) | K71: =IF(I71="","",IF(I71=0,"","m")) | N71: =IF(O71="","",IF(O71=0,"","L=")) | Q71: =IF(O71="","",IF(O71=0,"","m")) | AC71: =IF(U66="",0,IF(U66>SUM(W66:AA71),U66-SUM(W66:AA71),0)) -> 0
B74: =IF(S74="","",IF(B66="","",1+B66)) | E74: =IF(F74="","",IF(F74=0,"","L=")) | H74: =IF(F74="","",IF(F74=0,"","m")) | K74: =IF(L74="","",IF(L74=0,"","L=")) | N74: =IF(L74="","",IF(L74=0,"","m")) | R74: =IF(OR(S74="入力ｴﾗｰ",S74=0,S74="")=TRUE,"",IF(F74="","甲",IF(F74=0,"甲",""))) | S74: =IF((F74+I79+L74+O79)=0,"",IF((F74+I79+L74+O79)>SUM($AC$1:$AC$3),"入力ｴﾗｰ",SUM($AC$1:$AC$3)-(F74+I79+L74+O79))) | T74: =IF(S74="","",IF(S74="入力ｴﾗｰ","","m")) | U74: =IF(B74="","",COUNT(F74,I79,L74,O79)-IF(S74=0,1,0)-V74)
R77: =IF(R74="甲","",IF(OR(S74=0,S74="")=TRUE,"",IF(S74="入力ｴﾗｰ","","乙")))
H79: =IF(I79="","",IF(I79=0,"","L=")) | K79: =IF(I79="","",IF(I79=0,"","m")) | N79: =IF(O79="","",IF(O79=0,"","L=")) | Q79: =IF(O79="","",IF(O79=0,"","m")) | AC79: =IF(U74="",0,IF(U74>SUM(W74:AA79),U74-SUM(W74:AA79),0)) -> 0
B82: =IF(S82="","",IF(B74="","",1+B74)) | E82: =IF(F82="","",IF(F82=0,"","L=")) | H82: =IF(F82="","",IF(F82=0,"","m")) | K82: =IF(L82="","",IF(L82=0,"","L=")) | N82: =IF(L82="","",IF(L82=0,"","m")) | R82: =IF(OR(S82="入力ｴﾗｰ",S82=0,S82="")=TRUE,"",IF(F82="","甲",IF(F82=0,"甲",""))) | S82: =IF((F82+I87+L82+O87)=0,"",IF((F82+I87+L82+O87)>SUM($AC$1:$AC$3),"入力ｴﾗｰ",SUM($AC$1:$AC$3)-(F82+I87+L82+O87))) | T82: =IF(S82="","",IF(S82="入力ｴﾗｰ","","m")) | U82: =IF(B82="","",COUNT(F82,I87,L82,O87)-IF(S82=0,1,0)-V82)
R85: =IF(R82="甲","",IF(OR(S82=0,S82="")=TRUE,"",IF(S82="入力ｴﾗｰ","","乙")))
H87: =IF(I87="","",IF(I87=0,"","L=")) | K87: =IF(I87="","",IF(I87=0,"","m")) | N87: =IF(O87="","",IF(O87=0,"","L=")) | Q87: =IF(O87="","",IF(O87=0,"","m")) | AC87: =IF(U82="",0,IF(U82>SUM(W82:AA87),U82-SUM(W82:AA87),0)) -> 0
B90: =IF(S90="","",IF(B82="","",1+B82)) | E90: =IF(F90="","",IF(F90=0,"","L=")) | H90: =IF(F90="","",IF(F90=0,"","m")) | K90: =IF(L90="","",IF(L90=0,"","L=")) | N90: =IF(L90="","",IF(L90=0,"","m")) | R90: =IF(OR(S90="入力ｴﾗｰ",S90=0,S90="")=TRUE,"",IF(F90="","甲",IF(F90=0,"甲",""))) | S90: =IF((F90+I95+L90+O95)=0,"",IF((F90+I95+L90+O95)>SUM($AC$1:$AC$3),"入力ｴﾗｰ",SUM($AC$1:$AC$3)-(F90+I95+L90+O95))) | T90: =IF(S90="","",IF(S90="入力ｴﾗｰ","","m")) | U90: =IF(B90="","",COUNT(F90,I95,L90,O95)-IF(S90=0,1,0)-V90)
R93: =IF(R90="甲","",IF(OR(S90=0,S90="")=TRUE,"",IF(S90="入力ｴﾗｰ","","乙")))
H95: =IF(I95="","",IF(I95=0,"","L=")) | K95: =IF(I95="","",IF(I95=0,"","m")) | N95: =IF(O95="","",IF(O95=0,"","L=")) | Q95: =IF(O95="","",IF(O95=0,"","m")) | AC95: =IF(U90="",0,IF(U90>SUM(W90:AA95),U90-SUM(W90:AA95),0)) -> 0
B98: =IF(S98="","",IF(B90="","",1+B90)) | E98: =IF(F98="","",IF(F98=0,"","L=")) | H98: =IF(F98="","",IF(F98=0,"","m")) | K98: =IF(L98="","",IF(L98=0,"","L=")) | N98: =IF(L98="","",IF(L98=0,"","m")) | R98: =IF(OR(S98="入力ｴﾗｰ",S98=0,S98="")=TRUE,"",IF(F98="","甲",IF(F98=0,"甲",""))) | S98: =IF((F98+I103+L98+O103)=0,"",IF((F98+I103+L98+O103)>SUM($AC$1:$AC$3),"入力ｴﾗｰ",SUM($AC$1:$AC$3)-(F98+I103+L98+O103))) | T98: =IF(S98="","",IF(S98="入力ｴﾗｰ","","m")) | U98: =IF(B98="","",COUNT(F98,I103,L98,O103)-IF(S98=0,1,0)-V98)
...

Sheet GX　400
B1: 工事名： | C1: ='白紙(5m)'!C1 -> 東白川特2高層配水池揚水管取替工事 | S1: 管 | X1: 口 | AC1: =IF(Y2<=100,4,0) -> 0
U2: GX | Y2: 400 | AC2: =IF(AC1=4,0,IF(Y2<=250,5,0)) -> 0
S3: 種 | W3: 形 | X3: 径 | AA3: ㎜ | AC3: =IF(Y2>250,6,0) -> 6
B5: 管切断工・挿し口加工数量計算書 | U5: ※切管延長に挿し口リング延長を含む
B7: 管番号 | C7: 形 状 | R7: 残延長 | U7: 切断 | W7: 挿 し 口 加 工
U8: ＧＸ形 | V8: ＫＴ形 | W8: ＧＸ形 | X8: ＮＳ形 | Y8: ＫＦ形 | Z8: ＮＳ(溝) | AA8: ＳⅡ(溝)
B10: =IF(S10="","",1) -> 1 | E10: =IF(F10="","",IF(F10=0,"","L=")) -> L= | F10: 2.5 | H10: =IF(F10="","",IF(F10=0,"","m")) -> m | K10: =IF(L10="","",IF(L10=0,"","L=")) | N10: =IF(L10="","",IF(L10=0,"","m")) | R10: =IF(OR(S10="入力ｴﾗｰ",S10=0,S10="")=TRUE,"",IF(F10="","甲",IF(F10=0,"甲",""))) | S10: =IF((F10+I15+L10+O15)=0,"",IF((F10+I15+L10+O15)>SUM($AC$1:$AC$3),"入力ｴﾗｰ",SUM($AC$1:$AC$3)-(F10+I15+L10+O15))) -> 2.1 | T10: =IF(S10="","",IF(S10="入力ｴﾗｰ","","m")) -> m | U10: =IF(B10="","",COUNT(F10,I15,L10,O15)-IF(S10=0,1,0)-V10) -> 2 | W10: 2
R13: =IF(R10="甲","",IF(OR(S10=0,S10="")=TRUE,"",IF(S10="入力ｴﾗｰ","","乙"))) -> 乙
H15: =IF(I15="","",IF(I15=0,"","L=")) | K15: =IF(I15="","",IF(I15=0,"","m")) | N15: =IF(O15="","",IF(O15=0,"","L=")) -> L= | O15: 1.4 | Q15: =IF(O15="","",IF(O15=0,"","m")) -> m | AC15: =IF(U10="",0,IF(U10>SUM(W10:AA15),U10-SUM(W10:AA15),0)) -> 0
B18: =IF(S18="","",IF(B10="","",1+B10)) -> 2 | E18: =IF(F18="","",IF(F18=0,"","L=")) -> L= | F18: 5.6 | H18: =IF(F18="","",IF(F18=0,"","m")) -> m | K18: =IF(L18="","",IF(L18=0,"","L=")) | N18: =IF(L18="","",IF(L18=0,"","m")) | R18: =IF(OR(S18="入力ｴﾗｰ",S18=0,S18="")=TRUE,"",IF(F18="","甲",IF(F18=0,"甲",""))) | S18: =IF((F18+I23+L18+O23)=0,"",IF((F18+I23+L18+O23)>SUM($AC$1:$AC$3),"入力ｴﾗｰ",SUM($AC$1:$AC$3)-(F18+I23+L18+O23))) -> 0.4 | T18: =IF(S18="","",IF(S18="入力ｴﾗｰ","","m")) -> m | U18: =IF(B18="","",COUNT(F18,I23,L18,O23)-IF(S18=0,1,0)-V18) -> 1 | W18: 1
R21: =IF(R18="甲","",IF(OR(S18=0,S18="")=TRUE,"",IF(S18="入力ｴﾗｰ","","乙"))) -> 乙
H23: =IF(I23="","",IF(I23=0,"","L=")) | K23: =IF(I23="","",IF(I23=0,"","m")) | N23: =IF(O23="","",IF(O23=0,"","L=")) | Q23: =IF(O23="","",IF(O23=0,"","m")) | AC23: =IF(U18="",0,IF(U18>SUM(W18:AA23),U18-SUM(W18:AA23),0)) -> 0
B26: =IF(S26="","",IF(B18="","",1+B18)) -> 3 | E26: =IF(F26="","",IF(F26=0,"","L=")) -> L= | F26: 5.5 | H26: =IF(F26="","",IF(F26=0,"","m")) -> m | K26: =IF(L26="","",IF(L26=0,"","L=")) | N26: =IF(L26="","",IF(L26=0,"","m")) | R26: =IF(OR(S26="入力ｴﾗｰ",S26=0,S26="")=TRUE,"",IF(F26="","甲",IF(F26=0,"甲",""))) | S26: =IF((F26+I31+L26+O31)=0,"",IF((F26+I31+L26+O31)>SUM($AC$1:$AC$3),"入力ｴﾗｰ",SUM($AC$1:$AC$3)-(F26+I31+L26+O31))) -> 0.5 | T26: =IF(S26="","",IF(S26="入力ｴﾗｰ","","m")) -> m | U26: =IF(B26="","",COUNT(F26,I31,L26,O31)-IF(S26=0,1,0)-V26) -> 1 | W26: 1
R29: =IF(R26="甲","",IF(OR(S26=0,S26="")=TRUE,"",IF(S26="入力ｴﾗｰ","","乙"))) -> 乙
H31: =IF(I31="","",IF(I31=0,"","L=")) | K31: =IF(I31="","",IF(I31=0,"","m")) | N31: =IF(O31="","",IF(O31=0,"","L=")) | Q31: =IF(O31="","",IF(O31=0,"","m")) | AC31: =IF(U26="",0,IF(U26>SUM(W26:AA31),U26-SUM(W26:AA31),0)) -> 0
B34: =IF(S34="","",IF(B26="","",1+B26)) -> 4 | E34: =IF(F34="","",IF(F34=0,"","L=")) -> L= | F34: 1.9 | H34: =IF(F34="","",IF(F34=0,"","m")) -> m | K34: =IF(L34="","",IF(L34=0,"","L=")) | N34: =IF(L34="","",IF(L34=0,"","m")) | R34: =IF(OR(S34="入力ｴﾗｰ",S34=0,S34="")=TRUE,"",IF(F34="","甲",IF(F34=0,"甲",""))) | S34: =IF((F34+I39+L34+O39)=0,"",IF((F34+I39+L34+O39)>SUM($AC$1:$AC$3),"入力ｴﾗｰ",SUM($AC$1:$AC$3)-(F34+I39+L34+O39))) -> 2.5 | T34: =IF(S34="","",IF(S34="入力ｴﾗｰ","","m")) -> m | U34: =IF(B34="","",COUNT(F34,I39,L34,O39)-IF(S34=0,1,0)-V34) -> 2 | W34: 2
R37: =IF(R34="甲","",IF(OR(S34=0,S34="")=TRUE,"",IF(S34="入力ｴﾗｰ","","乙"))) -> 乙
H39: =IF(I39="","",IF(I39=0,"","L=")) | K39: =IF(I39="","",IF(I39=0,"","m")) | N39: =IF(O39="","",IF(O39=0,"","L=")) -> L= | O39: 1.6 | Q39: =IF(O39="","",IF(O39=0,"","m")) -> m | AC39: =IF(U34="",0,IF(U34>SUM(W34:AA39),U34-SUM(W34:AA39),0)) -> 0
B42: =IF(S42="","",IF(B34="","",1+B34)) -> 5 | E42: =IF(F42="","",IF(F42=0,"","L=")) -> L= | F42: 3.6 | H42: =IF(F42="","",IF(F42=0,"","m")) -> m | K42: =IF(L42="","",IF(L42=0,"","L=")) | N42: =IF(L42="","",IF(L42=0,"","m")) | R42: =IF(OR(S42="入力ｴﾗｰ",S42=0,S42="")=TRUE,"",IF(F42="","甲",IF(F42=0,"甲",""))) | S42: =IF((F42+I47+L42+O47)=0,"",IF((F42+I47+L42+O47)>SUM($AC$1:$AC$3),"入力ｴﾗｰ",SUM($AC$1:$AC$3)-(F42+I47+L42+O47))) -> 0.8 | T42: =IF(S42="","",IF(S42="入力ｴﾗｰ","","m")) -> m | U42: =IF(B42="","",COUNT(F42,I47,L42,O47)-IF(S42=0,1,0)-V42) -> 2 | W42: 2
R45: =IF(R42="甲","",IF(OR(S42=0,S42="")=TRUE,"",IF(S42="入力ｴﾗｰ","","乙"))) -> 乙
H47: =IF(I47="","",IF(I47=0,"","L=")) | K47: =IF(I47="","",IF(I47=0,"","m")) | N47: =IF(O47="","",IF(O47=0,"","L=")) -> L= | O47: 1.6 | Q47: =IF(O47="","",IF(O47=0,"","m")) -> m | AC47: =IF(U42="",0,IF(U42>SUM(W42:AA47),U42-SUM(W42:AA47),0)) -> 0
B50: =IF(S50="","",IF(B42="","",1+B42)) -> 6 | E50: =IF(F50="","",IF(F50=0,"","L=")) -> L= | F50: 2.8 | H50: =IF(F50="","",IF(F50=0,"","m")) -> m | K50: =IF(L50="","",IF(L50=0,"","L=")) | N50: =IF(L50="","",IF(L50=0,"","m")) | R50: =IF(OR(S50="入力ｴﾗｰ",S50=0,S50="")=TRUE,"",IF(F50="","甲",IF(F50=0,"甲",""))) | S50: =IF((F50+I55+L50+O55)=0,"",IF((F50+I55+L50+O55)>SUM($AC$1:$AC$3),"入力ｴﾗｰ",SUM($AC$1:$AC$3)-(F50+I55+L50+O55))) -> 2.1 | T50: =IF(S50="","",IF(S50="入力ｴﾗｰ","","m")) -> m | U50: =IF(B50="","",COUNT(F50,I55,L50,O55)-IF(S50=0,1,0)-V50) -> 2 | W50: 2
R53: =IF(R50="甲","",IF(OR(S50=0,S50="")=TRUE,"",IF(S50="入力ｴﾗｰ","","乙"))) -> 乙
H55: =IF(I55="","",IF(I55=0,"","L=")) | K55: =IF(I55="","",IF(I55=0,"","m")) | N55: =IF(O55="","",IF(O55=0,"","L=")) -> L= | O55: 1.1 | Q55: =IF(O55="","",IF(O55=0,"","m")) -> m | AC55: =IF(U50="",0,IF(U50>SUM(W50:AA55),U50-SUM(W50:AA55),0)) -> 0
B58: =IF(S58="","",IF(B50="","",1+B50)) -> 7 | E58: =IF(F58="","",IF(F58=0,"","L=")) -> L= | F58: 3.8 | H58: =IF(F58="","",IF(F58=0,"","m")) -> m | K58: =IF(L58="","",IF(L58=0,"","L=")) | N58: =IF(L58="","",IF(L58=0,"","m")) | R58: =IF(OR(S58="入力ｴﾗｰ",S58=0,S58="")=TRUE,"",IF(F58="","甲",IF(F58=0,"甲",""))) | S58: =IF((F58+I63+L58+O63)=0,"",IF((F58+I63+L58+O63)>SUM($AC$1:$AC$3),"入力ｴﾗｰ",SUM($AC$1:$AC$3)-(F58+I63+L58+O63))) -> 0.6 | T58: =IF(S58="","",IF(S58="入力ｴﾗｰ","","m")) -> m | U58: =IF(B58="","",COUNT(F58,I63,L58,O63)-IF(S58=0,1,0)-V58) -> 2 | W58: 2
R61: =IF(R58="甲","",IF(OR(S58=0,S58="")=TRUE,"",IF(S58="入力ｴﾗｰ","","乙"))) -> 乙
H63: =IF(I63="","",IF(I63=0,"","L=")) | K63: =IF(I63="","",IF(I63=0,"","m")) | N63: =IF(O63="","",IF(O63=0,"","L=")) -> L= | O63: 1.6 | Q63: =IF(O63="","",IF(O63=0,"","m")) -> m | AC63: =IF(U58="",0,IF(U58>SUM(W58:AA63),U58-SUM(W58:AA63),0)) -> 0
B66: =IF(S66="","",IF(B58="","",1+B58)) -> 8 | E66: =IF(F66="","",IF(F66=0,"","L=")) -> L= | F66: 2.2 | H66: =IF(F66="","",IF(F66=0,"","m")) -> m | K66: =IF(L66="","",IF(L66=0,"","L=")) | N66: =IF(L66="","",IF(L66=0,"","m")) | R66: =IF(OR(S66="入力ｴﾗｰ",S66=0,S66="")=TRUE,"",IF(F66="","甲",IF(F66=0,"甲",""))) | S66: =IF((F66+I71+L66+O71)=0,"",IF((F66+I71+L66+O71)>SUM($AC$1:$AC$3),"入力ｴﾗｰ",SUM($AC$1:$AC$3)-(F66+I71+L66+O71))) -> 2.7 | T66: =IF(S66="","",IF(S66="入力ｴﾗｰ","","m")) -> m | U66: =IF(B66="","",COUNT(F66,I71,L66,O71)-IF(S66=0,1,0)-V66) -> 2 | W66: 2
R69: =IF(R66="甲","",IF(OR(S66=0,S66="")=TRUE,"",IF(S66="入力ｴﾗｰ","","乙"))) -> 乙
H71: =IF(I71="","",IF(I71=0,"","L=")) | K71: =IF(I71="","",IF(I71=0,"","m")) | N71: =IF(O71="","",IF(O71=0,"","L=")) -> L= | O71: 1.1 | Q71: =IF(O71="","",IF(O71=0,"","m")) -> m | AC71: =IF(U66="",0,IF(U66>SUM(W66:AA71),U66-SUM(W66:AA71),0)) -> 0
B74: =IF(S74="","",IF(B66="","",1+B66)) -> 9 | E74: =IF(F74="","",IF(F74=0,"","L=")) -> L= | F74: 3.9 | H74: =IF(F74="","",IF(F74=0,"","m")) -> m | K74: =IF(L74="","",IF(L74=0,"","L=")) | N74: =IF(L74="","",IF(L74=0,"","m")) | R74: =IF(OR(S74="入力ｴﾗｰ",S74=0,S74="")=TRUE,"",IF(F74="","甲",IF(F74=0,"甲",""))) | S74: =IF((F74+I79+L74+O79)=0,"",IF((F74+I79+L74+O79)>SUM($AC$1:$AC$3),"入力ｴﾗｰ",SUM($AC$1:$AC$3)-(F74+I79+L74+O79))) -> 1 | T74: =IF(S74="","",IF(S74="入力ｴﾗｰ","","m")) -> m | U74: =IF(B74="","",COUNT(F74,I79,L74,O79)-IF(S74=0,1,0)-V74) -> 2 | W74: 2
R77: =IF(R74="甲","",IF(OR(S74=0,S74="")=TRUE,"",IF(S74="入力ｴﾗｰ","","乙"))) -> 乙
H79: =IF(I79="","",IF(I79=0,"","L=")) | K79: =IF(I79="","",IF(I79=0,"","m")) | N79: =IF(O79="","",IF(O79=0,"","L=")) -> L= | O79: 1.1 | Q79: =IF(O79="","",IF(O79=0,"","m")) -> m | AC79: =IF(U74="",0,IF(U74>SUM(W74:AA79),U74-SUM(W74:AA79),0)) -> 0
B82: =IF(S82="","",IF(B74="","",1+B74)) -> 10 | E82: =IF(F82="","",IF(F82=0,"","L=")) -> L= | F82: 2.3 | H82: =IF(F82="","",IF(F82=0,"","m")) -> m | K82: =IF(L82="","",IF(L82=0,"","L=")) | N82: =IF(L82="","",IF(L82=0,"","m")) | R82: =IF(OR(S82="入力ｴﾗｰ",S82=0,S82="")=TRUE,"",IF(F82="","甲",IF(F82=0,"甲",""))) | S82: =IF((F82+I87+L82+O87)=0,"",IF((F82+I87+L82+O87)>SUM($AC$1:$AC$3),"入力ｴﾗｰ",SUM($AC$1:$AC$3)-(F82+I87+L82+O87))) -> 3.7 | T82: =IF(S82="","",IF(S82="入力ｴﾗｰ","","m")) -> m | U82: =IF(B82="","",COUNT(F82,I87,L82,O87)-IF(S82=0,1,0)-V82) -> 1 | W82: 1
R85: =IF(R82="甲","",IF(OR(S82=0,S82="")=TRUE,"",IF(S82="入力ｴﾗｰ","","乙"))) -> 乙
H87: =IF(I87="","",IF(I87=0,"","L=")) | K87: =IF(I87="","",IF(I87=0,"","m")) | N87: =IF(O87="","",IF(O87=0,"","L=")) | Q87: =IF(O87="","",IF(O87=0,"","m")) | AC87: =IF(U82="",0,IF(U82>SUM(W82:AA87),U82-SUM(W82:AA87),0)) -> 0
B90: =IF(S90="","",IF(B82="","",1+B82)) -> 11 | E90: =IF(F90="","",IF(F90=0,"","L=")) -> L= | F90: 3.3 | H90: =IF(F90="","",IF(F90=0,"","m")) -> m | K90: =IF(L90="","",IF(L90=0,"","L=")) | N90: =IF(L90="","",IF(L90=0,"","m")) | R90: =IF(OR(S90="入力ｴﾗｰ",S90=0,S90="")=TRUE,"",IF(F90="","甲",IF(F90=0,"甲",""))) | S90: =IF((F90+I95+L90+O95)=0,"",IF((F90+I95+L90+O95)>SUM($AC$1:$AC$3),"入力ｴﾗｰ",SUM($AC$1:$AC$3)-(F90+I95+L90+O95))) -> 2.7 | T90: =IF(S90="","",IF(S90="入力ｴﾗｰ","","m")) -> m | U90: =IF(B90="","",COUNT(F90,I95,L90,O95)-IF(S90=0,1,0)-V90) -> 1 | W90: 1
R93: =IF(R90="甲","",IF(OR(S90=0,S90="")=TRUE,"",IF(S90="入力ｴﾗｰ","","乙"))) -> 乙
H95: =IF(I95="","",IF(I95=0,"","L=")) | K95: =IF(I95="","",IF(I95=0,"","m")) | N95: =IF(O95="","",IF(O95=0,"","L=")) | Q95: =IF(O95="","",IF(O95=0,"","m")) | AC95: =IF(U90="",0,IF(U90>SUM(W90:AA95),U90-SUM(W90:AA95),0)) -> 0
B98: =IF(S98="","",IF(B90="","",1+B90)) -> 12 | E98: =IF(F98="","",IF(F98=0,"","L=")) -> L= | F98: 4 | H98: =IF(F98="","",IF(F98=0,"","m")) -> m | K98: =IF(L98="","",IF(L98=0,"","L=")) | N98: =IF(L98="","",IF(L98=0,"","m")) | R98: =IF(OR(S98="入力ｴﾗｰ",S98=0,S98="")=TRUE,"",IF(F98="","甲",IF(F98=0,"甲",""))) | S98: =IF((F98+I103+L98+O103)=0,"",IF((F98+I103+L98+O103)>SUM($AC$1:$AC$3),"入力ｴﾗｰ",SUM($AC$1:$AC$3)-(F98+I103+L98+O103))) -> 2 | T98: =IF(S98="","",IF(S98="入力ｴﾗｰ","","m")) -> m | U98: =IF(B98="","",COUNT(F98,I103,L98,O103)-IF(S98=0,1,0)-V98) -> 1 | W98: 1
...

Sheet GX　400 (2)
B1: 工事名： | C1: ='白紙(5m)'!C1 -> 東白川特2高層配水池揚水管取替工事 | S1: 管 | X1: 口 | AC1: =IF(Y2<=100,4,0) -> 0
U2: GX | Y2: 400 | AC2: =IF(AC1=4,0,IF(Y2<=250,5,0)) -> 0
S3: 種 | W3: 形 | X3: 径 | AA3: ㎜ | AC3: =IF(Y2>250,6,0) -> 6
B5: 管切断工・挿し口加工数量計算書 | U5: ※切管延長に挿し口リング延長を含む
B7: 管番号 | C7: 形 状 | R7: 残延長 | U7: 切断 | W7: 挿 し 口 加 工
U8: ＧＸ形 | V8: ＫＴ形 | W8: ＧＸ形 | X8: ＮＳ形 | Y8: ＫＦ形 | Z8: ＮＳ(溝) | AA8: ＳⅡ(溝)
B10: =IF(S10="","",1)+13 -> 14 | E10: =IF(F10="","",IF(F10=0,"","L=")) -> L= | F10: 2 | H10: =IF(F10="","",IF(F10=0,"","m")) -> m | K10: =IF(L10="","",IF(L10=0,"","L=")) | N10: =IF(L10="","",IF(L10=0,"","m")) | R10: =IF(OR(S10="入力ｴﾗｰ",S10=0,S10="")=TRUE,"",IF(F10="","甲",IF(F10=0,"甲",""))) | S10: =IF((F10+I15+L10+O15)=0,"",IF((F10+I15+L10+O15)>SUM($AC$1:$AC$3),"入力ｴﾗｰ",SUM($AC$1:$AC$3)-(F10+I15+L10+O15))) -> 4 | T10: =IF(S10="","",IF(S10="入力ｴﾗｰ","","m")) -> m | U10: =IF(B10="","",COUNT(F10,I15,L10,O15)-IF(S10=0,1,0)-V10) -> 1 | W10: 1
R13: =IF(R10="甲","",IF(OR(S10=0,S10="")=TRUE,"",IF(S10="入力ｴﾗｰ","","乙"))) -> 乙
H15: =IF(I15="","",IF(I15=0,"","L=")) | K15: =IF(I15="","",IF(I15=0,"","m")) | N15: =IF(O15="","",IF(O15=0,"","L=")) | Q15: =IF(O15="","",IF(O15=0,"","m")) | AC15: =IF(U10="",0,IF(U10>SUM(W10:AA15),U10-SUM(W10:AA15),0)) -> 0
B18: =IF(S18="","",IF(B10="","",1+B10)) -> 15 | E18: =IF(F18="","",IF(F18=0,"","L=")) -> L= | F18: 3.3 | H18: =IF(F18="","",IF(F18=0,"","m")) -> m | K18: =IF(L18="","",IF(L18=0,"","L=")) | N18: =IF(L18="","",IF(L18=0,"","m")) | R18: =IF(OR(S18="入力ｴﾗｰ",S18=0,S18="")=TRUE,"",IF(F18="","甲",IF(F18=0,"甲",""))) | S18: =IF((F18+I23+L18+O23)=0,"",IF((F18+I23+L18+O23)>SUM($AC$1:$AC$3),"入力ｴﾗｰ",SUM($AC$1:$AC$3)-(F18+I23+L18+O23))) -> 2.7 | T18: =IF(S18="","",IF(S18="入力ｴﾗｰ","","m")) -> m | U18: =IF(B18="","",COUNT(F18,I23,L18,O23)-IF(S18=0,1,0)-V18) -> 1 | W18: 1
R21: =IF(R18="甲","",IF(OR(S18=0,S18="")=TRUE,"",IF(S18="入力ｴﾗｰ","","乙"))) -> 乙
H23: =IF(I23="","",IF(I23=0,"","L=")) | K23: =IF(I23="","",IF(I23=0,"","m")) | N23: =IF(O23="","",IF(O23=0,"","L=")) | Q23: =IF(O23="","",IF(O23=0,"","m")) | AC23: =IF(U18="",0,IF(U18>SUM(W18:AA23),U18-SUM(W18:AA23),0)) -> 0
B26: =IF(S26="","",IF(B18="","",1+B18)) -> 16 | E26: =IF(F26="","",IF(F26=0,"","L=")) -> L= | F26: 5.1 | H26: =IF(F26="","",IF(F26=0,"","m")) -> m | K26: =IF(L26="","",IF(L26=0,"","L=")) | N26: =IF(L26="","",IF(L26=0,"","m")) | R26: =IF(OR(S26="入力ｴﾗｰ",S26=0,S26="")=TRUE,"",IF(F26="","甲",IF(F26=0,"甲",""))) | S26: =IF((F26+I31+L26+O31)=0,"",IF((F26+I31+L26+O31)>SUM($AC$1:$AC$3),"入力ｴﾗｰ",SUM($AC$1:$AC$3)-(F26+I31+L26+O31))) -> 0.9 | T26: =IF(S26="","",IF(S26="入力ｴﾗｰ","","m")) -> m | U26: =IF(B26="","",COUNT(F26,I31,L26,O31)-IF(S26=0,1,0)-V26) -> 1 | W26: 1
R29: =IF(R26="甲","",IF(OR(S26=0,S26="")=TRUE,"",IF(S26="入力ｴﾗｰ","","乙"))) -> 乙
H31: =IF(I31="","",IF(I31=0,"","L=")) | K31: =IF(I31="","",IF(I31=0,"","m")) | N31: =IF(O31="","",IF(O31=0,"","L=")) | Q31: =IF(O31="","",IF(O31=0,"","m")) | AC31: =IF(U26="",0,IF(U26>SUM(W26:AA31),U26-SUM(W26:AA31),0)) -> 0
B34: =IF(S34="","",IF(B26="","",1+B26)) -> 17 | E34: =IF(F34="","",IF(F34=0,"","L=")) -> L= | F34: 2.39 | H34: =IF(F34="","",IF(F34=0,"","m")) -> m | K34: =IF(L34="","",IF(L34=0,"","L=")) | N34: =IF(L34="","",IF(L34=0,"","m")) | R34: =IF(OR(S34="入力ｴﾗｰ",S34=0,S34="")=TRUE,"",IF(F34="","甲",IF(F34=0,"甲",""))) | S34: =IF((F34+I39+L34+O39)=0,"",IF((F34+I39+L34+O39)>SUM($AC$1:$AC$3),"入力ｴﾗｰ",SUM($AC$1:$AC$3)-(F34+I39+L34+O39))) -> 3.61 | T34: =IF(S34="","",IF(S34="入力ｴﾗｰ","","m")) -> m | U34: =IF(B34="","",COUNT(F34,I39,L34,O39)-IF(S34=0,1,0)-V34) -> 1 | W34: 1
R37: =IF(R34="甲","",IF(OR(S34=0,S34="")=TRUE,"",IF(S34="入力ｴﾗｰ","","乙"))) -> 乙
H39: =IF(I39="","",IF(I39=0,"","L=")) | K39: =IF(I39="","",IF(I39=0,"","m")) | N39: =IF(O39="","",IF(O39=0,"","L=")) | Q39: =IF(O39="","",IF(O39=0,"","m")) | AC39: =IF(U34="",0,IF(U34>SUM(W34:AA39),U34-SUM(W34:AA39),0)) -> 0
B42: =IF(S42="","",IF(B34="","",1+B34)) -> 18 | E42: =IF(F42="","",IF(F42=0,"","L=")) -> L= | F42: 4.42 | H42: =IF(F42="","",IF(F42=0,"","m")) -> m | K42: =IF(L42="","",IF(L42=0,"","L=")) | N42: =IF(L42="","",IF(L42=0,"","m")) | R42: =IF(OR(S42="入力ｴﾗｰ",S42=0,S42="")=TRUE,"",IF(F42="","甲",IF(F42=0,"甲",""))) | S42: =IF((F42+I47+L42+O47)=0,"",IF((F42+I47+L42+O47)>SUM($AC$1:$AC$3),"入力ｴﾗｰ",SUM($AC$1:$AC$3)-(F42+I47+L42+O47))) -> 1.58 | T42: =IF(S42="","",IF(S42="入力ｴﾗｰ","","m")) -> m | U42: =IF(B42="","",COUNT(F42,I47,L42,O47)-IF(S42=0,1,0)-V42) -> 1 | W42: 1
R45: =IF(R42="甲","",IF(OR(S42=0,S42="")=TRUE,"",IF(S42="入力ｴﾗｰ","","乙"))) -> 乙
H47: =IF(I47="","",IF(I47=0,"","L=")) | K47: =IF(I47="","",IF(I47=0,"","m")) | N47: =IF(O47="","",IF(O47=0,"","L=")) | Q47: =IF(O47="","",IF(O47=0,"","m")) | AC47: =IF(U42="",0,IF(U42>SUM(W42:AA47),U42-SUM(W42:AA47),0)) -> 0
B50: =IF(S50="","",IF(B42="","",1+B42)) -> 19 | E50: =IF(F50="","",IF(F50=0,"","L=")) -> L= | F50: 4 | H50: =IF(F50="","",IF(F50=0,"","m")) -> m | K50: =IF(L50="","",IF(L50=0,"","L=")) | N50: =IF(L50="","",IF(L50=0,"","m")) | R50: =IF(OR(S50="入力ｴﾗｰ",S50=0,S50="")=TRUE,"",IF(F50="","甲",IF(F50=0,"甲",""))) | S50: =IF((F50+I55+L50+O55)=0,"",IF((F50+I55+L50+O55)>SUM($AC$1:$AC$3),"入力ｴﾗｰ",SUM($AC$1:$AC$3)-(F50+I55+L50+O55))) -> 2 | T50: =IF(S50="","",IF(S50="入力ｴﾗｰ","","m")) -> m | U50: =IF(B50="","",COUNT(F50,I55,L50,O55)-IF(S50=0,1,0)-V50) -> 1 | W50: 1
R53: =IF(R50="甲","",IF(OR(S50=0,S50="")=TRUE,"",IF(S50="入力ｴﾗｰ","","乙"))) -> 乙
H55: =IF(I55="","",IF(I55=0,"","L=")) | K55: =IF(I55="","",IF(I55=0,"","m")) | N55: =IF(O55="","",IF(O55=0,"","L=")) | Q55: =IF(O55="","",IF(O55=0,"","m")) | AC55: =IF(U50="",0,IF(U50>SUM(W50:AA55),U50-SUM(W50:AA55),0)) -> 0
B58: =IF(S58="","",IF(B50="","",1+B50)) -> 20 | E58: =IF(F58="","",IF(F58=0,"","L=")) -> L= | F58: 3.5 | H58: =IF(F58="","",IF(F58=0,"","m")) -> m | K58: =IF(L58="","",IF(L58=0,"","L=")) | N58: =IF(L58="","",IF(L58=0,"","m")) | R58: =IF(OR(S58="入力ｴﾗｰ",S58=0,S58="")=TRUE,"",IF(F58="","甲",IF(F58=0,"甲",""))) | S58: =IF((F58+I63+L58+O63)=0,"",IF((F58+I63+L58+O63)>SUM($AC$1:$AC$3),"入力ｴﾗｰ",SUM($AC$1:$AC$3)-(F58+I63+L58+O63))) -> 2.5 | T58: =IF(S58="","",IF(S58="入力ｴﾗｰ","","m")) -> m | U58: =IF(B58="","",COUNT(F58,I63,L58,O63)-IF(S58=0,1,0)-V58) -> 1 | W58: 1
R61: =IF(R58="甲","",IF(OR(S58=0,S58="")=TRUE,"",IF(S58="入力ｴﾗｰ","","乙"))) -> 乙
H63: =IF(I63="","",IF(I63=0,"","L=")) | K63: =IF(I63="","",IF(I63=0,"","m")) | N63: =IF(O63="","",IF(O63=0,"","L=")) | Q63: =IF(O63="","",IF(O63=0,"","m")) | AC63: =IF(U58="",0,IF(U58>SUM(W58:AA63),U58-SUM(W58:AA63),0)) -> 0
B66: =IF(S66="","",IF(B58="","",1+B58)) -> 21 | E66: =IF(F66="","",IF(F66=0,"","L=")) -> L= | F66: 3.4 | H66: =IF(F66="","",IF(F66=0,"","m")) -> m | K66: =IF(L66="","",IF(L66=0,"","L=")) | N66: =IF(L66="","",IF(L66=0,"","m")) | R66: =IF(OR(S66="入力ｴﾗｰ",S66=0,S66="")=TRUE,"",IF(F66="","甲",IF(F66=0,"甲",""))) | S66: =IF((F66+I71+L66+O71)=0,"",IF((F66+I71+L66+O71)>SUM($AC$1:$AC$3),"入力ｴﾗｰ",SUM($AC$1:$AC$3)-(F66+I71+L66+O71))) -> 2.6 | T66: =IF(S66="","",IF(S66="入力ｴﾗｰ","","m")) -> m | U66: =IF(B66="","",COUNT(F66,I71,L66,O71)-IF(S66=0,1,0)-V66) -> 1 | W66: 1
R69: =IF(R66="甲","",IF(OR(S66=0,S66="")=TRUE,"",IF(S66="入力ｴﾗｰ","","乙"))) -> 乙
H71: =IF(I71="","",IF(I71=0,"","L=")) | K71: =IF(I71="","",IF(I71=0,"","m")) | N71: =IF(O71="","",IF(O71=0,"","L=")) | Q71: =IF(O71="","",IF(O71=0,"","m")) | AC71: =IF(U66="",0,IF(U66>SUM(W66:AA71),U66-SUM(W66:AA71),0)) -> 0
B74: =IF(S74="","",IF(B66="","",1+B66)) -> 22 | E74: =IF(F74="","",IF(F74=0,"","L=")) -> L= | F74: 2.2 | H74: =IF(F74="","",IF(F74=0,"","m")) -> m | K74: =IF(L74="","",IF(L74=0,"","L=")) | N74: =IF(L74="","",IF(L74=0,"","m")) | R74: =IF(OR(S74="入力ｴﾗｰ",S74=0,S74="")=TRUE,"",IF(F74="","甲",IF(F74=0,"甲",""))) | S74: =IF((F74+I79+L74+O79)=0,"",IF((F74+I79+L74+O79)>SUM($AC$1:$AC$3),"入力ｴﾗｰ",SUM($AC$1:$AC$3)-(F74+I79+L74+O79))) -> 3.8 | T74: =IF(S74="","",IF(S74="入力ｴﾗｰ","","m")) -> m | U74: =IF(B74="","",COUNT(F74,I79,L74,O79)-IF(S74=0,1,0)-V74) -> 1 | W74: 1
R77: =IF(R74="甲","",IF(OR(S74=0,S74="")=TRUE,"",IF(S74="入力ｴﾗｰ","","乙"))) -> 乙
H79: =IF(I79="","",IF(I79=0,"","L=")) | K79: =IF(I79="","",IF(I79=0,"","m")) | N79: =IF(O79="","",IF(O79=0,"","L=")) | Q79: =IF(O79="","",IF(O79=0,"","m")) | AC79: =IF(U74="",0,IF(U74>SUM(W74:AA79),U74-SUM(W74:AA79),0)) -> 0
B82: =IF(S82="","",IF(B74="","",1+B74)) -> 23 | E82: =IF(F82="","",IF(F82=0,"","L=")) -> L= | F82: 4 | H82: =IF(F82="","",IF(F82=0,"","m")) -> m | K82: =IF(L82="","",IF(L82=0,"","L=")) | N82: =IF(L82="","",IF(L82=0,"","m")) | R82: =IF(OR(S82="入力ｴﾗｰ",S82=0,S82="")=TRUE,"",IF(F82="","甲",IF(F82=0,"甲",""))) | S82: =IF((F82+I87+L82+O87)=0,"",IF((F82+I87+L82+O87)>SUM($AC$1:$AC$3),"入力ｴﾗｰ",SUM($AC$1:$AC$3)-(F82+I87+L82+O87))) -> 2 | T82: =IF(S82="","",IF(S82="入力ｴﾗｰ","","m")) -> m | U82: =IF(B82="","",COUNT(F82,I87,L82,O87)-IF(S82=0,1,0)-V82) -> 1 | W82: 1
R85: =IF(R82="甲","",IF(OR(S82=0,S82="")=TRUE,"",IF(S82="入力ｴﾗｰ","","乙"))) -> 乙
H87: =IF(I87="","",IF(I87=0,"","L=")) | K87: =IF(I87="","",IF(I87=0,"","m")) | N87: =IF(O87="","",IF(O87=0,"","L=")) | Q87: =IF(O87="","",IF(O87=0,"","m")) | AC87: =IF(U82="",0,IF(U82>SUM(W82:AA87),U82-SUM(W82:AA87),0)) -> 0
B90: =IF(S90="","",IF(B82="","",1+B82)) -> 24 | E90: =IF(F90="","",IF(F90=0,"","L=")) -> L= | F90: 1.6 | H90: =IF(F90="","",IF(F90=0,"","m")) -> m | K90: =IF(L90="","",IF(L90=0,"","L=")) | N90: =IF(L90="","",IF(L90=0,"","m")) | R90: =IF(OR(S90="入力ｴﾗｰ",S90=0,S90="")=TRUE,"",IF(F90="","甲",IF(F90=0,"甲",""))) | S90: =IF((F90+I95+L90+O95)=0,"",IF((F90+I95+L90+O95)>SUM($AC$1:$AC$3),"入力ｴﾗｰ",SUM($AC$1:$AC$3)-(F90+I95+L90+O95))) -> 4.4 | T90: =IF(S90="","",IF(S90="入力ｴﾗｰ","","m")) -> m | U90: =IF(B90="","",COUNT(F90,I95,L90,O95)-IF(S90=0,1,0)-V90) -> 1 | W90: 1
R93: =IF(R90="甲","",IF(OR(S90=0,S90="")=TRUE,"",IF(S90="入力ｴﾗｰ","","乙"))) -> 乙
H95: =IF(I95="","",IF(I95=0,"","L=")) | K95: =IF(I95="","",IF(I95=0,"","m")) | N95: =IF(O95="","",IF(O95=0,"","L=")) | Q95: =IF(O95="","",IF(O95=0,"","m")) | AC95: =IF(U90="",0,IF(U90>SUM(W90:AA95),U90-SUM(W90:AA95),0)) -> 0
B98: =IF(S98="","",IF(B90="","",1+B90)) -> 25 | E98: =IF(F98="","",IF(F98=0,"","L=")) -> L= | F98: 3.8 | H98: =IF(F98="","",IF(F98=0,"","m")) -> m | K98: =IF(L98="","",IF(L98=0,"","L=")) | N98: =IF(L98="","",IF(L98=0,"","m")) | R98: =IF(OR(S98="入力ｴﾗｰ",S98=0,S98="")=TRUE,"",IF(F98="","甲",IF(F98=0,"甲",""))) | S98: =IF((F98+I103+L98+O103)=0,"",IF((F98+I103+L98+O103)>SUM($AC$1:$AC$3),"入力ｴﾗｰ",SUM($AC$1:$AC$3)-(F98+I103+L98+O103))) -> 2.2 | T98: =IF(S98="","",IF(S98="入力ｴﾗｰ","","m")) -> m | U98: =IF(B98="","",COUNT(F98,I103,L98,O103)-IF(S98=0,1,0)-V98) -> 1 | W98: 1
...

Sheet GX　400 (3)
B1: 工事名： | C1: ='白紙(5m)'!C1 -> 東白川特2高層配水池揚水管取替工事 | S1: 管 | X1: 口 | AC1: =IF(Y2<=100,4,0) -> 0
U2: GX | Y2: 400 | AC2: =IF(AC1=4,0,IF(Y2<=250,5,0)) -> 0
S3: 種 | W3: 形 | X3: 径 | AA3: ㎜ | AC3: =IF(Y2>250,6,0) -> 6
B5: 管切断工・挿し口加工数量計算書 | U5: ※切管延長に挿し口リング延長を含む
B7: 管番号 | C7: 形 状 | R7: 残延長 | U7: 切断 | W7: 挿 し 口 加 工
U8: ＧＸ形 | V8: ＫＴ形 | W8: ＧＸ形 | X8: ＮＳ形 | Y8: ＫＦ形 | Z8: ＮＳ(溝) | AA8: ＳⅡ(溝)
