Workbook
Name 掘削幅: 延長表!$AG$6:$AI$18
Name 掘削幅矢板: 延長表!$AJ$6:$AL$18
Name 範囲1: #REF!
Name 範囲1: #REF!
Name 範囲2: #REF!
Name 範囲2: #REF!
Name 範囲３: #REF!
Name 範囲３: #REF!
Name 範囲４: #REF!
Name 範囲４: #REF!

Sheet 表紙
B1: 7
B2: 工事名： | C2: 東白川特2高層配水池揚水管取替工事
C3: 事業名： | D3: 基幹施設整備事業
C4: 工事番号： | D4: 5070281
A5: 数 量 計 算 書
B6: 工事場所： | C6: 神戸市須磨区東白川台他

Sheet 総括表（土工事）
J1: =入力セル（各数量計算書の数量を転記間違いないように！）
J2: =この表内でﾘﾝｸ入力されてるセル
B3: 数量総括表（土工事-1）
B4: 配 水 管 土 工 事
B6: =表紙!C2 -> 東白川特2高層配水池揚水管取替工事
B7: 名 称 | E7: 摘 要 | J7: 試 掘 （PE50-300)新設 （PE50-PE75） 取替 | K7: 試 掘 （200-300） 新設 | L7: 試 掘 （75-300） 取替・撤去 | M7: 試 掘 （400-500） | N7: 試 掘 （600以上） | O7: 給水2度 | P7: 仮配管 | Q7: 給水付替 | R7: 管工事 （PE50-300)新設 （PE50-PE75）取替 | S7: 管工事 （75-300） 取替・撤去 | T7: 管工事 （400-500） | U7: 管工事 （600以上） | V7: 舗 装 | W7: 付帯工 | X7: 夜間 | Y7: 計 | Z7: 設計書 | AB7: 数値基準
AB8: 0.1 | AC8: 1 | AD8: 10 | AE8: 100
B9: 舗装切断工 （管工事） | E9: As舗装 | H9: t≦15㎝ | J9: ='試掘（舗50'!P4 -> 3.6 | M9: ='試掘（舗400'!P4 -> 110 | R9: ='管工（舗50'!T10 -> 90.41 | S9: ='管工（舗75'!T10 -> 2900.2 | T9: ='管工（舗400'!T10 -> 2156.46 | Y9: =SUM(J9:X9) -> 5260.67 | Z9: =SUM(AB9:AE9) -> 5260 | AB9: =IF($Y9<1,ROUND($Y9,1),0) -> 0 | AC9: =IF(AND($Y9>=1,$Y9<100),ROUND($Y9,0),0) -> 0 | AD9: =IF($Y9>=100,ROUND($Y9,-1),0) -> 5260
E10: As舗装 | H10: 15㎝<t≦30㎝ | Y10: =SUM(J10:X10) -> 0 | Z10: =SUM(AB10:AE10) -> 0 | AB10: =IF($Y10<1,ROUND($Y10,1),0) -> 0 | AC10: =IF(AND($Y10>=1,$Y10<100),ROUND($Y10,0),0) -> 0 | AD10: =IF($Y10>=100,ROUND($Y10,-1),0) -> 0
E11: Co舗装 | H11: t≦15㎝ | M11: ='試掘（舗400'!S4 -> 4 | S11: ='管工（舗75'!X10 -> 132.2 | T11: ='管工（舗400'!X10 -> 67.4 | Y11: =SUM(J11:X11) -> 203.6 | Z11: =SUM(AB11:AE11) -> 200 | AB11: =IF($Y11<1,ROUND($Y11,1),0) -> 0 | AC11: =IF(AND($Y11>=1,$Y11<100),ROUND($Y11,0),0) -> 0 | AD11: =IF($Y11>=100,ROUND($Y11,-1),0) -> 200
E12: Co舗装 | H12: 15㎝<t≦30㎝ | Y12: =SUM(J12:X12) -> 0 | Z12: =SUM(AB12:AE12) -> 0 | AB12: =IF($Y12<1,ROUND($Y12,1),0) -> 0 | AC12: =IF(AND($Y12>=1,$Y12<100),ROUND($Y12,0),0) -> 0 | AD12: =IF($Y12>=100,ROUND($Y12,-1),0) -> 0
B13: 舗 装 版 破 砕 （ 管 工 事 ） | C13: 人力 | E13: Ａｓ | F13: 4cm以下 | I13: 4 | J13: ='試掘（舗50'!P11 -> 0.6 | M13: ='試掘（舗400'!P11 -> 1 | Y13: =SUM(J13:X13) -> 1.6 | Z13: =SUM(AB13:AE13) -> 2 | AB13: =IF($Y13<1,ROUND($Y13,1),0) -> 0 | AC13: =IF(AND($Y13>=1,$Y13<1000),ROUND($Y13,0),0) -> 2 | AD13: =IF($Y13>=1000,ROUND($Y13,-1),0) -> 0
F14: 10㎝以下 | I14: 5 | J14: ='試掘（舗50'!P12 -> 1.2 | Y14: =SUM(J14:X14) -> 1.2 | Z14: =SUM(AC14:AE14) -> 0
I15: 10 | M15: ='試掘（舗400'!P12 -> 50 | Y15: =SUM(J15:X15) -> 50 | Z15: =SUM(AC15:AE15) -> 0
Y16: =SUM(J16:X16) -> 0 | Z16: =SUM(AC16:AE16) -> 0
H17: 計 | Y17: =SUM(Y14:Y16) -> 51.2 | Z17: =SUM(AB17:AE17) -> 51 | AB17: =IF($Y17<1,ROUND($Y17,1),0) -> 0 | AC17: =IF(AND($Y17>=1,$Y17<1000),ROUND($Y17,0),0) -> 51 | AD17: =IF($Y17>=1000,ROUND($Y17,-1),0) -> 0
F18: 15㎝以下 | I18: 14 | Y18: =SUM(J18:X18) -> 0 | Z18: =SUM(AC18:AE18) -> 0
I19: 15 | M19: ='試掘（舗400'!P13 -> 4 | Y19: =SUM(J19:X19) -> 4 | Z19: =SUM(AC19:AE19) -> 0
H20: 計 | Y20: =SUM(Y18:Y19) -> 4 | Z20: =SUM(AB20:AE20) -> 4 | AB20: =IF($Y20<1,ROUND($Y20,1),0) -> 0 | AC20: =IF(AND($Y20>=1,$Y20<1000),ROUND($Y20,0),0) -> 4 | AD20: =IF($Y20>=1000,ROUND($Y20,-1),0) -> 0
F21: 15㎝超 | I21: 20 | Y21: =SUM(J21:X21) -> 0 | Z21: =SUM(AB21:AE21) -> 0 | AB21: =IF($Y21<1,ROUND($Y21,1),0) -> 0 | AC21: =IF(AND($Y21>=1,$Y21<1000),ROUND($Y21,0),0) -> 0 | AD21: =IF($Y21>=1000,ROUND($Y21,-1),0) -> 0
E22: Ｃｏ | F22: 4cm以下 | I22: 4 | Y22: =SUM(J22:X22) -> 0 | Z22: =SUM(AB22:AE22) -> 0 | AB22: =IF($Y22<1,ROUND($Y22,1),0) -> 0 | AC22: =IF(AND($Y22>=1,$Y22<1000),ROUND($Y22,0),0) -> 0 | AD22: =IF($Y22>=1000,ROUND($Y22,-1),0) -> 0
F23: 10cm以下 | I23: 8 | Y23: =SUM(J23:X23) -> 0 | Z23: =SUM(AB23:AE23) -> 0 | AB23: =IF($Y23<1,ROUND($Y23,1),0) -> 0 | AC23: =IF(AND($Y23>=1,$Y23<1000),ROUND($Y23,0),0) -> 0 | AD23: =IF($Y23>=1000,ROUND($Y23,-1),0) -> 0
F24: 15cm以下 | I24: 15 | M24: ='試掘（舗400'!S11 -> 2 | Y24: =SUM(J24:X24) -> 2 | Z24: =SUM(AB24:AE24) -> 2 | AB24: =IF($Y24<1,ROUND($Y24,1),0) -> 0 | AC24: =IF(AND($Y24>=1,$Y24<1000),ROUND($Y24,0),0) -> 2 | AD24: =IF($Y24>=1000,ROUND($Y24,-1),0) -> 0
F25: 15㎝超 | I25: 20 | Y25: =SUM(J25:X25) -> 0 | Z25: =SUM(AB25:AE25) -> 0 | AB25: =IF($Y25<1,ROUND($Y25,1),0) -> 0 | AC25: =IF(AND($Y25>=1,$Y25<1000),ROUND($Y25,0),0) -> 0 | AD25: =IF($Y25>=1000,ROUND($Y25,-1),0) -> 0
C26: 機械 | E26: As ・ Co | F26: 10cm以下 | I26: 4 | Y26: =SUM(J26:X26) -> 0 | Z26: =SUM(AC26:AE26) -> 0
I27: 5 | Y27: =SUM(J27:X27) -> 0 | Z27: =SUM(AC27:AE27) -> 0
I28: 10 | Y28: =SUM(J28:X28) -> 0 | Z28: =SUM(AC28:AE28) -> 0
Y29: =SUM(J29:X29) -> 0 | Z29: =SUM(AC29:AE29) -> 0
I30: 計 | Y30: =SUM(Y26:Y29) -> 0 | Z30: =SUM(AB30:AE30) -> 0 | AB30: =IF($Y30<1,ROUND($Y30,1),0) -> 0 | AC30: =IF(AND($Y30>=1,$Y30<1000),ROUND($Y30,0),0) -> 0 | AD30: =IF($Y30>=1000,ROUND($Y30,-1),0) -> 0
I31: 4 | R31: ='管工（舗50'!T16 -> 4.75 | Y31: =SUM(J31:X31) -> 4.75 | Z31: =SUM(AC31:AE31) -> 0
I32: 5 | R32: ='管工（舗50'!T17 -> 1.2 | Y32: =SUM(J32:X32) -> 1.2 | Z32: =SUM(AC32:AE32) -> 0
I33: 10 | R33: ='管工（舗50'!T18 -> 21.8 | Y33: =SUM(J33:X33) -> 21.8 | Z33: =SUM(AC33:AE33) -> 0
Y34: =SUM(J34:X34) -> 0 | Z34: =SUM(AC34:AE34) -> 0
I35: 計 | Y35: =SUM(Y31:Y34) -> 27.75 | Z35: =SUM(AB35:AE35) -> 28 | AB35: =IF($Y35<1,ROUND($Y35,1),0) -> 0 | AC35: =IF(AND($Y35>=1,$Y35<1000),ROUND($Y35,0),0) -> 28 | AD35: =IF($Y35>=1000,ROUND($Y35,-1),0) -> 0
I36: 4 | S36: ='管工（舗75'!T16 -> 3.36 | Y36: =SUM(J36:X36) -> 3.36 | Z36: =SUM(AC36:AE36) -> 0
I37: 5 | Y37: =SUM(J37:X37) -> 0 | Z37: =SUM(AC37:AE37) -> 0
I38: 10 | S38: ='管工（舗75'!T17 -> 695.28 | Y38: =SUM(J38:X38) -> 695.28 | Z38: =SUM(AC38:AE38) -> 0
Y39: =SUM(J39:X39) -> 0 | Z39: =SUM(AC39:AE39) -> 0
I40: 計 | Y40: =SUM(Y36:Y39) -> 698.64 | Z40: =SUM(AB40:AE40) -> 699 | AB40: =IF($Y40<1,ROUND($Y40,1),0) -> 0 | AC40: =IF(AND($Y40>=1,$Y40<1000),ROUND($Y40,0),0) -> 699 | AD40: =IF($Y40>=1000,ROUND($Y40,-1),0) -> 0
I41: 4 | T41: ='管工（舗400'!T16 -> 9 | Y41: =SUM(J41:X41) -> 9 | Z41: =SUM(AC41:AE41) -> 0
...

Sheet 総括表（舗装工事）
B1: 数量総括表（舗装工事-1）
B2: 舗装復旧工事・舗装工事
B4: ='舗装（集計）'!L1 -> 東白川特2高層配水池揚水管取替工事
B5: 名 称 | D5: 摘 要 | I5: 舗装本復旧 | J5: その他 | K5: 計 | L5: 設計書 | O5: 数値基準
O6: 0.1 | P6: 1 | Q6: 10 | R6: 100
B7: 舗装版切断 (舗装工事) | D7: As | E7: t≦15㎝ | I7: 648.1 | K7: =SUM(I7:J7) -> 648.1 | L7: =SUM(O7:R7) -> 650 | O7: =IF($K7<1,ROUND($K7,1),0) -> 0 | P7: =IF(AND($K7>=1,$K7<100),ROUND($K7,0),0) -> 0 | Q7: =IF($K7>=100,ROUND($K7,-1),0) -> 650
E8: 15㎝<t≦30㎝ | K8: =SUM(I8:J8) -> 0 | L8: =SUM(O8:R8) -> 0 | O8: =IF($K8<1,ROUND($K8,1),0) -> 0 | P8: =IF(AND($K8>=1,$K8<100),ROUND($K8,0),0) -> 0 | Q8: =IF($K8>=100,ROUND($K8,-1),0) -> 0
D9: Co | E9: t≦15㎝ | K9: =SUM(I9:J9) -> 0 | L9: =SUM(O9:R9) -> 0 | O9: =IF($K9<1,ROUND($K9,1),0) -> 0 | P9: =IF(AND($K9>=1,$K9<100),ROUND($K9,0),0) -> 0 | Q9: =IF($K9>=100,ROUND($K9,-1),0) -> 0
E10: 15㎝<t≦30㎝ | K10: =SUM(I10:J10) -> 0 | L10: =SUM(O10:R10) -> 0 | O10: =IF($K10<1,ROUND($K10,1),0) -> 0 | P10: =IF(AND($K10>=1,$K10<100),ROUND($K10,0),0) -> 0 | Q10: =IF($K10>=100,ROUND($K10,-1),0) -> 0
B11: 舗 装 版 破 砕 （ 舗 装 工 事 ） | C11: 人力 | D11: As | E11: 4㎝以下 | H11: 4 | K11: =SUM(I11:J11) -> 0 | L11: =SUM(O11:R11) -> 0 | O11: =IF($K11<1,ROUND($K11,1),0) -> 0 | P11: =IF(AND($K11>=1,$K11<1000),ROUND($K11,0),0) -> 0 | Q11: =IF($K11>=1000,ROUND($K11,-1),0) -> 0
E12: 10㎝以下 | H12: 5 | K12: =SUM(I12:J12) -> 0 | L12: =SUM(P12:R12) -> 0
H13: 10 | K13: =SUM(I13:J13) -> 0 | L13: =SUM(P13:R13) -> 0
K14: =SUM(I14:J14) -> 0 | L14: =SUM(P14:R14) -> 0
H15: 計 | K15: =SUM(K12:K14) -> 0 | L15: =SUM(O15:R15) -> 0 | O15: =IF($K15<1,ROUND($K15,1),0) -> 0 | P15: =IF(AND($K15>=1,$K15<1000),ROUND($K15,0),0) -> 0 | Q15: =IF($K15>=1000,ROUND($K15,-1),0) -> 0
E16: 15㎝以下 | H16: 15 | K16: =SUM(I16:J16) -> 0 | L16: =SUM(P16:R16) -> 0
H17: 14 | K17: =SUM(I17:J17) -> 0 | L17: =SUM(P17:R17) -> 0
H18: 計 | K18: =SUM(K16:K17) -> 0 | L18: =SUM(O18:R18) -> 0 | O18: =IF($K18<1,ROUND($K18,1),0) -> 0 | P18: =IF(AND($K18>=1,$K18<1000),ROUND($K18,0),0) -> 0 | Q18: =IF($K18>=1000,ROUND($K18,-1),0) -> 0
E19: 15㎝超 | H19: 20 | K19: =SUM(I19:J19) -> 0 | L19: =SUM(O19:R19) -> 0 | O19: =IF($K19<1,ROUND($K19,1),0) -> 0 | P19: =IF(AND($K19>=1,$K19<1000),ROUND($K19,0),0) -> 0 | Q19: =IF($K19>=1000,ROUND($K19,-1),0) -> 0
D20: Co | E20: 4㎝以下 | H20: 4 | K20: =SUM(I20:J20) -> 0 | L20: =SUM(O20:R20) -> 0 | O20: =IF($K20<1,ROUND($K20,1),0) -> 0 | P20: =IF(AND($K20>=1,$K20<1000),ROUND($K20,0),0) -> 0 | Q20: =IF($K20>=1000,ROUND($K20,-1),0) -> 0
E21: 10㎝以下 | H21: 8 | K21: =SUM(I21:J21) -> 0 | L21: =SUM(O21:R21) -> 0 | O21: =IF($K21<1,ROUND($K21,1),0) -> 0 | P21: =IF(AND($K21>=1,$K21<1000),ROUND($K21,0),0) -> 0 | Q21: =IF($K21>=1000,ROUND($K21,-1),0) -> 0
E22: 15㎝以下 | H22: 14 | K22: =SUM(I22:J22) -> 0 | L22: =SUM(O22:R22) -> 0 | O22: =IF($K22<1,ROUND($K22,1),0) -> 0 | P22: =IF(AND($K22>=1,$K22<1000),ROUND($K22,0),0) -> 0 | Q22: =IF($K22>=1000,ROUND($K22,-1),0) -> 0
E23: 15㎝超 | H23: 20 | K23: =SUM(I23:J23) -> 0 | L23: =SUM(O23:R23) -> 0 | O23: =IF($K23<1,ROUND($K23,1),0) -> 0 | P23: =IF(AND($K23>=1,$K23<1000),ROUND($K23,0),0) -> 0 | Q23: =IF($K23>=1000,ROUND($K23,-1),0) -> 0
C24: 機械 | D24: As | E24: 15㎝以下 | H24: 4 | I24: ='舗装（集計）'!AD25 -> 82.4 | K24: =SUM(I24:J24) -> 82.4 | L24: =SUM(P24:R24) -> 0
H25: 5 | I25: ='舗装（集計）'!AD26 -> 1763.4 | K25: =SUM(I25:J25) -> 1763.4 | L25: =SUM(P25:R25) -> 0
H26: 10 | I26: ='舗装（集計）'!AD27 -> 3484.51 | K26: =SUM(I26:J26) -> 3484.51 | L26: =SUM(P26:R26) -> 0
H27: 14 | K27: =SUM(I27:J27) -> 0 | L27: =SUM(P27:R27) -> 0
H28: 15 | I28: ='舗装（集計）'!AD28 -> 728.88 | K28: =SUM(I28:J28) -> 728.88
H29: アスカーブ | J29: 0.61 | K29: =SUM(I29:J29) -> 0.61 | L29: =SUM(P29:R29) -> 0
K30: =SUM(I30:J30) -> 0 | L30: =SUM(P30:R30) -> 0
H31: 計 | K31: =SUM(K24:K30) -> 6059.8 | L31: =SUM(O31:R31) -> 6060 | O31: =IF($K31<1,ROUND($K31,1),0) -> 0 | P31: =IF(AND($K31>=1,$K31<1000),ROUND($K31,0),0) -> 0 | Q31: =IF($K31>=1000,ROUND($K31,-1),0) -> 6060
E32: 15㎝超 | H32: 20 | K32: =SUM(I32:J32) -> 0 | L32: =SUM(O32:R32) -> 0 | O32: =IF($K32<1,ROUND($K32,1),0) -> 0 | P32: =IF(AND($K32>=1,$K32<1000),ROUND($K32,0),0) -> 0 | Q32: =IF($K32>=1000,ROUND($K32,-1),0) -> 0
D33: Co | E33: 10㎝以下 | H33: 8 | K33: =SUM(I33:J33) -> 0 | L33: =SUM(O33:R33) -> 0 | O33: =IF($K33<1,ROUND($K33,1),0) -> 0 | P33: =IF(AND($K33>=1,$K33<1000),ROUND($K33,0),0) -> 0 | Q33: =IF($K33>=1000,ROUND($K33,-1),0) -> 0
E34: 15㎝以下 | H34: 15 | I34: ='舗装（集計）'!AG25+'舗装（集計）'!AG26 -> 119.61 | K34: =SUM(I34:J34) -> 119.61 | L34: =SUM(O34:R34) -> 120 | O34: =IF($K34<1,ROUND($K34,1),0) -> 0 | P34: =IF(AND($K34>=1,$K34<1000),ROUND($K34,0),0) -> 120 | Q34: =IF($K34>=1000,ROUND($K34,-1),0) -> 0
E35: 15㎝超 | H35: 20 | K35: =SUM(I35:J35) -> 0 | L35: =SUM(O35:R35) -> 0 | O35: =IF($K35<1,ROUND($K35,1),0) -> 0 | P35: =IF(AND($K35>=1,$K35<1000),ROUND($K35,0),0) -> 0 | Q35: =IF($K35>=1000,ROUND($K35,-1),0) -> 0
B36: 路面切削工 | D36: 路面切削工 | G36: 5 | K36: =SUM(I36:J36) -> 0 | L36: =SUM(O36:R36) -> 0 | O36: =IF($K36<1,ROUND($K36,1),0) -> 0 | P36: =IF(AND($K36>=1,$K36<1000),ROUND($K36,0),0) -> 0 | Q36: =IF($K36>=1000,ROUND($K36,-1),0) -> 0
D37: 切削ｵｰﾊﾞｰﾚｲ | G37: 5 | K37: =SUM(I37:J37) -> 0 | L37: =SUM(O37:R37) -> 0 | O37: =IF($K37<1,ROUND($K37,1),0) -> 0 | P37: =IF(AND($K37>=1,$K37<1000),ROUND($K37,0),0) -> 0 | Q37: =IF($K37>=1000,ROUND($K37,-1),0) -> 0
B38: Co構造物取壊し工 | D38: 無筋Co | J38: 4.53 | K38: =SUM(I38:J38) -> 4.53 | L38: =SUM(O38:R38) -> 5 | O38: =IF($K38<1,ROUND($K38,1),0) -> 0 | P38: =IF($K38>=1,ROUND($K38,0),0) -> 5
D39: 鉄筋Co | K39: =SUM(I39:J39) -> 0 | L39: =SUM(O39:R39) -> 0 | O39: =IF($K39<1,ROUND($K39,1),0) -> 0 | P39: =IF($K39>=1,ROUND($K39,0),0) -> 0
B40: 殻 運 搬 | C40: 殻運搬 （現場～仮置場） | D40: 舗装版 破砕 | E40: 15㎝以下 | G40: =V40 -> 4.2 | K40: =SUM(I40:J40) -> 0 | L40: =SUM(O40:R40) -> 0 | O40: =IF($K40<1,ROUND($K40,1),0) -> 0 | P40: =IF($K40>=1,ROUND($K40,0),0) -> 0 | T40: 舗装版破砕工 | U40: 15㎝以下 | V40: 4.2 | W40: ㎞
E41: 15㎝超 | G41: =V41 -> 4.2 | K41: =SUM(I41:J41) -> 0 | L41: =SUM(O41:R41) -> 0 | O41: =IF($K41<1,ROUND($K41,1),0) -> 0 | P41: =IF($K41>=1,ROUND($K41,0),0) -> 0 | U41: 15㎝超 | V41: 4.2 | W41: ㎞
...

Sheet 延長表
AG2: 掘削幅
AG3: 矢板無 | AJ3: 矢板有
AG4: 口径 | AJ4: 口径
AH5: 新設 | AI5: 取替・撤去 | AK5: 新設 | AL5: 取替・撤去
AG6: PEφ50 | AH6: 0.6 | AI6: 0.6 | AJ6: PEφ50 | AK6: 0.9
AG7: PEφ75 | AH7: 0.6 | AI7: 0.6 | AJ7: PEφ75 | AK7: 0.9
AG8: 75 | AH8: 0.6 | AI8: 0.8 | AJ8: 75 | AK8: 0.9 | AL8: 0.9
AG9: 100 | AH9: 0.6 | AI9: 0.8 | AJ9: 100 | AK9: 0.9 | AL9: 0.9
AG10: 150 | AH10: 0.6 | AI10: 0.8 | AJ10: 150 | AK10: 0.9 | AL10: 0.9
AG11: 200 | AH11: 0.6 | AI11: 0.8 | AJ11: 200 | AK11: 0.9 | AL11: 0.9
AG12: 300 | AH12: 0.7 | AI12: 0.8 | AJ12: 300 | AK12: 0.9 | AL12: 0.9
AG13: 400 | AJ13: 400 | AK13: 1 | AL13: 1
AG14: 500 | AJ14: 500 | AK14: 1.1 | AL14: 1.1
AG15: 600 | AJ15: 600 | AK15: 1.2 | AL15: 1.2
AG16: 700 | AJ16: 700 | AK16: 1.5 | AL16: 1.5
AG17: 800 | AJ17: 800 | AK17: 1.6 | AL17: 1.6
AG18: 900 | AJ18: 900 | AK18: 1.9 | AL18: 1.9
B29: ■延長表 | T29: 工事名： | U29: =表紙!$C$2 -> 東白川特2高層配水池揚水管取替工事
B30: 口 径 | E30: 矢板 有無 | F30: 掘削幅 | G30: 土工延長 | H30: 舗装別掘削延長 | T30: 据付・撤去延長 | V30: 弁栓類室 据付・撤去工 | AD30: 連 絡 箇 所
H31: 車 道 | N31: 歩 道 | S31: 合 計 | T31: 据 付 | U31: 撤 去 | V31: 据 付 | AA31: 撤 去
H32: 2-2号工 | I32: 3号工 | J32: 7号工 | M32: 計 | N32: １０号工 | O32: 10乗→10-1乗 | P32: 10→10-1号工 | R32: 計 | V32: 電送ピット | W32: 空気弁 | X32: 仕切弁（車） | Y32: 仕切弁（歩） | AA32: 電送ピット | AB32: 空気弁 | AC32: 仕切弁
B33: ■一般部
B34: SP300A | C34: =IF(B34="","","→") -> → | D34: SP300A | E34: 有 | F34: 0.9 | G34: =S34 -> 1.5 | J34: 1.5 | M34: =SUM(H34:L34) -> 1.5 | R34: =SUM(N34:Q34) -> 0 | S34: =M34+R34 -> 1.5 | T34: =S34-AD34*0.5 -> 1 | U34: =S34-AD34*0.5 -> 1 | W34: 1 | AB34: 1 | AD34: 1
B35: SP300A | C35: =IF(B35="","","→") -> → | D35: SP400A | E35: 有 | F35: 1 | G35: =S35 -> 233.5 | I35: 206.3 | J35: 27.2 | M35: =SUM(H35:L35) -> 233.5 | R35: =SUM(N35:Q35) -> 0 | S35: =M35+R35 -> 233.5 | T35: =S35-AD35*0.5 -> 233.5 | U35: =S35-AD35*0.5 -> 233.5 | V35: 1 | W35: 2
B36: SP300A | C36: =IF(B36="","","→") -> → | D36: 400 | E36: 有 | F36: 1 | G36: =S36 -> 86.6 | H36: 5.6 | I36: 78.2 | J36: 2.8 | M36: =SUM(H36:L36) -> 86.6 | R36: =SUM(N36:Q36) -> 0 | S36: =M36+R36 -> 86.6 | T36: =S36-AD36*0.5 -> 86.6 | U36: =S36-AD36*0.5 -> 86.6 | AA36: 1
B37: SP400A | C37: =IF(B37="","","→") -> → | D37: 400 | E37: 有 | F37: 1 | G37: =S37 -> 448.03 | I37: 448.03 | M37: =SUM(H37:L37) -> 448.03 | R37: =SUM(N37:Q37) -> 0 | S37: =M37+R37 -> 448.03 | T37: =S37-AD37*0.8 -> 448.03 | U37: =S37-AD37*0.8 -> 448.03 | V37: 7 | W37: 7 | AA37: 4 | AB37: 1
F38: =IF(B38="",0,IF(E38="有",MAX(VLOOKUP(B38,掘削幅矢板,3,FALSE),VLOOKUP(D38,掘削幅矢板,2,FALSE)),MAX(VLOOKUP(B38,掘削幅,3,FALSE),VLOOKUP(D38,掘削幅,2,FALSE)))) -> 0 | G38: =S38 -> 0 | M38: =SUM(H38:L38) -> 0 | R38: =SUM(N38:Q38) -> 0 | S38: =M38+R38 -> 0
B39: 電送管φ80×2 | G39: =S39 -> 0 | M39: =SUM(H39:L39) -> 0 | R39: =SUM(N39:Q39) -> 0 | S39: =M39+R39 -> 0 | T39: =4.7*2 -> 9.4
B40: 電送管φ80×2 | G40: =S40 -> 0 | M40: =SUM(H40:L40) -> 0 | R40: =SUM(N40:Q40) -> 0 | S40: =M40+R40 -> 0 | T40: =(233.5+86.6+446.8)*2 -> 1533.8
B41: ■新設部
B42: SP80A | E42: 有 | F42: 0.9 | G42: =S42 -> 1.6 | I42: 1.6 | M42: =SUM(H42:L42) -> 1.6 | R42: =SUM(N42:Q42) -> 0 | S42: =M42+R42 -> 1.6 | T42: =S42-AD42*0.5 -> 1.1 | AD42: 1
B43: SP400A | E43: 有 | F43: 1 | G43: =S43 -> 225.8 | I43: 222.1 | J43: 3.7 | M43: =SUM(H43:L43) -> 225.8 | R43: =SUM(N43:Q43) -> 0 | S43: =M43+R43 -> 225.8 | T43: =S43 -> 225.8 | V43: 6 | W43: 1
B44: 400 | E44: 有 | F44: =IF(B44="",0,IF(E44="有",VLOOKUP(B44,掘削幅矢板,2,FALSE),VLOOKUP(B44,掘削幅,2,FALSE))) -> 1 | G44: =S44 -> 105.2 | H44: 72.3 | I44: 21.2 | M44: =SUM(H44:L44) -> 93.5 | O44: 2.7 | P44: 9 | R44: =SUM(N44:Q44) -> 11.7 | S44: =M44+R44 -> 105.2 | T44: =S44-X44*0.47-Y44*0.47-AD44*0.8 -> 103.46 | V44: 3 | W44: 2 | X44: 1 | Y44: 1 | AD44: 1
B45: 200 | F45: =IF(B45="",0,IF(E45="有",VLOOKUP(B45,掘削幅矢板,2,FALSE),VLOOKUP(B45,掘削幅,2,FALSE))) -> 0.6 | G45: =S45 -> 42.09 | I45: 34.75 | M45: =SUM(H45:L45) -> 34.75 | P45: 7.34 | R45: =SUM(N45:Q45) -> 7.34 | S45: =M45+R45 -> 42.09 | T45: =S45-X45*0.3-Y45*0.3-AD45*0.5 -> 41.19 | X45: 2 | Y45: 1
B46: 300 | F46: =IF(B46="",0,IF(E46="有",VLOOKUP(B46,掘削幅矢板,2,FALSE),VLOOKUP(B46,掘削幅,2,FALSE))) -> 0.7 | G46: =S46 -> 1.515 | I46: 1.01 | M46: =SUM(H46:L46) -> 1.01 | P46: 0.505 | R46: =SUM(N46:Q46) -> 0.505 | S46: =M46+R46 -> 1.515 | T46: =S46-X46*0.4-Y46*0.4-AD46*0.5 -> 1.515
F47: =IF(B47="",0,IF(E47="有",VLOOKUP(B47,掘削幅矢板,2,FALSE),VLOOKUP(B47,掘削幅,2,FALSE))) -> 0 | G47: =S47 -> 0 | M47: =SUM(H47:L47) -> 0 | R47: =SUM(N47:Q47) -> 0 | S47: =M47+R47 -> 0
B48: 電送管φ80×2 | G48: =S48 -> 0 | M48: =SUM(H48:L48) -> 0 | R48: =SUM(N48:Q48) -> 0 | S48: =M48+R48 -> 0 | T48: =(214.1+93.7)*2 -> 615.6
B49: ■撤去部
B50: SP250A | F50: 0.8 | G50: =S50 -> 3 | H50: 3 | M50: =SUM(H50:L50) -> 3 | R50: =SUM(N50:Q50) -> 0 | S50: =M50+R50 -> 3 | U50: =S50-AD50*0.5 -> 2.5 | AD50: 1
B51: SP300A | F51: 0.8 | G51: =S51 -> 703.3 | H51: 229.9 | I51: 441.4 | J51: 29.8 | M51: =SUM(H51:L51) -> 701.1 | N51: 2.2 | R51: =SUM(N51:Q51) -> 2.2 | S51: =M51+R51 -> 703.3 | U51: =S51-AD51*0.5 -> 702.3 | AA51: 2 | AB51: 3 | AD51: 2
...

Sheet 試掘（舗50
A1: =IF(AK43="×","■試験掘（PEφ50～φ300）【新設】 （PEφ50～PEφ75）【取替】 舗装復旧積算用集計表","■試験掘（PEφ50～φ300）【新設】（PEφ50～φ75）【取替】 舗装復旧積算用集計表No.1") -> ■試験掘（PEφ50～φ300）【新設】 （PEφ50～PEφ75）【取替】 舗装復旧積算用集計表 | L1: 工事名： | O1: =表紙!C2 -> 東白川特2高層配水池揚水管取替工事 | U1: =IF(AK43="×","二枚目使用する時は印刷範囲へ(※掘削延長を入力すると１Pも含め様式変換されます)","■試験掘（ＰＥφ50～φ150）【新設】 舗装復旧積算用集計表No.2") -> 二枚目使用する時は印刷範囲へ(※掘削延長を入力すると１Pも含め様式変換されます) | AF1: 工事名： | AI1: □□（○○）配水管取替工事
B2: =IF(AK43="×","□掘削面積","□掘削面積No.1") -> □掘削面積 | M2: =IF(AK43="×","□舗装切断工","□舗装切断工No.1") -> □舗装切断工 | V2: □掘削面積No.2 | AG2: □舗装切断工No.2
C3: 在来舗装 | E3: 3 | H3: 10→10-1 | N3: 種別・舗装厚 | P3: 合 計 | Q3: 種別・舗装厚 | S3: 合 計 | W3: 在来舗装 | Y3: 3 | AB3: 10 | AH3: 種別・舗装厚 | AJ3: 合 計 | AK3: 種別・舗装厚 | AM3: 合 計
C4: 復旧号工 | E4: 5 | H4: 5 | N4: As | O4: t≦15 | P4: =F43+F47+F51+F55+F59+F63 -> 3.6 | Q4: Co | R4: t≦15 | S4: =I43+I47+I51+I55+I59+I63 -> 0 | W4: 復旧号工 | Y4: 5 | AB4: 5 | AH4: As | AI4: t≦15 | AJ4: =Z43+Z47+Z51+Z55+Z59+Z63 -> 0 | AK4: Co | AL4: t≦15 | AM4: =AC43+AC47+AC51+AC55+AC59+AC63 -> 0
C5: 区 分 | E5: 車 道 | H5: 歩 道 | N5: As | O5: 15<t≦30 | P5: =F44+F48+F52+F56+F60+F64 -> 0 | Q5: Co | R5: 15<t≦30 | S5: =I44+I48+I52+I56+I60+I64 -> 0 | W5: 区 分 | Y5: 車 道 | AB5: 歩 道 | AH5: As | AI5: 15<t≦30 | AJ5: =Z44+Z48+Z52+Z56+Z60+Z64 -> 0 | AK5: Co | AL5: 15<t≦30 | AM5: =AC44+AC48+AC52+AC56+AC60+AC64 -> 0
C6: 施工区分 | E6: 昼間施工 | H6: 昼間施工 | N6: As | O6: 30<t≦40 | P6: =F45+F49+F53+F57+F61+F65 -> 0 | W6: 施工区分 | Y6: 昼間施工 | AB6: 昼間施工 | AH6: As | AI6: 30<t≦40 | AJ6: =Z45+Z49+Z53+Z57+Z61+Z65 -> 0
C7: 管布設延長 | E7: =延長表!I45 -> 34.75 | F7: 20 | G7: =ROUNDUP(E7/F7,0) -> 2 | H7: =延長表!P45 -> 7.34 | I7: 20 | J7: =ROUNDUP(H7/I7,0) -> 1 | W7: 管布設延長 | Z7: 20 | AA7: =ROUNDUP(Y7/Z7,0) -> 0 | AC7: 20 | AD7: =ROUNDUP(AB7/AC7,0) -> 0
C8: 掘削面積 | E8: =G7 -> 2 | F8: 0.6 | G8: =ROUND(E8*F8,2) -> 1.2 | H8: =J7 -> 1 | I8: 0.6 | J8: =ROUND(H8*I8,2) -> 0.6 | W8: 掘削面積 | Y8: =AA7 -> 0 | Z8: 0.6 | AA8: =ROUND(Y8*Z8,2) -> 0 | AB8: =AD7 -> 0 | AC8: 0.6 | AD8: =ROUND(AB8*AC8,2) -> 0
C9: 合 計 | E9: =SUM(G8:G8) -> 1.2 | H9: =SUM(J8:J8) -> 0.6 | M9: =IF(AK43="×","□舗装版破砕工（人力）","□舗装版破砕工（人力）No.1") -> □舗装版破砕工（人力） | W9: 合 計 | Y9: =SUM(AA8:AA8) -> 0 | AB9: =SUM(AD8:AD8) -> 0 | AG9: □舗装版破砕工（人力）No.2
C10: 舗装版破砕工 | E10: As | H10: As | N10: 種別・舗装厚 | P10: 合 計 | Q10: 種別・舗装厚 | S10: 合 計 | W10: 舗装版破砕工 | Y10: As | AB10: As | AH10: 種別・舗装厚 | AJ10: 合 計 | AK10: 種別・舗装厚 | AM10: 合 計
E11: 10 | H11: 4 | N11: As | O11: =IF(MAX($E$381:$E$420)<ROW()-10,"",INDEX($D$381:$D$420,MATCH(ROW()-10,$E$381:$E$420,0),1)) -> 4 | P11: =SUMIF($D$381:$D$420,O11,$F$381:$F$420) -> 0.6 | Q11: Co | R11: =IF(MAX($G$381:$G$420)<ROW()-10,"",INDEX($D$381:$D$420,MATCH(ROW()-10,$G$381:$G$420,0),1)) | S11: =SUMIF($D$381:$D$420,R11,$H$381:$H$420) -> 0 | Y11: 10 | AB11: 4 | AH11: As | AI11: =IF(MAX($Y$381:$Y$420)<ROW()-10,"",INDEX($X$381:$X$420,MATCH(ROW()-10,$Y$381:$Y$420,0),1)) | AJ11: =SUMIF($X$381:$X$420,AI11,$Z$381:$Z$420) -> 0 | AK11: Co | AL11: =IF(MAX($AA$381:$AA$420)<ROW()-10,"",INDEX($X$381:$X$420,MATCH(ROW()-10,$AA$381:$AA$420,0),1)) | AM11: =SUMIF($X$381:$X$420,AL11,$AB$381:$AB$420) -> 0
C12: 先行路盤 | E12: 発生土（再使用） | N12: As | O12: =IF(MAX($E$381:$E$420)<ROW()-10,"",INDEX($D$381:$D$420,MATCH(ROW()-10,$E$381:$E$420,0),1)) -> 10 | P12: =SUMIF($D$381:$D$420,O12,$F$381:$F$420) -> 1.2 | Q12: Co | R12: =IF(MAX($G$381:$G$420)<ROW()-10,"",INDEX($D$381:$D$420,MATCH(ROW()-10,$G$381:$G$420,0),1)) | S12: =SUMIF($D$381:$D$420,R12,$H$381:$H$420) -> 0 | W12: 先行路盤 | Y12: 発生土（再使用） | AB12: 発生土（再使用） | AH12: As | AI12: =IF(MAX($Y$381:$Y$420)<ROW()-10,"",INDEX($X$381:$X$420,MATCH(ROW()-10,$Y$381:$Y$420,0),1)) | AJ12: =SUMIF($X$381:$X$420,AI12,$Z$381:$Z$420) -> 0 | AK12: Co | AL12: =IF(MAX($AA$381:$AA$420)<ROW()-10,"",INDEX($X$381:$X$420,MATCH(ROW()-10,$AA$381:$AA$420,0),1)) | AM12: =SUMIF($X$381:$X$420,AL12,$AB$381:$AB$420) -> 0
E13: 25 | N13: As | O13: =IF(MAX($E$381:$E$420)<ROW()-10,"",INDEX($D$381:$D$420,MATCH(ROW()-10,$E$381:$E$420,0),1)) | P13: =SUMIF($D$381:$D$420,O13,$F$381:$F$420) -> 0 | Q13: Co | R13: =IF(MAX($G$381:$G$420)<ROW()-10,"",INDEX($D$381:$D$420,MATCH(ROW()-10,$G$381:$G$420,0),1)) | S13: =SUMIF($D$381:$D$420,R13,$H$381:$H$420) -> 0 | Y13: 25 | AB13: 10 | AH13: As | AI13: =IF(MAX($Y$381:$Y$420)<ROW()-10,"",INDEX($X$381:$X$420,MATCH(ROW()-10,$Y$381:$Y$420,0),1)) | AJ13: =SUMIF($X$381:$X$420,AI13,$Z$381:$Z$420) -> 0 | AK13: Co | AL13: =IF(MAX($AA$381:$AA$420)<ROW()-10,"",INDEX($X$381:$X$420,MATCH(ROW()-10,$AA$381:$AA$420,0),1)) | AM13: =SUMIF($X$381:$X$420,AL13,$AB$381:$AB$420) -> 0
C14: 仮復旧 | E14: 5 | H14: 4 | N14: As | O14: =IF(MAX($E$381:$E$420)<ROW()-10,"",INDEX($D$381:$D$420,MATCH(ROW()-10,$E$381:$E$420,0),1)) | P14: =SUMIF($D$381:$D$420,O14,$F$381:$F$420) -> 0 | Q14: Co | R14: =IF(MAX($G$381:$G$420)<ROW()-10,"",INDEX($D$381:$D$420,MATCH(ROW()-10,$G$381:$G$420,0),1)) | S14: =SUMIF($D$381:$D$420,R14,$H$381:$H$420) -> 0 | W14: 仮復旧 | Y14: 5 | AB14: 4 | AH14: As | AI14: =IF(MAX($Y$381:$Y$420)<ROW()-10,"",INDEX($X$381:$X$420,MATCH(ROW()-10,$Y$381:$Y$420,0),1)) | AJ14: =SUMIF($X$381:$X$420,AI14,$Z$381:$Z$420) -> 0 | AK14: Co | AL14: =IF(MAX($AA$381:$AA$420)<ROW()-10,"",INDEX($X$381:$X$420,MATCH(ROW()-10,$AA$381:$AA$420,0),1)) | AM14: =SUMIF($X$381:$X$420,AL14,$AB$381:$AB$420) -> 0
C15: 在来舗装 | N15: As | O15: =IF(MAX($E$381:$E$420)<ROW()-10,"",INDEX($D$381:$D$420,MATCH(ROW()-10,$E$381:$E$420,0),1)) | P15: =SUMIF($D$381:$D$420,O15,$F$381:$F$420) -> 0 | Q15: Co | R15: =IF(MAX($G$381:$G$420)<ROW()-10,"",INDEX($D$381:$D$420,MATCH(ROW()-10,$G$381:$G$420,0),1)) | S15: =SUMIF($D$381:$D$420,R15,$H$381:$H$420) -> 0 | W15: 在来舗装 | Y15: 2 | AH15: As | AI15: =IF(MAX($Y$381:$Y$420)<ROW()-10,"",INDEX($X$381:$X$420,MATCH(ROW()-10,$Y$381:$Y$420,0),1)) | AJ15: =SUMIF($X$381:$X$420,AI15,$Z$381:$Z$420) -> 0 | AK15: Co | AL15: =IF(MAX($AA$381:$AA$420)<ROW()-10,"",INDEX($X$381:$X$420,MATCH(ROW()-10,$AA$381:$AA$420,0),1)) | AM15: =SUMIF($X$381:$X$420,AL15,$AB$381:$AB$420) -> 0
C16: 復旧号工 | N16: As | O16: =IF(MAX($E$381:$E$420)<ROW()-10,"",INDEX($D$381:$D$420,MATCH(ROW()-10,$E$381:$E$420,0),1)) | P16: =SUMIF($D$381:$D$420,O16,$F$381:$F$420) -> 0 | Q16: Co | R16: =IF(MAX($G$381:$G$420)<ROW()-10,"",INDEX($D$381:$D$420,MATCH(ROW()-10,$G$381:$G$420,0),1)) | S16: =SUMIF($D$381:$D$420,R16,$H$381:$H$420) -> 0 | W16: 復旧号工 | Y16: 5 | AH16: As | AI16: =IF(MAX($Y$381:$Y$420)<ROW()-10,"",INDEX($X$381:$X$420,MATCH(ROW()-10,$Y$381:$Y$420,0),1)) | AJ16: =SUMIF($X$381:$X$420,AI16,$Z$381:$Z$420) -> 0 | AK16: Co | AL16: =IF(MAX($AA$381:$AA$420)<ROW()-10,"",INDEX($X$381:$X$420,MATCH(ROW()-10,$AA$381:$AA$420,0),1)) | AM16: =SUMIF($X$381:$X$420,AL16,$AB$381:$AB$420) -> 0
C17: 区 分 | W17: 区 分 | Y17: 車 道
C18: 施工区分 | W18: 施工区分 | Y18: 昼間施工
C19: 管布設延長 | F19: 20 | G19: =ROUNDUP(E19/F19,0) -> 0 | I19: 20 | J19: =ROUNDUP(H19/I19,0) -> 0 | M19: □殻運搬(総計) | W19: 管布設延長 | Z19: 20 | AA19: =ROUNDUP(Y19/Z19,0) -> 0 | AC19: 20 | AD19: =ROUNDUP(AB19/AC19,0) -> 0
C20: 掘削面積 | E20: =G19 -> 0 | F20: 0.6 | G20: =ROUND(E20*F20,2) -> 0 | H20: =J19 -> 0 | I20: 0.6 | J20: =ROUND(H20*I20,2) -> 0 | N20: 種 別 | P20: 合 計 | Q20: 種 別 | S20: 合 計 | W20: 掘削面積 | Y20: =AA19 -> 0 | Z20: 0.6 | AA20: =ROUND(Y20*Z20,2) -> 0 | AB20: =AD19 -> 0 | AC20: 0.6 | AD20: =ROUND(AB20*AC20,2) -> 0
C21: 合 計 | E21: =SUM(G20:G20) -> 0 | H21: =SUM(J20:J20) -> 0 | N21: As（車道） | P21: =SUMPRODUCT($X$336:$X$375,$Z$336:$Z$375)/100+SUMPRODUCT($D$336:$D$375,$F$336:$F$375)/100 -> 0.12 | Q21: Co | S21: =SUMPRODUCT($X$381:$X$420,$AB$381:$AB$420)/100+SUMPRODUCT($D$381:$D$420,$H$381:$H$420)/100 -> 0 | W21: 合 計 | Y21: =SUM(AA20:AA20) -> 0 | AB21: =SUM(AD20:AD20) -> 0
C22: 舗装版破砕工 | N22: As（歩道） | P22: =SUMPRODUCT($X$336:$X$375,$Y$336:$Y$375)/100+SUMPRODUCT($D$336:$D$375,$E$336:$E$375)/100 -> 0.024 | Q22: 全種 | S22: =IF($Q$22="全種",$P$21+$S$21+$P$22,"0")+IF($Q$22="As（車道）＋As（歩道）",$P$21+$P$22,"0")+IF($Q$22="As（車道）＋Co",$P$21+$S$21,"0")+IF($Q$22="As（歩道）＋Co",$P$22+$S$21,"0") -> 0.144 | W22: 舗装版破砕工 | Y22: As | AB22: As
Y23: 15 | AB23: 10
C24: 先行路盤 | M24: =IF(AK43="×","□先行路盤（再使用）","□先行路盤（再使用）No.1") -> □先行路盤（再使用） | W24: 先行路盤 | Y24: 発生土（再使用） | AB24: 発生土（再使用） | AG24: □先行路盤（再使用）No.2
N25: 種別・路盤厚 | P25: 合 計 | Q25: 種別・路盤厚 | S25: 合 計 | Y25: 50 | AB25: 25 | AH25: 種別・路盤厚 | AJ25: 合 計 | AK25: 種別・路盤厚 | AM25: 合 計
C26: 仮復旧 | N26: 再使用 | O26: =IF(MAX($I$617:$I$676)<ROW()-25,"",INDEX($H$617:$H$676,MATCH(ROW()-25,$I$617:$I$676,0),1)) -> 25 | P26: =SUMIF($H$618:$H$677,O26,$J$618:$J$677) -> 1.2 | W26: 仮復旧 | Y26: 10 | AB26: 5 | AH26: 再使用 | AI26: =IF(MAX($AC$618:$AC$677)<ROW()-25,"",INDEX($AB$618:$AB$677,MATCH(ROW()-25,$AC$618:$AC$677,0),1)) | AJ26: =SUMIF($AB$618:$AB$677,AI26,$AD$618:$AD$677) -> 0
C27: 在来舗装 | N27: 再使用 | O27: =IF(MAX($I$617:$I$676)<ROW()-25,"",INDEX($H$617:$H$676,MATCH(ROW()-25,$I$617:$I$676,0),1)) | P27: =SUMIF($H$618:$H$677,O27,$J$618:$J$677) -> 0 | W27: 在来舗装 | AH27: 再使用 | AI27: =IF(MAX($AC$618:$AC$677)<ROW()-25,"",INDEX($AB$618:$AB$677,MATCH(ROW()-25,$AC$618:$AC$677,0),1)) | AJ27: =SUMIF($AB$618:$AB$677,AI27,$AD$618:$AD$677) -> 0
C28: 復旧号工 | N28: 再使用 | O28: =IF(MAX($I$617:$I$676)<ROW()-25,"",INDEX($H$617:$H$676,MATCH(ROW()-25,$I$617:$I$676,0),1)) | P28: =SUMIF($H$618:$H$677,O28,$J$618:$J$677) -> 0 | W28: 復旧号工 | AH28: 再使用 | AI28: =IF(MAX($AC$618:$AC$677)<ROW()-25,"",INDEX($AB$618:$AB$677,MATCH(ROW()-25,$AC$618:$AC$677,0),1)) | AJ28: =SUMIF($AB$618:$AB$677,AI28,$AD$618:$AD$677) -> 0
C29: 区 分 | N29: 再使用 | O29: =IF(MAX($I$617:$I$676)<ROW()-25,"",INDEX($H$617:$H$676,MATCH(ROW()-25,$I$617:$I$676,0),1)) | P29: =SUMIF($H$618:$H$677,O29,$J$618:$J$677) -> 0 | W29: 区 分 | Y29: 車 道 | AB29: 車 道 | AH29: 再使用 | AI29: =IF(MAX($AC$618:$AC$677)<ROW()-25,"",INDEX($AB$618:$AB$677,MATCH(ROW()-25,$AC$618:$AC$677,0),1)) | AJ29: =SUMIF($AB$618:$AB$677,AI29,$AD$618:$AD$677) -> 0
C30: 施工区分 | N30: 再使用 | O30: =IF(MAX($I$617:$I$676)<ROW()-25,"",INDEX($H$617:$H$676,MATCH(ROW()-25,$I$617:$I$676,0),1)) | P30: =SUMIF($H$618:$H$677,O30,$J$618:$J$677) -> 0 | W30: 施工区分 | Y30: 昼間施工 | AB30: 昼間施工 | AH30: 再使用 | AI30: =IF(MAX($AC$618:$AC$677)<ROW()-25,"",INDEX($AB$618:$AB$677,MATCH(ROW()-25,$AC$618:$AC$677,0),1)) | AJ30: =SUMIF($AB$618:$AB$677,AI30,$AD$618:$AD$677) -> 0
C31: 管布設延長 | F31: 20 | G31: =ROUNDUP(E31/F31,0) -> 0 | I31: 20 | J31: =ROUNDUP(H31/I31,0) -> 0 | N31: 再使用 | O31: =IF(MAX($I$617:$I$676)<ROW()-25,"",INDEX($H$617:$H$676,MATCH(ROW()-25,$I$617:$I$676,0),1)) | P31: =SUMIF($H$618:$H$677,O31,$J$618:$J$677) -> 0 | W31: 管布設延長 | Z31: 20 | AA31: =ROUNDUP(Y31/Z31,0) -> 0 | AC31: 20 | AD31: =ROUNDUP(AB31/AC31,0) -> 0 | AH31: 再使用 | AI31: =IF(MAX($AC$618:$AC$677)<ROW()-25,"",INDEX($AB$618:$AB$677,MATCH(ROW()-25,$AC$618:$AC$677,0),1)) | AJ31: =SUMIF($AB$618:$AB$677,AI31,$AD$618:$AD$677) -> 0
C32: 掘削面積 | E32: =G31 -> 0 | F32: 0.6 | G32: =ROUND(E32*F32,2) -> 0 | H32: =J31 -> 0 | I32: 0.6 | J32: =ROUND(H32*I32,2) -> 0 | O32: =IF(AK43="×","※先行路盤(再使用) 土量 計 ： H= ","※先行路盤(再使用) 土量No.1 計 ： ") -> ※先行路盤(再使用) 土量 計 ： H= | S32: =ROUND(SUMPRODUCT(O26:O31,P26:P31)/100+SUMPRODUCT(R26:R31,S26:S31)/100,2) -> 0.3 | W32: 掘削面積 | Y32: =AA31 -> 0 | Z32: 0.6 | AA32: =ROUND(Y32*Z32,2) -> 0 | AB32: =AD31 -> 0 | AC32: 0.6 | AD32: =ROUND(AB32*AC32,2) -> 0 | AI32: ※先行路盤(再使用) 土量No.1+No.2 計 ： H= | AM32: =IF(AK43="○",AK44+S32,"")
C33: 合 計 | E33: =SUM(G32:G32) -> 0 | H33: =SUM(J32:J32) -> 0 | M33: =IF(AK43="×","□仮復旧工","□仮復旧工No.1") -> □仮復旧工 | W33: 合 計 | Y33: =SUM(AA32:AA32) -> 0 | AB33: =SUM(AD32:AD32) -> 0 | AG33: □仮復旧工No.2
C34: 舗装版破砕工 | N34: 種別・舗装厚 | P34: 合 計 | Q34: 種別・舗装厚 | S34: 合 計 | W34: 舗装版破砕工 | Y34: As | AB34: As | AH34: 種別・舗装厚 | AJ34: 合 計 | AK34: 種別・舗装厚 | AM34: 合 計
N35: As | O35: =IF(MAX($I$380:$I$419)<ROW()-34,"",INDEX($D$380:$D$419,MATCH(ROW()-34,$I$380:$I$419,0),1)) -> 4 | P35: =SUMIF($D$381:$D$420,O35,$J$381:$J$420) -> 0.6 | Q35: As | R35: =IF(MAX($I$381:$I$420)<ROW()-30,"",INDEX($D$381:$D$420,MATCH(ROW()-30,$I$381:$I$420,0),1)) | S35: =SUMIF($D$381:$D$420,R35,$J$381:$J$420) -> 0 | AH35: As | AI35: =IF(MAX($AC$381:$AC$420)<ROW()-34,"",INDEX($X$381:$X$420,MATCH(ROW()-34,$AC$381:$AC$420,0),1)) | AJ35: =SUMIF($X$381:$X$420,AI35,$AD$381:$AD$420) -> 0 | AK35: As | AL35: =IF(MAX($AC$381:$AC$420)<ROW()-30,"",INDEX($X$381:$X$420,MATCH(ROW()-30,$AC$381:$AC$420,0),1)) | AM35: =SUMIF($X$381:$X$420,AL35,$AD$381:$AD$420) -> 0
C36: 先行路盤 | N36: As | O36: =IF(MAX($I$380:$I$419)<ROW()-34,"",INDEX($D$380:$D$419,MATCH(ROW()-34,$I$380:$I$419,0),1)) -> 5 | P36: =SUMIF($D$381:$D$420,O36,$J$381:$J$420) -> 1.2 | Q36: As | R36: =IF(MAX($I$381:$I$420)<ROW()-30,"",INDEX($D$381:$D$420,MATCH(ROW()-30,$I$381:$I$420,0),1)) | S36: =SUMIF($D$381:$D$420,R36,$J$381:$J$420) -> 0 | W36: 先行路盤 | Y36: 発生土（再使用） | AB36: 発生土（再使用） | AH36: As | AI36: =IF(MAX($AC$381:$AC$420)<ROW()-34,"",INDEX($X$381:$X$420,MATCH(ROW()-34,$AC$381:$AC$420,0),1)) | AJ36: =SUMIF($X$381:$X$420,AI36,$AD$381:$AD$420) -> 0 | AK36: As | AL36: =IF(MAX($AC$381:$AC$420)<ROW()-30,"",INDEX($X$381:$X$420,MATCH(ROW()-30,$AC$381:$AC$420,0),1)) | AM36: =SUMIF($X$381:$X$420,AL36,$AD$381:$AD$420) -> 0
N37: As | O37: =IF(MAX($I$380:$I$419)<ROW()-34,"",INDEX($D$380:$D$419,MATCH(ROW()-34,$I$380:$I$419,0),1)) | P37: =SUMIF($D$381:$D$420,O37,$J$381:$J$420) -> 0 | AH37: As | AI37: =IF(MAX($AC$381:$AC$420)<ROW()-34,"",INDEX($X$381:$X$420,MATCH(ROW()-34,$AC$381:$AC$420,0),1)) | AJ37: =SUMIF($X$381:$X$420,AI37,$AD$381:$AD$420) -> 0
C38: 仮復旧 | N38: As | O38: =IF(MAX($I$380:$I$419)<ROW()-34,"",INDEX($D$380:$D$419,MATCH(ROW()-34,$I$380:$I$419,0),1)) | P38: =SUMIF($D$381:$D$420,O38,$J$381:$J$420) -> 0 | W38: 仮復旧 | AH38: As | AI38: =IF(MAX($AC$381:$AC$420)<ROW()-34,"",INDEX($X$381:$X$420,MATCH(ROW()-34,$AC$381:$AC$420,0),1)) | AJ38: =SUMIF($X$381:$X$420,AI38,$AD$381:$AD$420) -> 0
O39: =IF(AK43="×","※仮復旧 土量 計 ： M= ","※仮復旧 土量No.1 計 ： ") -> ※仮復旧 土量 計 ： M= | S39: =ROUND(SUMPRODUCT(O35:O38,P35:P38)/100+SUMPRODUCT(R35:R38,S35:S38)/100,2) -> 0.08 | AI39: ※仮復旧 土量No.1+No.2 計 ： M= | AM39: =IF(AK43="○",AK45+S39,"")
B41: □だみー | V41: □だみー
...

Sheet 試掘（土50
A1: ■試験掘（PEφ50～φ300）【新設】 （PEφ50～PEφ75）【取替】 土工事積算用集計表 | O1: 工事名： | T1: =表紙!C2 -> 東白川特2高層配水池揚水管取替工事
B2: □舗装数量
C3: ○舗装版取壊 数量 | J3: □As殻Co殻運搬（現場～仮置場） | U3: ≪※ | W3: 仮置無し | X3: の場合≫
D4: 舗装種別 | F4: 掘削面積 | G4: 舗装厚 | O4: F1
D5: 3 | E5: As車道 | F5: ='試掘（舗50'!E9 -> 1.2 | G5: 0.1 | H5: =ROUND(F5*G5,2) -> 0.12 | L5: As（車道） | N5: （ | O5: =IF($W$3="仮置無し",0,$H$17) -> 0 | P5: ） | AC5: = | AD5: =O5 -> 0
H6: =ROUND(F6*G6,2) -> 0 | O6: F2
H7: =ROUND(F7*G7,2) -> 0 | L7: As（歩道） | N7: （ | O7: =IF($W$3="仮置無し",0,$H$30) -> 0 | P7: ） | AC7: = | AD7: =O7 -> 0
H8: =ROUND(F8*G8,2) -> 0 | O8: G
H9: =ROUND(F9*G9,2) -> 0 | L9: Co | N9: （ | O9: =IF($W$3="仮置無し",0,$H$43) -> 0 | P9: ） | AC9: = | AD9: =O9 -> 0
H10: =ROUND(F10*G10,2) -> 0
H11: =ROUND(F11*G11,2) -> 0 | J11: □掘削
H12: =ROUND(F12*G12,2) -> 0 | K12: ●全体土量 | O12: 試掘箇所数 | AD12: A
H13: =ROUND(F13*G13,2) -> 0 | L13: 試掘全体土量 | N13: （ | O13: =SUM('試掘（舗50'!AA7,'試掘（舗50'!AD7,'試掘（舗50'!AA19,'試掘（舗50'!AD19,'試掘（舗50'!AA31,'試掘（舗50'!AD31,'試掘（舗50'!G7,'試掘（舗50'!J7,'試掘（舗50'!G19,'試掘（舗50'!J19,'試掘（舗50'!G31,'試掘（舗50'!J31) -> 3 | P13: ） | Q13: × | R13: =ROUND(0.6*1*1.2,2) -> 0.72 | AC13: = | AD13: =ROUND(O13*R13,2) -> 2.16
H14: =ROUND(F14*G14,2) -> 0 | K14: ●全体床堀土量 | O14: A | S14: F1 | W14: F2 | AA14: G | AD14: B1
H15: =ROUND(F15*G15,2) -> 0 | L15: 全体床堀土量 | N15: （ | O15: =$AD$13 -> 2.16 | P15: ） | Q15: - | R15: （ | S15: =$H$17 -> 0.12 | T15: ） | U15: - | V15: （ | W15: =$H$30 -> 0.02 | X15: ） | Y15: - | Z15: （ | AA15: =$H$43 -> 0 | AB15: ） | AC15: = | AD15: =O15-S15-W15-AA15 -> 2.02
H16: =ROUND(F16*G16,2) -> 0 | K16: ●床 堀 | O16: B1
D17: （F1）As車道部 取壊 数量 | H17: =SUM(H5:H16) -> 0.12 | L17: 砂質土（人力） | N17: （ | O17: =$AD$15 -> 2.02 | P17: ） | AC17: = | AD17: =O17 -> 2.02
D18: 10→10-1 | E18: As歩道 | F18: ='試掘（舗50'!H9 -> 0.6 | G18: 0.04 | H18: =ROUND(F18*G18,2) -> 0.02 | K18: ●全体埋戻土量 | O18: A | S18: H | W18: M | AD18: B2
F19: ='試掘（舗50'!E21 -> 0 | H19: =ROUND(F19*G19,2) -> 0 | L19: 全体埋戻土量 | N19: （ | O19: =$AD$13 -> 2.16 | P19: ） | Q19: - | R19: （ | S19: =IF('試掘（舗50'!AM32="",'試掘（舗50'!S32,'試掘（舗50'!AM32) -> 0.3 | T19: ） | U19: - | V19: （ | W19: =IF('試掘（舗50'!AM39="",'試掘（舗50'!S39,'試掘（舗50'!AM39) -> 0.08 | X19: ） | AC19: = | AD19: =O19-S19-W19 -> 1.78
F20: ='試掘（舗50'!H21 -> 0 | H20: =ROUND(F20*G20,2) -> 0 | K20: ●土砂運搬（現場～仮置場） | O20: B1 | S20: B2 | AD20: B3
H21: =ROUND(F21*G21,2) -> 0 | L21: 砂質土（機械） | N21: （ | O21: =$AD$15 -> 2.02 | P21: ） | Q21: - | R21: （ | S21: =$AD$19 -> 1.78 | T21: ） | AC21: = | AD21: =O21-S21 -> 0.24
H22: =ROUND(F22*G22,2) -> 0
H23: =ROUND(F23*G23,2) -> 0
H24: =ROUND(F24*G24,2) -> 0
H25: =ROUND(F25*G25,2) -> 0 | J25: □埋戻し | O25: B2
H26: =ROUND(F26*G26,2) -> 0 | L26: 発生土（機械） | N26: （ | O26: =$AD$19 -> 1.78 | P26: ） | AC26: = | AD26: =O26 -> 1.78
H27: =ROUND(F27*G27,2) -> 0
H28: =ROUND(F28*G28,2) -> 0 | J28: =IF(W3="仮置有り","□As殻Co殻運搬処理（仮置場～処分地）","□As殻Co殻運搬処理（現場～処分地）") -> □As殻Co殻運搬処理（現場～処分地）
H29: =ROUND(F29*G29,2) -> 0 | K29: ●仮置土積込工 | O29: F1 | S29: F2 | U29: ≪※ | W29: =W3 -> 仮置無し | X29: の場合≫
D30: （F2）As歩道部 取壊 数量 | H30: =SUM(H18:H29) -> 0.02 | L30: As | N30: （ | O30: =IF($W$3="仮置無し",0,$H$17) -> 0 | P30: ） | Q30: + | R30: （ | S30: =IF($W$3="仮置無し",0,$H$30) -> 0 | T30: ） | AC30: = | AD30: =O30+S30 -> 0
E31: Co | H31: =ROUND(F31*G31,2) -> 0 | O31: G
H32: =ROUND(F32*G32,2) -> 0 | L32: Co | N32: （ | O32: =IF($W$3="仮置無し",0,$H$43) -> 0 | P32: ） | AC32: = | AD32: =O32 -> 0
H33: =ROUND(F33*G33,2) -> 0 | K33: ●殻運搬処理 | O33: F1
H34: =ROUND(F34*G34,2) -> 0 | L34: As（車道） | N34: （ | O34: =$H$17 -> 0.12 | P34: ） | AC34: = | AD34: =O34 -> 0.12
H35: =ROUND(F35*G35,2) -> 0 | O35: F2
H36: =ROUND(F36*G36,2) -> 0 | L36: As（歩道） | N36: （ | O36: =$H$30 -> 0.02 | P36: ） | AC36: = | AD36: =O36 -> 0.02
H37: =ROUND(F37*G37,2) -> 0 | O37: G
H38: =ROUND(F38*G38,2) -> 0 | L38: Co | N38: （ | O38: =$H$43 -> 0 | P38: ） | AC38: = | AD38: =O38 -> 0
H39: =ROUND(F39*G39,2) -> 0
H40: =ROUND(F40*G40,2) -> 0 | J40: □残土運搬処理（仮置場～処分地）
...

Sheet 試掘（舗300
A1: =IF(AK43="×","■試験掘（φ300）【新設】 舗装復旧積算用集計表","■試験掘（φ300）【新設】 舗装復旧積算用集計表No.1") -> ■試験掘（φ300）【新設】 舗装復旧積算用集計表 | L1: 工事名： | O1: =表紙!C2 -> 東白川特2高層配水池揚水管取替工事 | U1: =IF(AK43="×","二枚目使用する時は印刷範囲へ(※掘削延長を入力すると１Pも含め様式変換されます)","■試験掘（φ200～φ300）【新設】 舗装復旧積算用集計表No.2") -> 二枚目使用する時は印刷範囲へ(※掘削延長を入力すると１Pも含め様式変換されます) | AF1: 工事名： | AI1: =表紙!C2 -> 東白川特2高層配水池揚水管取替工事
B2: =IF(AK43="×","□掘削面積","□掘削面積No.1") -> □掘削面積 | M2: =IF(AK43="×","□舗装切断工","□舗装切断工No.1") -> □舗装切断工 | V2: □掘削面積No.2 | AG2: □舗装切断工No.2
C3: 在来舗装 | E3: 3 | H3: 10→10-1 | N3: 種別・舗装厚 | P3: 合 計 | Q3: 種別・舗装厚 | S3: 合 計 | W3: 在来舗装 | Y3: 3 | AB3: 10 | AH3: 種別・舗装厚 | AJ3: 合 計 | AK3: 種別・舗装厚 | AM3: 合 計
C4: 復旧号工 | E4: 5 | H4: 5 | N4: As | O4: t≦15 | P4: =F43+F47+F51+F55+F59+F63 -> 0 | Q4: Co | R4: t≦15 | S4: =I43+I47+I51+I55+I59+I63 -> 0 | W4: 復旧号工 | Y4: 5 | AB4: 5 | AH4: As | AI4: t≦15 | AJ4: =Z43+Z47+Z51+Z55+Z59+Z63 -> 0 | AK4: Co | AL4: t≦15 | AM4: =AC43+AC47+AC51+AC55+AC59+AC63 -> 0
C5: 区 分 | E5: 車 道 | H5: 歩 道 | N5: As | O5: 15<t≦30 | P5: =F44+F48+F52+F56+F60+F64 -> 0 | Q5: Co | R5: 15<t≦30 | S5: =I44+I48+I52+I56+I60+I64 -> 0 | W5: 区 分 | Y5: 車 道 | AB5: 歩 道 | AH5: As | AI5: 15<t≦30 | AJ5: =Z44+Z48+Z52+Z56+Z60+Z64 -> 0 | AK5: Co | AL5: 15<t≦30 | AM5: =AC44+AC48+AC52+AC56+AC60+AC64 -> 0
C6: 施工区分 | E6: 昼間施工 | H6: 昼間施工 | N6: As | O6: 30<t≦40 | P6: =F45+F49+F53+F57+F61+F65 -> 0 | W6: 施工区分 | Y6: 昼間施工 | AB6: 昼間施工 | AH6: As | AI6: 30<t≦40 | AJ6: =Z45+Z49+Z53+Z57+Z61+Z65 -> 0
C7: 管布設延長 | F7: 20 | G7: =ROUNDUP(E7/F7,0) -> 0 | I7: 20 | J7: =ROUNDUP(H7/I7,0) -> 0 | W7: 管布設延長 | Z7: 20 | AA7: =ROUNDUP(Y7/Z7,0) -> 0 | AC7: 20 | AD7: =ROUNDUP(AB7/AC7,0) -> 0
C8: 掘削面積 | E8: =G7 -> 0 | F8: 0.7 | G8: =ROUND(E8*F8,2) -> 0 | H8: =J7 -> 0 | I8: 0.7 | J8: =ROUND(H8*I8,2) -> 0 | W8: 掘削面積 | Y8: =AA7 -> 0 | Z8: 0.7 | AA8: =ROUND(Y8*Z8,2) -> 0 | AB8: =AD7 -> 0 | AC8: 0.7 | AD8: =ROUND(AB8*AC8,2) -> 0
C9: 合 計 | E9: =SUM(G8:G8) -> 0 | H9: =SUM(J8:J8) -> 0 | M9: =IF(AK43="×","□舗装版破砕工（人力）","□舗装版破砕工（人力）No.1") -> □舗装版破砕工（人力） | W9: 合 計 | Y9: =SUM(AA8:AA8) -> 0 | AB9: =SUM(AD8:AD8) -> 0 | AG9: □舗装版破砕工（人力）No.2
C10: 舗装版破砕工 | E10: As | H10: As | N10: 種別・舗装厚 | P10: 合 計 | Q10: 種別・舗装厚 | S10: 合 計 | W10: 舗装版破砕工 | Y10: As | AB10: As | AH10: 種別・舗装厚 | AJ10: 合 計 | AK10: 種別・舗装厚 | AM10: 合 計
E11: 10 | H11: 4 | N11: As | O11: =IF(MAX($E$381:$E$420)<ROW()-10,"",INDEX($D$381:$D$420,MATCH(ROW()-10,$E$381:$E$420,0),1)) | P11: =SUMIF($D$381:$D$420,O11,$F$381:$F$420) -> 0 | Q11: Co | R11: =IF(MAX($G$381:$G$420)<ROW()-10,"",INDEX($D$381:$D$420,MATCH(ROW()-10,$G$381:$G$420,0),1)) | S11: =SUMIF($D$381:$D$420,R11,$H$381:$H$420) -> 0 | Y11: 10 | AB11: 4 | AH11: As | AI11: =IF(MAX($Y$381:$Y$420)<ROW()-10,"",INDEX($X$381:$X$420,MATCH(ROW()-10,$Y$381:$Y$420,0),1)) | AJ11: =SUMIF($X$381:$X$420,AI11,$Z$381:$Z$420) -> 0 | AK11: Co | AL11: =IF(MAX($AA$381:$AA$420)<ROW()-10,"",INDEX($X$381:$X$420,MATCH(ROW()-10,$AA$381:$AA$420,0),1)) | AM11: =SUMIF($X$381:$X$420,AL11,$AB$381:$AB$420) -> 0
C12: 先行路盤 | E12: 発生土（再使用） | N12: As | O12: =IF(MAX($E$381:$E$420)<ROW()-10,"",INDEX($D$381:$D$420,MATCH(ROW()-10,$E$381:$E$420,0),1)) | P12: =SUMIF($D$381:$D$420,O12,$F$381:$F$420) -> 0 | Q12: Co | R12: =IF(MAX($G$381:$G$420)<ROW()-10,"",INDEX($D$381:$D$420,MATCH(ROW()-10,$G$381:$G$420,0),1)) | S12: =SUMIF($D$381:$D$420,R12,$H$381:$H$420) -> 0 | W12: 先行路盤 | Y12: 発生土（再使用） | AB12: 発生土（再使用） | AH12: As | AI12: =IF(MAX($Y$381:$Y$420)<ROW()-10,"",INDEX($X$381:$X$420,MATCH(ROW()-10,$Y$381:$Y$420,0),1)) | AJ12: =SUMIF($X$381:$X$420,AI12,$Z$381:$Z$420) -> 0 | AK12: Co | AL12: =IF(MAX($AA$381:$AA$420)<ROW()-10,"",INDEX($X$381:$X$420,MATCH(ROW()-10,$AA$381:$AA$420,0),1)) | AM12: =SUMIF($X$381:$X$420,AL12,$AB$381:$AB$420) -> 0
E13: 25 | N13: As | O13: =IF(MAX($E$381:$E$420)<ROW()-10,"",INDEX($D$381:$D$420,MATCH(ROW()-10,$E$381:$E$420,0),1)) | P13: =SUMIF($D$381:$D$420,O13,$F$381:$F$420) -> 0 | Q13: Co | R13: =IF(MAX($G$381:$G$420)<ROW()-10,"",INDEX($D$381:$D$420,MATCH(ROW()-10,$G$381:$G$420,0),1)) | S13: =SUMIF($D$381:$D$420,R13,$H$381:$H$420) -> 0 | Y13: 25 | AB13: 10 | AH13: As | AI13: =IF(MAX($Y$381:$Y$420)<ROW()-10,"",INDEX($X$381:$X$420,MATCH(ROW()-10,$Y$381:$Y$420,0),1)) | AJ13: =SUMIF($X$381:$X$420,AI13,$Z$381:$Z$420) -> 0 | AK13: Co | AL13: =IF(MAX($AA$381:$AA$420)<ROW()-10,"",INDEX($X$381:$X$420,MATCH(ROW()-10,$AA$381:$AA$420,0),1)) | AM13: =SUMIF($X$381:$X$420,AL13,$AB$381:$AB$420) -> 0
C14: 仮復旧 | E14: 5 | H14: 4 | N14: As | O14: =IF(MAX($E$381:$E$420)<ROW()-10,"",INDEX($D$381:$D$420,MATCH(ROW()-10,$E$381:$E$420,0),1)) | P14: =SUMIF($D$381:$D$420,O14,$F$381:$F$420) -> 0 | Q14: Co | R14: =IF(MAX($G$381:$G$420)<ROW()-10,"",INDEX($D$381:$D$420,MATCH(ROW()-10,$G$381:$G$420,0),1)) | S14: =SUMIF($D$381:$D$420,R14,$H$381:$H$420) -> 0 | W14: 仮復旧 | Y14: 5 | AB14: 4 | AH14: As | AI14: =IF(MAX($Y$381:$Y$420)<ROW()-10,"",INDEX($X$381:$X$420,MATCH(ROW()-10,$Y$381:$Y$420,0),1)) | AJ14: =SUMIF($X$381:$X$420,AI14,$Z$381:$Z$420) -> 0 | AK14: Co | AL14: =IF(MAX($AA$381:$AA$420)<ROW()-10,"",INDEX($X$381:$X$420,MATCH(ROW()-10,$AA$381:$AA$420,0),1)) | AM14: =SUMIF($X$381:$X$420,AL14,$AB$381:$AB$420) -> 0
C15: 在来舗装 | N15: As | O15: =IF(MAX($E$381:$E$420)<ROW()-10,"",INDEX($D$381:$D$420,MATCH(ROW()-10,$E$381:$E$420,0),1)) | P15: =SUMIF($D$381:$D$420,O15,$F$381:$F$420) -> 0 | Q15: Co | R15: =IF(MAX($G$381:$G$420)<ROW()-10,"",INDEX($D$381:$D$420,MATCH(ROW()-10,$G$381:$G$420,0),1)) | S15: =SUMIF($D$381:$D$420,R15,$H$381:$H$420) -> 0 | W15: 在来舗装 | Y15: 2 | AH15: As | AI15: =IF(MAX($Y$381:$Y$420)<ROW()-10,"",INDEX($X$381:$X$420,MATCH(ROW()-10,$Y$381:$Y$420,0),1)) | AJ15: =SUMIF($X$381:$X$420,AI15,$Z$381:$Z$420) -> 0 | AK15: Co | AL15: =IF(MAX($AA$381:$AA$420)<ROW()-10,"",INDEX($X$381:$X$420,MATCH(ROW()-10,$AA$381:$AA$420,0),1)) | AM15: =SUMIF($X$381:$X$420,AL15,$AB$381:$AB$420) -> 0
C16: 復旧号工 | N16: As | O16: =IF(MAX($E$381:$E$420)<ROW()-10,"",INDEX($D$381:$D$420,MATCH(ROW()-10,$E$381:$E$420,0),1)) | P16: =SUMIF($D$381:$D$420,O16,$F$381:$F$420) -> 0 | Q16: Co | R16: =IF(MAX($G$381:$G$420)<ROW()-10,"",INDEX($D$381:$D$420,MATCH(ROW()-10,$G$381:$G$420,0),1)) | S16: =SUMIF($D$381:$D$420,R16,$H$381:$H$420) -> 0 | W16: 復旧号工 | Y16: 5 | AH16: As | AI16: =IF(MAX($Y$381:$Y$420)<ROW()-10,"",INDEX($X$381:$X$420,MATCH(ROW()-10,$Y$381:$Y$420,0),1)) | AJ16: =SUMIF($X$381:$X$420,AI16,$Z$381:$Z$420) -> 0 | AK16: Co | AL16: =IF(MAX($AA$381:$AA$420)<ROW()-10,"",INDEX($X$381:$X$420,MATCH(ROW()-10,$AA$381:$AA$420,0),1)) | AM16: =SUMIF($X$381:$X$420,AL16,$AB$381:$AB$420) -> 0
C17: 区 分 | W17: 区 分 | Y17: 車 道
C18: 施工区分 | W18: 施工区分 | Y18: 昼間施工
C19: 管布設延長 | F19: 20 | G19: =ROUNDUP(E19/F19,0) -> 0 | I19: 20 | J19: =ROUNDUP(H19/I19,0) -> 0 | M19: □殻運搬(総計) | W19: 管布設延長 | Z19: 20 | AA19: =ROUNDUP(Y19/Z19,0) -> 0 | AC19: 20 | AD19: =ROUNDUP(AB19/AC19,0) -> 0
C20: 掘削面積 | E20: =G19 -> 0 | F20: 0.7 | G20: =ROUND(E20*F20,2) -> 0 | H20: =J19 -> 0 | I20: 0.7 | J20: =ROUND(H20*I20,2) -> 0 | N20: 種 別 | P20: 合 計 | Q20: 種 別 | S20: 合 計 | W20: 掘削面積 | Y20: =AA19 -> 0 | Z20: 0.7 | AA20: =ROUND(Y20*Z20,2) -> 0 | AB20: =AD19 -> 0 | AC20: 0.7 | AD20: =ROUND(AB20*AC20,2) -> 0
C21: 合 計 | E21: =SUM(G20:G20) -> 0 | H21: =SUM(J20:J20) -> 0 | N21: As（車道） | P21: =SUMPRODUCT($X$336:$X$375,$Z$336:$Z$375)/100+SUMPRODUCT($D$336:$D$375,$F$336:$F$375)/100 -> 0 | Q21: Co | S21: =SUMPRODUCT($X$381:$X$420,$AB$381:$AB$420)/100+SUMPRODUCT($D$381:$D$420,$H$381:$H$420)/100 -> 0 | W21: 合 計 | Y21: =SUM(AA20:AA20) -> 0 | AB21: =SUM(AD20:AD20) -> 0
C22: 舗装版破砕工 | N22: As（歩道） | P22: =SUMPRODUCT($X$336:$X$375,$Y$336:$Y$375)/100+SUMPRODUCT($D$336:$D$375,$E$336:$E$375)/100 -> 0 | Q22: 全種 | S22: =IF($Q$22="全種",$P$21+$S$21+$P$22,"0")+IF($Q$22="As（車道）＋As（歩道）",$P$21+$P$22,"0")+IF($Q$22="As（車道）＋Co",$P$21+$S$21,"0")+IF($Q$22="As（歩道）＋Co",$P$22+$S$21,"0") -> 0 | W22: 舗装版破砕工 | Y22: As | AB22: As
Y23: 15 | AB23: 10
C24: 先行路盤 | M24: =IF(AK43="×","□先行路盤（再使用）","□先行路盤（再使用）No.1") -> □先行路盤（再使用） | W24: 先行路盤 | Y24: 発生土（再使用） | AB24: 発生土（再使用） | AG24: □先行路盤（再使用）No.2
N25: 種別・路盤厚 | P25: 合 計 | Q25: 種別・路盤厚 | S25: 合 計 | Y25: 50 | AB25: 25 | AH25: 種別・路盤厚 | AJ25: 合 計 | AK25: 種別・路盤厚 | AM25: 合 計
C26: 仮復旧 | N26: 再使用 | O26: =IF(MAX($I$618:$I$677)<ROW()-25,"",INDEX($H$618:$H$677,MATCH(ROW()-25,$I$618:$I$677,0),1)) | P26: =SUMIF($H$618:$H$677,O26,$J$618:$J$677) -> 0 | W26: 仮復旧 | Y26: 10 | AB26: 5 | AH26: 再使用 | AI26: =IF(MAX($AC$618:$AC$677)<ROW()-25,"",INDEX($AB$618:$AB$677,MATCH(ROW()-25,$AC$618:$AC$677,0),1)) | AJ26: =SUMIF($AB$618:$AB$677,AI26,$AD$618:$AD$677) -> 0
C27: 在来舗装 | N27: 再使用 | O27: =IF(MAX($I$618:$I$677)<ROW()-25,"",INDEX($H$618:$H$677,MATCH(ROW()-25,$I$618:$I$677,0),1)) | P27: =SUMIF($H$618:$H$677,O27,$J$618:$J$677) -> 0 | W27: 在来舗装 | AH27: 再使用 | AI27: =IF(MAX($AC$618:$AC$677)<ROW()-25,"",INDEX($AB$618:$AB$677,MATCH(ROW()-25,$AC$618:$AC$677,0),1)) | AJ27: =SUMIF($AB$618:$AB$677,AI27,$AD$618:$AD$677) -> 0
C28: 復旧号工 | N28: 再使用 | O28: =IF(MAX($I$618:$I$677)<ROW()-25,"",INDEX($H$618:$H$677,MATCH(ROW()-25,$I$618:$I$677,0),1)) | P28: =SUMIF($H$618:$H$677,O28,$J$618:$J$677) -> 0 | W28: 復旧号工 | AH28: 再使用 | AI28: =IF(MAX($AC$618:$AC$677)<ROW()-25,"",INDEX($AB$618:$AB$677,MATCH(ROW()-25,$AC$618:$AC$677,0),1)) | AJ28: =SUMIF($AB$618:$AB$677,AI28,$AD$618:$AD$677) -> 0
C29: 区 分 | N29: 再使用 | O29: =IF(MAX($I$618:$I$677)<ROW()-25,"",INDEX($H$618:$H$677,MATCH(ROW()-25,$I$618:$I$677,0),1)) | P29: =SUMIF($H$618:$H$677,O29,$J$618:$J$677) -> 0 | W29: 区 分 | Y29: 車 道 | AB29: 車 道 | AH29: 再使用 | AI29: =IF(MAX($AC$618:$AC$677)<ROW()-25,"",INDEX($AB$618:$AB$677,MATCH(ROW()-25,$AC$618:$AC$677,0),1)) | AJ29: =SUMIF($AB$618:$AB$677,AI29,$AD$618:$AD$677) -> 0
C30: 施工区分 | N30: 再使用 | O30: =IF(MAX($I$618:$I$677)<ROW()-25,"",INDEX($H$618:$H$677,MATCH(ROW()-25,$I$618:$I$677,0),1)) | P30: =SUMIF($H$618:$H$677,O30,$J$618:$J$677) -> 0 | W30: 施工区分 | Y30: 昼間施工 | AB30: 昼間施工 | AH30: 再使用 | AI30: =IF(MAX($AC$618:$AC$677)<ROW()-25,"",INDEX($AB$618:$AB$677,MATCH(ROW()-25,$AC$618:$AC$677,0),1)) | AJ30: =SUMIF($AB$618:$AB$677,AI30,$AD$618:$AD$677) -> 0
C31: 管布設延長 | F31: 20 | G31: =ROUNDUP(E31/F31,0) -> 0 | I31: 20 | J31: =ROUNDUP(H31/I31,0) -> 0 | N31: 再使用 | O31: =IF(MAX($I$618:$I$677)<ROW()-25,"",INDEX($H$618:$H$677,MATCH(ROW()-25,$I$618:$I$677,0),1)) | P31: =SUMIF($H$618:$H$677,O31,$J$618:$J$677) -> 0 | W31: 管布設延長 | Z31: 20 | AA31: =ROUNDUP(Y31/Z31,0) -> 0 | AC31: 20 | AD31: =ROUNDUP(AB31/AC31,0) -> 0 | AH31: 再使用 | AI31: =IF(MAX($AC$618:$AC$677)<ROW()-25,"",INDEX($AB$618:$AB$677,MATCH(ROW()-25,$AC$618:$AC$677,0),1)) | AJ31: =SUMIF($AB$618:$AB$677,AI31,$AD$618:$AD$677) -> 0
C32: 掘削面積 | E32: =G31 -> 0 | F32: 0.7 | G32: =ROUND(E32*F32,2) -> 0 | H32: =J31 -> 0 | I32: 0.7 | J32: =ROUND(H32*I32,2) -> 0 | O32: =IF(AK43="×","※先行路盤(再使用) 土量 計 ： H= ","※先行路盤(再使用) 土量No.1 計 ： ") -> ※先行路盤(再使用) 土量 計 ： H= | S32: =ROUND(SUMPRODUCT(O26:O31,P26:P31)/100+SUMPRODUCT(R26:R31,S26:S31)/100,2) -> 0 | W32: 掘削面積 | Y32: =AA31 -> 0 | Z32: 0.7 | AA32: =ROUND(Y32*Z32,2) -> 0 | AB32: =AD31 -> 0 | AC32: 0.7 | AD32: =ROUND(AB32*AC32,2) -> 0 | AI32: ※先行路盤(再使用) 土量No.1+No.2 計 ： H= | AM32: =IF(AK43="○",AK44+S32,"")
C33: 合 計 | E33: =SUM(G32:G32) -> 0 | H33: =SUM(J32:J32) -> 0 | M33: =IF(AK43="×","□仮復旧工","□仮復旧工No.1") -> □仮復旧工 | W33: 合 計 | Y33: =SUM(AA32:AA32) -> 0 | AB33: =SUM(AD32:AD32) -> 0 | AG33: □仮復旧工No.2
C34: 舗装版破砕工 | N34: 種別・舗装厚 | P34: 合 計 | Q34: 種別・舗装厚 | S34: 合 計 | W34: 舗装版破砕工 | Y34: As | AB34: As | AH34: 種別・舗装厚 | AJ34: 合 計 | AK34: 種別・舗装厚 | AM34: 合 計
N35: As | O35: =IF(MAX($I$381:$I$420)<ROW()-34,"",INDEX($D$381:$D$420,MATCH(ROW()-34,$I$381:$I$420,0),1)) | P35: =SUMIF($D$381:$D$420,O35,$J$381:$J$420) -> 0 | Q35: As | R35: =IF(MAX($I$381:$I$420)<ROW()-30,"",INDEX($D$381:$D$420,MATCH(ROW()-30,$I$381:$I$420,0),1)) | S35: =SUMIF($D$381:$D$420,R35,$J$381:$J$420) -> 0 | AH35: As | AI35: =IF(MAX($AC$381:$AC$420)<ROW()-34,"",INDEX($X$381:$X$420,MATCH(ROW()-34,$AC$381:$AC$420,0),1)) | AJ35: =SUMIF($X$381:$X$420,AI35,$AD$381:$AD$420) -> 0 | AK35: As | AL35: =IF(MAX($AC$381:$AC$420)<ROW()-30,"",INDEX($X$381:$X$420,MATCH(ROW()-30,$AC$381:$AC$420,0),1)) | AM35: =SUMIF($X$381:$X$420,AL35,$AD$381:$AD$420) -> 0
C36: 先行路盤 | N36: As | O36: =IF(MAX($I$381:$I$420)<ROW()-34,"",INDEX($D$381:$D$420,MATCH(ROW()-34,$I$381:$I$420,0),1)) | P36: =SUMIF($D$381:$D$420,O36,$J$381:$J$420) -> 0 | Q36: As | R36: =IF(MAX($I$381:$I$420)<ROW()-30,"",INDEX($D$381:$D$420,MATCH(ROW()-30,$I$381:$I$420,0),1)) | S36: =SUMIF($D$381:$D$420,R36,$J$381:$J$420) -> 0 | W36: 先行路盤 | Y36: 発生土（再使用） | AB36: 発生土（再使用） | AH36: As | AI36: =IF(MAX($AC$381:$AC$420)<ROW()-34,"",INDEX($X$381:$X$420,MATCH(ROW()-34,$AC$381:$AC$420,0),1)) | AJ36: =SUMIF($X$381:$X$420,AI36,$AD$381:$AD$420) -> 0 | AK36: As | AL36: =IF(MAX($AC$381:$AC$420)<ROW()-30,"",INDEX($X$381:$X$420,MATCH(ROW()-30,$AC$381:$AC$420,0),1)) | AM36: =SUMIF($X$381:$X$420,AL36,$AD$381:$AD$420) -> 0
N37: As | O37: =IF(MAX($I$381:$I$420)<ROW()-34,"",INDEX($D$381:$D$420,MATCH(ROW()-34,$I$381:$I$420,0),1)) | P37: =SUMIF($D$381:$D$420,O37,$J$381:$J$420) -> 0 | AH37: As | AI37: =IF(MAX($AC$381:$AC$420)<ROW()-34,"",INDEX($X$381:$X$420,MATCH(ROW()-34,$AC$381:$AC$420,0),1)) | AJ37: =SUMIF($X$381:$X$420,AI37,$AD$381:$AD$420) -> 0
C38: 仮復旧 | N38: As | O38: =IF(MAX($I$381:$I$420)<ROW()-34,"",INDEX($D$381:$D$420,MATCH(ROW()-34,$I$381:$I$420,0),1)) | P38: =SUMIF($D$381:$D$420,O38,$J$381:$J$420) -> 0 | W38: 仮復旧 | AH38: As | AI38: =IF(MAX($AC$381:$AC$420)<ROW()-34,"",INDEX($X$381:$X$420,MATCH(ROW()-34,$AC$381:$AC$420,0),1)) | AJ38: =SUMIF($X$381:$X$420,AI38,$AD$381:$AD$420) -> 0
O39: =IF(AK43="×","※仮復旧 土量 計 ： M= ","※仮復旧 土量No.1 計 ： ") -> ※仮復旧 土量 計 ： M= | S39: =ROUND(SUMPRODUCT(O35:O38,P35:P38)/100+SUMPRODUCT(R35:R38,S35:S38)/100,2) -> 0 | AI39: ※仮復旧 土量No.1+No.2 計 ： M= | AM39: =IF(AK43="○",AK45+S40,"")
B41: □だみー | V41: □だみー
...

Sheet 試掘（土300
A1: ■試験掘（φ300）【新設】 土工事積算用集計表 | O1: 工事名： | T1: =表紙!C2 -> 東白川特2高層配水池揚水管取替工事
B2: □舗装数量
C3: ○舗装版取壊 数量 | J3: □As殻Co殻運搬（現場～仮置場） | U3: ≪※ | W3: 仮置無し | X3: の場合≫
D4: 舗装種別 | F4: 掘削面積 | G4: 舗装厚 | O4: F1
E5: As車道 | H5: =ROUND(F5*G5,2) -> 0 | L5: As（車道） | N5: （ | O5: =IF($W$3="仮置無し",0,$H$17) -> 0 | P5: ） | AC5: = | AD5: =O5 -> 0
H6: =ROUND(F6*G6,2) -> 0 | O6: F2
H7: =ROUND(F7*G7,2) -> 0 | L7: As（歩道） | N7: （ | O7: =IF($W$3="仮置無し",0,$H$30) -> 0 | P7: ） | AC7: = | AD7: =O7 -> 0
H8: =ROUND(F8*G8,2) -> 0 | O8: G
H9: =ROUND(F9*G9,2) -> 0 | L9: Co | N9: （ | O9: =IF($W$3="仮置無し",0,$H$43) -> 0 | P9: ） | AC9: = | AD9: =O9 -> 0
H10: =ROUND(F10*G10,2) -> 0
H11: =ROUND(F11*G11,2) -> 0 | J11: □掘削
H12: =ROUND(F12*G12,2) -> 0 | K12: ●全体土量 | O12: 試掘箇所数 | AD12: A
H13: =ROUND(F13*G13,2) -> 0 | L13: 試掘全体土量 | N13: （ | O13: =SUM('試掘（舗300'!AA7,'試掘（舗300'!AD7,'試掘（舗300'!AA19,'試掘（舗300'!AD19,'試掘（舗300'!AA31,'試掘（舗300'!AD31,'試掘（舗300'!G7,'試掘（舗300'!J7,'試掘（舗300'!G19,'試掘（舗300'!J19,'試掘（舗300'!G31,'試掘（舗300'!J31) -> 0 | P13: ） | Q13: × | R13: =ROUND(0.6*1*1.2,2) -> 0.72 | AC13: = | AD13: =ROUND(O13*R13,2) -> 0
H14: =ROUND(F14*G14,2) -> 0 | K14: ●全体床堀土量 | O14: A | S14: F1 | W14: F2 | AA14: G | AD14: B1
H15: =ROUND(F15*G15,2) -> 0 | L15: 全体床堀土量 | N15: （ | O15: =$AD$13 -> 0 | P15: ） | Q15: - | R15: （ | S15: =$H$17 -> 0 | T15: ） | U15: - | V15: （ | W15: =$H$30 -> 0 | X15: ） | Y15: - | Z15: （ | AA15: =$H$43 -> 0 | AB15: ） | AC15: = | AD15: =O15-S15-W15-AA15 -> 0
H16: =ROUND(F16*G16,2) -> 0 | K16: ●床 堀 | O16: B1
D17: （F1）As車道部 取壊 数量 | H17: =SUM(H5:H16) -> 0 | L17: 砂質土（人力） | N17: （ | O17: =$AD$15 -> 0 | P17: ） | AC17: = | AD17: =O17 -> 0
E18: As歩道 | H18: =ROUND(F18*G18,2) -> 0 | K18: ●全体埋戻土量 | O18: A | S18: H | W18: M | AD18: B2
H19: =ROUND(F19*G19,2) -> 0 | L19: 全体埋戻土量 | N19: （ | O19: =$AD$13 -> 0 | P19: ） | Q19: - | R19: （ | S19: =IF('試掘（舗300'!AM32="",'試掘（舗300'!S32,'試掘（舗300'!AM32) -> 0 | T19: ） | U19: - | V19: （ | W19: =IF('試掘（舗300'!AM39="",'試掘（舗300'!S39,'試掘（舗300'!AM39) -> 0 | X19: ） | AC19: = | AD19: =O19-S19-W19 -> 0
H20: =ROUND(F20*G20,2) -> 0 | K20: ●土砂運搬（現場～仮置場） | O20: B1 | S20: B2 | AD20: B3
H21: =ROUND(F21*G21,2) -> 0 | L21: 砂質土（機械） | N21: （ | O21: =$AD$15 -> 0 | P21: ） | Q21: - | R21: （ | S21: =$AD$19 -> 0 | T21: ） | AC21: = | AD21: =O21-S21 -> 0
H22: =ROUND(F22*G22,2) -> 0
H23: =ROUND(F23*G23,2) -> 0
H24: =ROUND(F24*G24,2) -> 0
H25: =ROUND(F25*G25,2) -> 0 | J25: □埋戻し | O25: B2
H26: =ROUND(F26*G26,2) -> 0 | L26: 発生土（機械） | N26: （ | O26: =$AD$19 -> 0 | P26: ） | AC26: = | AD26: =O26 -> 0
H27: =ROUND(F27*G27,2) -> 0
H28: =ROUND(F28*G28,2) -> 0 | J28: =IF(W3="仮置有り","□As殻Co殻運搬処理（仮置場～処分地）","□As殻Co殻運搬処理（現場～処分地）") -> □As殻Co殻運搬処理（現場～処分地）
H29: =ROUND(F29*G29,2) -> 0 | K29: ●仮置土積込工 | O29: F1 | S29: F2 | U29: ≪※ | W29: =W3 -> 仮置無し | X29: の場合≫
D30: （F2）As歩道部 取壊 数量 | H30: =SUM(H18:H29) -> 0 | L30: As | N30: （ | O30: =IF($W$3="仮置無し",0,$H$17) -> 0 | P30: ） | Q30: + | R30: （ | S30: =IF($W$3="仮置無し",0,$H$30) -> 0 | T30: ） | AC30: = | AD30: =O30+S30 -> 0
E31: Co | H31: =ROUND(F31*G31,2) -> 0 | O31: G
H32: =ROUND(F32*G32,2) -> 0 | L32: Co | N32: （ | O32: =IF($W$3="仮置無し",0,$H$43) -> 0 | P32: ） | AC32: = | AD32: =O32 -> 0
H33: =ROUND(F33*G33,2) -> 0 | K33: ●殻運搬処理 | O33: F1
H34: =ROUND(F34*G34,2) -> 0 | L34: As（車道） | N34: （ | O34: =$H$17 -> 0 | P34: ） | AC34: = | AD34: =O34 -> 0
H35: =ROUND(F35*G35,2) -> 0 | O35: F2
H36: =ROUND(F36*G36,2) -> 0 | L36: As（歩道） | N36: （ | O36: =$H$30 -> 0 | P36: ） | AC36: = | AD36: =O36 -> 0
H37: =ROUND(F37*G37,2) -> 0 | O37: G
H38: =ROUND(F38*G38,2) -> 0 | L38: Co | N38: （ | O38: =$H$43 -> 0 | P38: ） | AC38: = | AD38: =O38 -> 0
H39: =ROUND(F39*G39,2) -> 0
H40: =ROUND(F40*G40,2) -> 0 | J40: □残土運搬処理（仮置場～処分地）
...

Sheet 試掘（舗75
A1: =IF(AK43="×","■試験掘（φ75～φ300）【取替・撤去】 舗装復旧積算用集計表","■試験掘（φ75～φ300）【取替・撤去】 舗装復旧積算用集計表No.1") -> ■試験掘（φ75～φ300）【取替・撤去】 舗装復旧積算用集計表 | L1: 工事名： | O1: =表紙!C2 -> 東白川特2高層配水池揚水管取替工事 | U1: =IF(AK43="×","二枚目使用する時は印刷範囲へ(※掘削延長を入力すると１Pも含め様式変換されます)","■試験掘（φ75～φ300）【取替・撤去】 舗装復旧積算用集計表No.2") -> 二枚目使用する時は印刷範囲へ(※掘削延長を入力すると１Pも含め様式変換されます) | AF1: 工事名： | AI1: =表紙!C2 -> 東白川特2高層配水池揚水管取替工事
B2: =IF(AK43="×","□掘削面積","□掘削面積No.1") -> □掘削面積 | M2: =IF(AK43="×","□舗装切断工","□舗装切断工No.1") -> □舗装切断工 | V2: □掘削面積No.2 | AG2: □舗装切断工No.2
C3: 在来舗装 | E3: 2-2 | H3: 10→10-1 | N3: 種別・舗装厚 | P3: 合 計 | Q3: 種別・舗装厚 | S3: 合 計 | W3: 在来舗装 | Y3: 3 | AB3: 10 | AH3: 種別・舗装厚 | AJ3: 合 計 | AK3: 種別・舗装厚 | AM3: 合 計
C4: 復旧号工 | E4: 5 | H4: 5 | N4: As | O4: t≦15 | P4: =F43+F47+F51+F55+F59+F63 -> 0 | Q4: Co | R4: t≦15 | S4: =I43+I47+I51+I55+I59+I63 -> 0 | W4: 復旧号工 | Y4: 5 | AB4: 5 | AH4: As | AI4: t≦15 | AJ4: =Z43+Z47+Z51+Z55+Z59+Z63 -> 0 | AK4: Co | AL4: t≦15 | AM4: =AC43+AC47+AC51+AC55+AC59+AC63 -> 0
C5: 区 分 | E5: 車 道 | H5: 歩 道 | N5: As | O5: 15<t≦30 | P5: =F44+F48+F52+F56+F60+F64 -> 0 | Q5: Co | R5: 15<t≦30 | S5: =I44+I48+I52+I56+I60+I64 -> 0 | W5: 区 分 | Y5: 車 道 | AB5: 歩 道 | AH5: As | AI5: 15<t≦30 | AJ5: =Z44+Z48+Z52+Z56+Z60+Z64 -> 0 | AK5: Co | AL5: 15<t≦30 | AM5: =AC44+AC48+AC52+AC56+AC60+AC64 -> 0
C6: 施工区分 | E6: 昼間施工 | H6: 昼間施工 | N6: As | O6: 30<t≦40 | P6: =F45+F49+F53+F57+F61+F65 -> 0 | W6: 施工区分 | Y6: 昼間施工 | AB6: 昼間施工 | AH6: As | AI6: 30<t≦40 | AJ6: =Z45+Z49+Z53+Z57+Z61+Z65 -> 0
C7: 管布設延長 | F7: 20 | G7: =ROUNDUP(E7/F7,0) -> 0 | I7: 20 | J7: =ROUNDUP(H7/I7,0) -> 0 | W7: 管布設延長 | Z7: 20 | AA7: =ROUNDUP(Y7/Z7,0) -> 0 | AC7: 20 | AD7: =ROUNDUP(AB7/AC7,0) -> 0
C8: 掘削面積 | E8: =G7 -> 0 | F8: 0.8 | G8: =ROUND(E8*F8,2) -> 0 | H8: =J7 -> 0 | I8: 0.8 | J8: =ROUND(H8*I8,2) -> 0 | W8: 掘削面積 | Y8: =AA7 -> 0 | Z8: 0.8 | AA8: =ROUND(Y8*Z8,2) -> 0 | AB8: =AD7 -> 0 | AC8: 0.8 | AD8: =ROUND(AB8*AC8,2) -> 0
C9: 合 計 | E9: =SUM(G8:G8) -> 0 | H9: =SUM(J8:J8) -> 0 | M9: =IF(AK43="×","□舗装版破砕工（人力）","□舗装版破砕工（人力）No.1") -> □舗装版破砕工（人力） | W9: 合 計 | Y9: =SUM(AA8:AA8) -> 0 | AB9: =SUM(AD8:AD8) -> 0 | AG9: □舗装版破砕工（人力）No.2
C10: 舗装版破砕工 | E10: As | H10: As | N10: 種別・舗装厚 | P10: 合 計 | Q10: 種別・舗装厚 | S10: 合 計 | W10: 舗装版破砕工 | Y10: As | AB10: As | AH10: 種別・舗装厚 | AJ10: 合 計 | AK10: 種別・舗装厚 | AM10: 合 計
E11: 10 | H11: 10 | N11: As | O11: =IF(MAX($E$381:$E$420)<ROW()-10,"",INDEX($D$381:$D$420,MATCH(ROW()-10,$E$381:$E$420,0),1)) | P11: =SUMIF($D$381:$D$420,O11,$F$381:$F$420) -> 0 | Q11: Co | R11: =IF(MAX($G$381:$G$420)<ROW()-10,"",INDEX($D$381:$D$420,MATCH(ROW()-10,$G$381:$G$420,0),1)) | S11: =SUMIF($D$381:$D$420,R11,$H$381:$H$420) -> 0 | Y11: 10 | AB11: 4 | AH11: As | AI11: =IF(MAX($Y$381:$Y$420)<ROW()-10,"",INDEX($X$381:$X$420,MATCH(ROW()-10,$Y$381:$Y$420,0),1)) | AJ11: =SUMIF($X$381:$X$420,AI11,$Z$381:$Z$420) -> 0 | AK11: Co | AL11: =IF(MAX($AA$381:$AA$420)<ROW()-10,"",INDEX($X$381:$X$420,MATCH(ROW()-10,$AA$381:$AA$420,0),1)) | AM11: =SUMIF($X$381:$X$420,AL11,$AB$381:$AB$420) -> 0
C12: 先行路盤 | E12: 発生土（再使用） | H12: 発生土（再使用） | N12: As | O12: =IF(MAX($E$381:$E$420)<ROW()-10,"",INDEX($D$381:$D$420,MATCH(ROW()-10,$E$381:$E$420,0),1)) | P12: =SUMIF($D$381:$D$420,O12,$F$381:$F$420) -> 0 | Q12: Co | R12: =IF(MAX($G$381:$G$420)<ROW()-10,"",INDEX($D$381:$D$420,MATCH(ROW()-10,$G$381:$G$420,0),1)) | S12: =SUMIF($D$381:$D$420,R12,$H$381:$H$420) -> 0 | W12: 先行路盤 | Y12: 発生土（再使用） | AB12: 発生土（再使用） | AH12: As | AI12: =IF(MAX($Y$381:$Y$420)<ROW()-10,"",INDEX($X$381:$X$420,MATCH(ROW()-10,$Y$381:$Y$420,0),1)) | AJ12: =SUMIF($X$381:$X$420,AI12,$Z$381:$Z$420) -> 0 | AK12: Co | AL12: =IF(MAX($AA$381:$AA$420)<ROW()-10,"",INDEX($X$381:$X$420,MATCH(ROW()-10,$AA$381:$AA$420,0),1)) | AM12: =SUMIF($X$381:$X$420,AL12,$AB$381:$AB$420) -> 0
E13: 25 | H13: 25 | N13: As | O13: =IF(MAX($E$381:$E$420)<ROW()-10,"",INDEX($D$381:$D$420,MATCH(ROW()-10,$E$381:$E$420,0),1)) | P13: =SUMIF($D$381:$D$420,O13,$F$381:$F$420) -> 0 | Q13: Co | R13: =IF(MAX($G$381:$G$420)<ROW()-10,"",INDEX($D$381:$D$420,MATCH(ROW()-10,$G$381:$G$420,0),1)) | S13: =SUMIF($D$381:$D$420,R13,$H$381:$H$420) -> 0 | Y13: 25 | AB13: 10 | AH13: As | AI13: =IF(MAX($Y$381:$Y$420)<ROW()-10,"",INDEX($X$381:$X$420,MATCH(ROW()-10,$Y$381:$Y$420,0),1)) | AJ13: =SUMIF($X$381:$X$420,AI13,$Z$381:$Z$420) -> 0 | AK13: Co | AL13: =IF(MAX($AA$381:$AA$420)<ROW()-10,"",INDEX($X$381:$X$420,MATCH(ROW()-10,$AA$381:$AA$420,0),1)) | AM13: =SUMIF($X$381:$X$420,AL13,$AB$381:$AB$420) -> 0
C14: 仮復旧 | E14: 5 | H14: 5 | N14: As | O14: =IF(MAX($E$381:$E$420)<ROW()-10,"",INDEX($D$381:$D$420,MATCH(ROW()-10,$E$381:$E$420,0),1)) | P14: =SUMIF($D$381:$D$420,O14,$F$381:$F$420) -> 0 | Q14: Co | R14: =IF(MAX($G$381:$G$420)<ROW()-10,"",INDEX($D$381:$D$420,MATCH(ROW()-10,$G$381:$G$420,0),1)) | S14: =SUMIF($D$381:$D$420,R14,$H$381:$H$420) -> 0 | W14: 仮復旧 | Y14: 5 | AB14: 4 | AH14: As | AI14: =IF(MAX($Y$381:$Y$420)<ROW()-10,"",INDEX($X$381:$X$420,MATCH(ROW()-10,$Y$381:$Y$420,0),1)) | AJ14: =SUMIF($X$381:$X$420,AI14,$Z$381:$Z$420) -> 0 | AK14: Co | AL14: =IF(MAX($AA$381:$AA$420)<ROW()-10,"",INDEX($X$381:$X$420,MATCH(ROW()-10,$AA$381:$AA$420,0),1)) | AM14: =SUMIF($X$381:$X$420,AL14,$AB$381:$AB$420) -> 0
C15: 在来舗装 | N15: As | O15: =IF(MAX($E$381:$E$420)<ROW()-10,"",INDEX($D$381:$D$420,MATCH(ROW()-10,$E$381:$E$420,0),1)) | P15: =SUMIF($D$381:$D$420,O15,$F$381:$F$420) -> 0 | Q15: Co | R15: =IF(MAX($G$381:$G$420)<ROW()-10,"",INDEX($D$381:$D$420,MATCH(ROW()-10,$G$381:$G$420,0),1)) | S15: =SUMIF($D$381:$D$420,R15,$H$381:$H$420) -> 0 | W15: 在来舗装 | Y15: 2 | AH15: As | AI15: =IF(MAX($Y$381:$Y$420)<ROW()-10,"",INDEX($X$381:$X$420,MATCH(ROW()-10,$Y$381:$Y$420,0),1)) | AJ15: =SUMIF($X$381:$X$420,AI15,$Z$381:$Z$420) -> 0 | AK15: Co | AL15: =IF(MAX($AA$381:$AA$420)<ROW()-10,"",INDEX($X$381:$X$420,MATCH(ROW()-10,$AA$381:$AA$420,0),1)) | AM15: =SUMIF($X$381:$X$420,AL15,$AB$381:$AB$420) -> 0
C16: 復旧号工 | N16: As | O16: =IF(MAX($E$381:$E$420)<ROW()-10,"",INDEX($D$381:$D$420,MATCH(ROW()-10,$E$381:$E$420,0),1)) | P16: =SUMIF($D$381:$D$420,O16,$F$381:$F$420) -> 0 | Q16: Co | R16: =IF(MAX($G$381:$G$420)<ROW()-10,"",INDEX($D$381:$D$420,MATCH(ROW()-10,$G$381:$G$420,0),1)) | S16: =SUMIF($D$381:$D$420,R16,$H$381:$H$420) -> 0 | W16: 復旧号工 | Y16: 5 | AH16: As | AI16: =IF(MAX($Y$381:$Y$420)<ROW()-10,"",INDEX($X$381:$X$420,MATCH(ROW()-10,$Y$381:$Y$420,0),1)) | AJ16: =SUMIF($X$381:$X$420,AI16,$Z$381:$Z$420) -> 0 | AK16: Co | AL16: =IF(MAX($AA$381:$AA$420)<ROW()-10,"",INDEX($X$381:$X$420,MATCH(ROW()-10,$AA$381:$AA$420,0),1)) | AM16: =SUMIF($X$381:$X$420,AL16,$AB$381:$AB$420) -> 0
C17: 区 分 | W17: 区 分 | Y17: 車 道
C18: 施工区分 | W18: 施工区分 | Y18: 昼間施工
C19: 管布設延長 | F19: 20 | G19: =ROUNDUP(E19/F19,0) -> 0 | I19: 20 | J19: =ROUNDUP(H19/I19,0) -> 0 | M19: □殻運搬(総計) | W19: 管布設延長 | Z19: 20 | AA19: =ROUNDUP(Y19/Z19,0) -> 0 | AC19: 20 | AD19: =ROUNDUP(AB19/AC19,0) -> 0
C20: 掘削面積 | E20: =G19 -> 0 | F20: 0.8 | G20: =ROUND(E20*F20,2) -> 0 | H20: =J19 -> 0 | I20: 0.8 | J20: =ROUND(H20*I20,2) -> 0 | N20: 種 別 | P20: 合 計 | Q20: 種 別 | S20: 合 計 | W20: 掘削面積 | Y20: =AA19 -> 0 | Z20: 0.8 | AA20: =ROUND(Y20*Z20,2) -> 0 | AB20: =AD19 -> 0 | AC20: 0.8 | AD20: =ROUND(AB20*AC20,2) -> 0
C21: 合 計 | E21: =SUM(G20:G20) -> 0 | H21: =SUM(J20:J20) -> 0 | N21: As（車道） | P21: =SUMPRODUCT($X$336:$X$375,$Z$336:$Z$375)/100+SUMPRODUCT($D$336:$D$375,$F$336:$F$375)/100 -> 0 | Q21: Co | S21: =SUMPRODUCT($X$381:$X$420,$AB$381:$AB$420)/100+SUMPRODUCT($D$381:$D$420,$H$381:$H$420)/100 -> 0 | W21: 合 計 | Y21: =SUM(AA20:AA20) -> 0 | AB21: =SUM(AD20:AD20) -> 0
C22: 舗装版破砕工 | N22: As（歩道） | P22: =SUMPRODUCT($X$336:$X$375,$Y$336:$Y$375)/100+SUMPRODUCT($D$336:$D$375,$E$336:$E$375)/100 -> 0 | Q22: 全種 | S22: =IF($Q$22="全種",$P$21+$S$21+$P$22,"0")+IF($Q$22="As（車道）＋As（歩道）",$P$21+$P$22,"0")+IF($Q$22="As（車道）＋Co",$P$21+$S$21,"0")+IF($Q$22="As（歩道）＋Co",$P$22+$S$21,"0") -> 0 | W22: 舗装版破砕工 | Y22: As | AB22: As
Y23: 15 | AB23: 10
C24: 先行路盤 | M24: =IF(AK43="×","□先行路盤（再使用）","□先行路盤（再使用）No.1") -> □先行路盤（再使用） | W24: 先行路盤 | Y24: 発生土（再使用） | AB24: 発生土（再使用） | AG24: □先行路盤（再使用）No.2
N25: 種別・路盤厚 | P25: 合 計 | Q25: 種別・路盤厚 | S25: 合 計 | Y25: 50 | AB25: 25 | AH25: 種別・路盤厚 | AJ25: 合 計 | AK25: 種別・路盤厚 | AM25: 合 計
C26: 仮復旧 | N26: 再使用 | O26: =IF(MAX($I$618:$I$677)<ROW()-25,"",INDEX($H$618:$H$677,MATCH(ROW()-25,$I$618:$I$677,0),1)) | P26: =SUMIF($H$618:$H$677,O26,$J$618:$J$677) -> 0 | W26: 仮復旧 | Y26: 10 | AB26: 5 | AH26: 再使用 | AI26: =IF(MAX($AC$618:$AC$677)<ROW()-25,"",INDEX($AB$618:$AB$677,MATCH(ROW()-25,$AC$618:$AC$677,0),1)) | AJ26: =SUMIF($AB$618:$AB$677,AI26,$AD$618:$AD$677) -> 0
