Workbook
Name 範囲1: #REF!
Name 範囲1: #REF!
Name 範囲2: #REF!
Name 範囲2: #REF!
Name 範囲３: #REF!
Name 範囲３: #REF!
Name 範囲４: #REF!
Name 範囲４: #REF!

Sheet 表紙
B1: 7
B2: 工事名： | C2: 長田(花山町2丁目他)配水管取替工事
C3: 事業名： | D3: 経年配水管更新事業
C4: 工事番号： | D4: 5070089
A5: 数 量 計 算 書
B6: 工事場所： | C6: 神戸市長田区花山町2丁目他

Sheet 総括表（土工事）
J1: =入力セル（各数量計算書の数量を転記間違いないように！）
J2: =この表内でﾘﾝｸ入力されてるセル
B3: 数量総括表（土工事-1）
B4: 配 水 管 土 工 事
B6: =表紙!C2 -> 長田(花山町2丁目他)配水管取替工事
B7: 名 称 | E7: 摘 要 | J7: 試 掘 （PE50-300)新設 （PE50-PE75） 取替 | K7: 試 掘 （200-300） 新設 | L7: 試 掘 （75-300） 取替・撤去 | M7: 試 掘 （400-500） | N7: 試 掘 （600以上） | O7: 給水2度 | P7: 仮配管 | Q7: 給水付替 | R7: 管工事 （75-300)新設 | S7: 管工事 （200-300） 新設 | T7: 管工事 （75-300） 取替・撤去 | U7: 管工事 （400-500） | V7: 管工事 （600以上） | W7: 舗 装 | X7: 付帯工 | Y7: 夜間 | Z7: 計 | AA7: 設計書 | AC7: 数値基準
AC8: 0.1 | AD8: 1 | AE8: 10 | AF8: 100
B9: 舗装切断工 （管工事） | E9: As舗装 | H9: t≦15㎝ | J9: 50.4 | L9: 19.2 | P9: 362.6 | Q9: 411.6 | R9: 1639.93 | T9: 2069.28 | Z9: =SUM(J9:Y9) -> 4553.01 | AA9: =SUM(AC9:AF9) -> 4550 | AC9: =IF($Z9<1,ROUND($Z9,1),0) -> 0 | AD9: =IF(AND($Z9>=1,$Z9<100),ROUND($Z9,0),0) -> 0 | AE9: =IF($Z9>=100,ROUND($Z9,-1),0) -> 4550
E10: As舗装 | H10: 15㎝<t≦30㎝ | Z10: =SUM(J10:Y10) -> 0 | AA10: =SUM(AC10:AF10) -> 0 | AC10: =IF($Z10<1,ROUND($Z10,1),0) -> 0 | AD10: =IF(AND($Z10>=1,$Z10<100),ROUND($Z10,0),0) -> 0 | AE10: =IF($Z10>=100,ROUND($Z10,-1),0) -> 0
E11: Co舗装 | H11: t≦15㎝ | Z11: =SUM(J11:Y11) -> 0 | AA11: =SUM(AC11:AF11) -> 0 | AC11: =IF($Z11<1,ROUND($Z11,1),0) -> 0 | AD11: =IF(AND($Z11>=1,$Z11<100),ROUND($Z11,0),0) -> 0 | AE11: =IF($Z11>=100,ROUND($Z11,-1),0) -> 0
E12: Co舗装 | H12: 15㎝<t≦30㎝ | Z12: =SUM(J12:Y12) -> 0 | AA12: =SUM(AC12:AF12) -> 0 | AC12: =IF($Z12<1,ROUND($Z12,1),0) -> 0 | AD12: =IF(AND($Z12>=1,$Z12<100),ROUND($Z12,0),0) -> 0 | AE12: =IF($Z12>=100,ROUND($Z12,-1),0) -> 0
B13: 舗 装 版 破 砕 （ 管 工 事 ） | C13: 人力 | E13: Ａｓ | F13: 4cm以下 | I13: 4 | J13: 1.2 | L13: 0.8 | Z13: =SUM(J13:Y13) -> 2 | AA13: =SUM(AC13:AF13) -> 2 | AC13: =IF($Z13<1,ROUND($Z13,1),0) -> 0 | AD13: =IF(AND($Z13>=1,$Z13<1000),ROUND($Z13,0),0) -> 2 | AE13: =IF($Z13>=1000,ROUND($Z13,-1),0) -> 0
F14: 10㎝以下 | I14: 5 | Z14: =SUM(J14:Y14) -> 0 | AA14: =SUM(AD14:AF14) -> 0
I15: 10 | J15: 24 | L15: 8.8 | Z15: =SUM(J15:Y15) -> 32.8 | AA15: =SUM(AD15:AF15) -> 0
Z16: =SUM(J16:Y16) -> 0 | AA16: =SUM(AD16:AF16) -> 0
H17: 計 | Z17: =SUM(Z14:Z16) -> 32.8 | AA17: =SUM(AC17:AF17) -> 33 | AC17: =IF($Z17<1,ROUND($Z17,1),0) -> 0 | AD17: =IF(AND($Z17>=1,$Z17<1000),ROUND($Z17,0),0) -> 33 | AE17: =IF($Z17>=1000,ROUND($Z17,-1),0) -> 0
F18: 15㎝以下 | I18: 14 | Z18: =SUM(J18:Y18) -> 0 | AA18: =SUM(AD18:AF18) -> 0
I19: 15 | Z19: =SUM(J19:Y19) -> 0 | AA19: =SUM(AD19:AF19) -> 0
H20: 計 | Z20: =SUM(Z18:Z19) -> 0 | AA20: =SUM(AC20:AF20) -> 0 | AC20: =IF($Z20<1,ROUND($Z20,1),0) -> 0 | AD20: =IF(AND($Z20>=1,$Z20<1000),ROUND($Z20,0),0) -> 0 | AE20: =IF($Z20>=1000,ROUND($Z20,-1),0) -> 0
F21: 15㎝超 | I21: 20 | Z21: =SUM(J21:Y21) -> 0 | AA21: =SUM(AC21:AF21) -> 0 | AC21: =IF($Z21<1,ROUND($Z21,1),0) -> 0 | AD21: =IF(AND($Z21>=1,$Z21<1000),ROUND($Z21,0),0) -> 0 | AE21: =IF($Z21>=1000,ROUND($Z21,-1),0) -> 0
E22: Ｃｏ | F22: 4cm以下 | I22: 4 | Z22: =SUM(J22:Y22) -> 0 | AA22: =SUM(AC22:AF22) -> 0 | AC22: =IF($Z22<1,ROUND($Z22,1),0) -> 0 | AD22: =IF(AND($Z22>=1,$Z22<1000),ROUND($Z22,0),0) -> 0 | AE22: =IF($Z22>=1000,ROUND($Z22,-1),0) -> 0
F23: 10cm以下 | I23: 8 | Z23: =SUM(J23:Y23) -> 0 | AA23: =SUM(AC23:AF23) -> 0 | AC23: =IF($Z23<1,ROUND($Z23,1),0) -> 0 | AD23: =IF(AND($Z23>=1,$Z23<1000),ROUND($Z23,0),0) -> 0 | AE23: =IF($Z23>=1000,ROUND($Z23,-1),0) -> 0
F24: 15cm以下 | I24: 14 | Z24: =SUM(J24:Y24) -> 0 | AA24: =SUM(AC24:AF24) -> 0 | AC24: =IF($Z24<1,ROUND($Z24,1),0) -> 0 | AD24: =IF(AND($Z24>=1,$Z24<1000),ROUND($Z24,0),0) -> 0 | AE24: =IF($Z24>=1000,ROUND($Z24,-1),0) -> 0
F25: 15㎝超 | I25: 20 | Z25: =SUM(J25:Y25) -> 0 | AA25: =SUM(AC25:AF25) -> 0 | AC25: =IF($Z25<1,ROUND($Z25,1),0) -> 0 | AD25: =IF(AND($Z25>=1,$Z25<1000),ROUND($Z25,0),0) -> 0 | AE25: =IF($Z25>=1000,ROUND($Z25,-1),0) -> 0
C26: 機械 | E26: As ・ Co | F26: 10cm以下 | I26: 4 | Z26: =SUM(J26:Y26) -> 0 | AA26: =SUM(AD26:AF26) -> 0
I27: 5 | P27: 72.52 | Z27: =SUM(J27:Y27) -> 72.52 | AA27: =SUM(AD27:AF27) -> 0
I28: 10 | P28: 72.52 | Z28: =SUM(J28:Y28) -> 72.52 | AA28: =SUM(AD28:AF28) -> 0
Z29: =SUM(J29:Y29) -> 0 | AA29: =SUM(AD29:AF29) -> 0
I30: 計 | Z30: =SUM(Z26:Z29) -> 145.04 | AA30: =SUM(AC30:AF30) -> 145 | AC30: =IF($Z30<1,ROUND($Z30,1),0) -> 0 | AD30: =IF(AND($Z30>=1,$Z30<1000),ROUND($Z30,0),0) -> 145 | AE30: =IF($Z30>=1000,ROUND($Z30,-1),0) -> 0
I31: 4 | Q31: 2.04 | R31: 21.18 | Z31: =SUM(J31:Y31) -> 23.22 | AA31: =SUM(AD31:AF31) -> 0
I32: 5 | O32: 29.4 | R32: 24 | Z32: =SUM(J32:Y32) -> 53.4 | AA32: =SUM(AD32:AF32) -> 0
I33: 10 | Q33: 121.44 | R33: 487.14 | Z33: =SUM(J33:Y33) -> 608.58 | AA33: =SUM(AD33:AF33) -> 0
Z34: =SUM(J34:Y34) -> 0 | AA34: =SUM(AD34:AF34) -> 0
I35: 計 | Z35: =SUM(Z31:Z34) -> 685.2 | AA35: =SUM(AC35:AF35) -> 685 | AC35: =IF($Z35<1,ROUND($Z35,1),0) -> 0 | AD35: =IF(AND($Z35>=1,$Z35<1000),ROUND($Z35,0),0) -> 685 | AE35: =IF($Z35>=1000,ROUND($Z35,-1),0) -> 0
I36: 4 | T36: 13.46 | Z36: =SUM(J36:Y36) -> 13.46 | AA36: =SUM(AD36:AF36) -> 0
I37: 5 | T37: 8.8 | Z37: =SUM(J37:Y37) -> 8.8 | AA37: =SUM(AD37:AF37) -> 0
I38: 10 | T38: 801.76 | Z38: =SUM(J38:Y38) -> 801.76 | AA38: =SUM(AD38:AF38) -> 0
Z39: =SUM(J39:Y39) -> 0 | AA39: =SUM(AD39:AF39) -> 0
I40: 計 | Z40: =SUM(Z36:Z39) -> 824.02 | AA40: =SUM(AC40:AF40) -> 824 | AC40: =IF($Z40<1,ROUND($Z40,1),0) -> 0 | AD40: =IF(AND($Z40>=1,$Z40<1000),ROUND($Z40,0),0) -> 824 | AE40: =IF($Z40>=1000,ROUND($Z40,-1),0) -> 0
I41: 4 | Z41: =SUM(J41:Y41) -> 0 | AA41: =SUM(AD41:AF41) -> 0
...

Sheet 総括表（管工事）
B2: 数量総括表（管工事-1）
B3: 配 水 管 管 工 事
B5: ='総括表（土工事）'!$B$6:$AA$6 -> 長田(花山町2丁目他)配水管取替工事
B6: 名 称 | C6: 摘 要 | D6: 管工事 | E6: 備 考 | F6: 名 称 | G6: 摘 要 | J6: 管工事 | K6: 備 考
B7: 鋳鉄管据付 | C7: 75 | D7: 14.6 | E7: 給水 | F7: メカニカル継手 | G7: 75
C8: 100 | D8: 227.6 | G8: 100
C9: 150 | D9: 413.1 | G9: 150
C10: 200 | D10: 2.3 | G10: 200
C11: 300 | D11: 370.3 | G11: 300
C12: 400 | G12: 400
C13: 500 | G13: 500
C14: 600 | G14: 600
C15: 700 | G15: 700
C16: 800 | G16: 800 | I16: 800
C17: 900 | G17: 900 | I17: 900
B18: 鋼管据付 | C18: 75 | F18: 特殊メカニカル継手 | G18: 75
C19: 100 | G19: 100
C20: 150 | G20: 150 | J20: 3
C21: 200 | G21: 200 | J21: 2
C22: 300 | G22: 300 | J22: 8
C23: 400 | G23: 400
C24: 500 | G24: 500
C25: 600 | G25: 600
C26: 700 | G26: 700
C27: 800 | G27: 800 | I27: 800
C28: 900 | G28: 900 | I28: 900
B29: 鋳鉄管撤去 | C29: 75 | D29: 14.6 | F29: GX継手 （直部） | G29: 75 | J29: 4
C30: 100 | D30: 41 | G30: 100 | J30: 56
C31: 150 | D31: 243.5 | G31: 150 | J31: 84
C32: 200 | D32: 353.7 | G32: 200
C33: 300 | D33: 371 | G33: 300 | J33: 65
C34: 400 | G34: 400
C35: 500 | F35: GX継手 （異形部） | G35: 75 | J35: 14
C36: 600 | G36: 100 | J36: 49
C37: 700 | G37: 150 | J37: 59
C38: 800 | G38: 200
C39: 900 | G39: 300 | J39: 55
B40: 鋼管撤去 | C40: 75 | G40: 400
C41: 100 | F41: GX継手 （特殊押輪部） | G41: 75 | J41: 8
C42: 150 | G42: 100
...

Sheet 総括表（舗装工事）
B1: 数量総括表（舗装工事-1）
B2: 舗装復旧工事・舗装工事
B4: ='総括表（土工事）'!$B$6:$AA$6 -> 長田(花山町2丁目他)配水管取替工事
B5: 名 称 | D5: 摘 要 | I5: 舗装本復旧 | J5: その他 | K5: 計 | L5: 設計書 | O5: 数値基準
O6: 0.1 | P6: 1 | Q6: 10 | R6: 100
B7: 舗装版切断 (舗装工事) | D7: As | E7: t≦15㎝ | I7: 563.2 | K7: =SUM(I7:J7) -> 563.2 | L7: =SUM(O7:R7) -> 560 | O7: =IF($K7<1,ROUND($K7,1),0) -> 0 | P7: =IF(AND($K7>=1,$K7<100),ROUND($K7,0),0) -> 0 | Q7: =IF($K7>=100,ROUND($K7,-1),0) -> 560
E8: 15㎝<t≦30㎝ | K8: =SUM(I8:J8) -> 0 | L8: =SUM(O8:R8) -> 0 | O8: =IF($K8<1,ROUND($K8,1),0) -> 0 | P8: =IF(AND($K8>=1,$K8<100),ROUND($K8,0),0) -> 0 | Q8: =IF($K8>=100,ROUND($K8,-1),0) -> 0
D9: Co | E9: t≦15㎝ | K9: =SUM(I9:J9) -> 0 | L9: =SUM(O9:R9) -> 0 | O9: =IF($K9<1,ROUND($K9,1),0) -> 0 | P9: =IF(AND($K9>=1,$K9<100),ROUND($K9,0),0) -> 0 | Q9: =IF($K9>=100,ROUND($K9,-1),0) -> 0
E10: 15㎝<t≦30㎝ | K10: =SUM(I10:J10) -> 0 | L10: =SUM(O10:R10) -> 0 | O10: =IF($K10<1,ROUND($K10,1),0) -> 0 | P10: =IF(AND($K10>=1,$K10<100),ROUND($K10,0),0) -> 0 | Q10: =IF($K10>=100,ROUND($K10,-1),0) -> 0
B11: 舗 装 版 破 砕 （ 舗 装 工 事 ） | C11: 人力 | D11: As | E11: 4㎝以下 | H11: 4 | K11: =SUM(I11:J11) -> 0 | L11: =SUM(O11:R11) -> 0 | O11: =IF($K11<1,ROUND($K11,1),0) -> 0 | P11: =IF(AND($K11>=1,$K11<1000),ROUND($K11,0),0) -> 0 | Q11: =IF($K11>=1000,ROUND($K11,-1),0) -> 0
E12: 10㎝以下 | H12: 5 | K12: =SUM(I12:J12) -> 0 | L12: =SUM(P12:R12) -> 0
H13: 10 | K13: =SUM(I13:J13) -> 0 | L13: =SUM(P13:R13) -> 0
K14: =SUM(I14:J14) -> 0 | L14: =SUM(P14:R14) -> 0
H15: 計 | K15: =SUM(K12:K14) -> 0 | L15: =SUM(O15:R15) -> 0 | O15: =IF($K15<1,ROUND($K15,1),0) -> 0 | P15: =IF(AND($K15>=1,$K15<1000),ROUND($K15,0),0) -> 0 | Q15: =IF($K15>=1000,ROUND($K15,-1),0) -> 0
E16: 15㎝以下 | H16: 15 | K16: =SUM(I16:J16) -> 0 | L16: =SUM(P16:R16) -> 0
H17: 14 | K17: =SUM(I17:J17) -> 0 | L17: =SUM(P17:R17) -> 0
H18: 計 | K18: =SUM(K16:K17) -> 0 | L18: =SUM(O18:R18) -> 0 | O18: =IF($K18<1,ROUND($K18,1),0) -> 0 | P18: =IF(AND($K18>=1,$K18<1000),ROUND($K18,0),0) -> 0 | Q18: =IF($K18>=1000,ROUND($K18,-1),0) -> 0
E19: 15㎝超 | H19: 20 | K19: =SUM(I19:J19) -> 0 | L19: =SUM(O19:R19) -> 0 | O19: =IF($K19<1,ROUND($K19,1),0) -> 0 | P19: =IF(AND($K19>=1,$K19<1000),ROUND($K19,0),0) -> 0 | Q19: =IF($K19>=1000,ROUND($K19,-1),0) -> 0
D20: Co | E20: 4㎝以下 | H20: 4 | K20: =SUM(I20:J20) -> 0 | L20: =SUM(O20:R20) -> 0 | O20: =IF($K20<1,ROUND($K20,1),0) -> 0 | P20: =IF(AND($K20>=1,$K20<1000),ROUND($K20,0),0) -> 0 | Q20: =IF($K20>=1000,ROUND($K20,-1),0) -> 0
E21: 10㎝以下 | H21: 8 | K21: =SUM(I21:J21) -> 0 | L21: =SUM(O21:R21) -> 0 | O21: =IF($K21<1,ROUND($K21,1),0) -> 0 | P21: =IF(AND($K21>=1,$K21<1000),ROUND($K21,0),0) -> 0 | Q21: =IF($K21>=1000,ROUND($K21,-1),0) -> 0
E22: 15㎝以下 | H22: 14 | K22: =SUM(I22:J22) -> 0 | L22: =SUM(O22:R22) -> 0 | O22: =IF($K22<1,ROUND($K22,1),0) -> 0 | P22: =IF(AND($K22>=1,$K22<1000),ROUND($K22,0),0) -> 0 | Q22: =IF($K22>=1000,ROUND($K22,-1),0) -> 0
E23: 15㎝超 | H23: 20 | K23: =SUM(I23:J23) -> 0 | L23: =SUM(O23:R23) -> 0 | O23: =IF($K23<1,ROUND($K23,1),0) -> 0 | P23: =IF(AND($K23>=1,$K23<1000),ROUND($K23,0),0) -> 0 | Q23: =IF($K23>=1000,ROUND($K23,-1),0) -> 0
C24: 機械 | D24: As | E24: 15㎝以下 | H24: 4 | I24: 184.7 | K24: =SUM(I24:J24) -> 184.7 | L24: =SUM(P24:R24) -> 0
H25: 5 | I25: 1515.66 | K25: =SUM(I25:J25) -> 1515.66 | L25: =SUM(P25:R25) -> 0
H26: 10 | I26: 2735.46 | K26: =SUM(I26:J26) -> 2735.46 | L26: =SUM(P26:R26) -> 0
H27: 14 | K27: =SUM(I27:J27) -> 0 | L27: =SUM(P27:R27) -> 0
H28: 15 | I28: 40.38 | K28: =SUM(I28:J28) -> 40.38
K29: =SUM(I29:J29) -> 0 | L29: =SUM(P29:R29) -> 0
K30: =SUM(I30:J30) -> 0 | L30: =SUM(P30:R30) -> 0
H31: 計 | K31: =SUM(K24:K30) -> 4476.2 | L31: =SUM(O31:R31) -> 4480 | O31: =IF($K31<1,ROUND($K31,1),0) -> 0 | P31: =IF(AND($K31>=1,$K31<1000),ROUND($K31,0),0) -> 0 | Q31: =IF($K31>=1000,ROUND($K31,-1),0) -> 4480
E32: 15㎝超 | H32: 20 | K32: =SUM(I32:J32) -> 0 | L32: =SUM(O32:R32) -> 0 | O32: =IF($K32<1,ROUND($K32,1),0) -> 0 | P32: =IF(AND($K32>=1,$K32<1000),ROUND($K32,0),0) -> 0 | Q32: =IF($K32>=1000,ROUND($K32,-1),0) -> 0
D33: Co | E33: 10㎝以下 | H33: 8 | K33: =SUM(I33:J33) -> 0 | L33: =SUM(O33:R33) -> 0 | O33: =IF($K33<1,ROUND($K33,1),0) -> 0 | P33: =IF(AND($K33>=1,$K33<1000),ROUND($K33,0),0) -> 0 | Q33: =IF($K33>=1000,ROUND($K33,-1),0) -> 0
E34: 15㎝以下 | H34: 14 | I34: 8.1 | K34: =SUM(I34:J34) -> 8.1 | L34: =SUM(O34:R34) -> 8 | O34: =IF($K34<1,ROUND($K34,1),0) -> 0 | P34: =IF(AND($K34>=1,$K34<1000),ROUND($K34,0),0) -> 8 | Q34: =IF($K34>=1000,ROUND($K34,-1),0) -> 0
E35: 15㎝超 | H35: 20 | K35: =SUM(I35:J35) -> 0 | L35: =SUM(O35:R35) -> 0 | O35: =IF($K35<1,ROUND($K35,1),0) -> 0 | P35: =IF(AND($K35>=1,$K35<1000),ROUND($K35,0),0) -> 0 | Q35: =IF($K35>=1000,ROUND($K35,-1),0) -> 0
B36: 路面切削工 | D36: 路面切削工 | G36: 5 | K36: =SUM(I36:J36) -> 0 | L36: =SUM(O36:R36) -> 0 | O36: =IF($K36<1,ROUND($K36,1),0) -> 0 | P36: =IF(AND($K36>=1,$K36<1000),ROUND($K36,0),0) -> 0 | Q36: =IF($K36>=1000,ROUND($K36,-1),0) -> 0
D37: 切削ｵｰﾊﾞｰﾚｲ | G37: 5 | K37: =SUM(I37:J37) -> 0 | L37: =SUM(O37:R37) -> 0 | O37: =IF($K37<1,ROUND($K37,1),0) -> 0 | P37: =IF(AND($K37>=1,$K37<1000),ROUND($K37,0),0) -> 0 | Q37: =IF($K37>=1000,ROUND($K37,-1),0) -> 0
B38: Co構造物取壊し工 | D38: 無筋Co | J38: 2.49 | K38: =SUM(I38:J38) -> 2.49 | L38: =SUM(O38:R38) -> 2 | O38: =IF($K38<1,ROUND($K38,1),0) -> 0 | P38: =IF($K38>=1,ROUND($K38,0),0) -> 2
D39: 鉄筋Co | K39: =SUM(I39:J39) -> 0 | L39: =SUM(O39:R39) -> 0 | O39: =IF($K39<1,ROUND($K39,1),0) -> 0 | P39: =IF($K39>=1,ROUND($K39,0),0) -> 0
B40: 殻 運 搬 | C40: 殻運搬 （現場～仮置場） | D40: 舗装版 破砕 | E40: 15㎝以下 | G40: =V40 -> 4.2 | K40: =SUM(I40:J40) -> 0 | L40: =SUM(O40:R40) -> 0 | O40: =IF($K40<1,ROUND($K40,1),0) -> 0 | P40: =IF($K40>=1,ROUND($K40,0),0) -> 0 | T40: 舗装版破砕工 | U40: 15㎝以下 | V40: 4.2 | W40: ㎞
E41: 15㎝超 | G41: =V41 -> 4.2 | K41: =SUM(I41:J41) -> 0 | L41: =SUM(O41:R41) -> 0 | O41: =IF($K41<1,ROUND($K41,1),0) -> 0 | P41: =IF($K41>=1,ROUND($K41,0),0) -> 0 | U41: 15㎝超 | V41: 4.2 | W41: ㎞
...
